Workbook
Name List_海派: 价格快速查询!$V$14:$X$14
Name 仓库列表: 价格快速查询!$S$15:$S$74
Name 海派选项: 价格快速查询!#REF!
Name 海运选项: 价格快速查询!$V$17:$W$17
Name 空派选项: 价格快速查询!$V$18:$AA$18

Sheet 查询首页
A1: =_xlfn.DISPIMG("ID_D6697A225B864C34A678052B48D4E660",1) -> =DISPIMG("ID_D6697A225B864C34A678052B48D4E660",1)

Sheet 美国赔偿标准和免赔声明
A1: =_xlfn.DISPIMG("ID_D6697A225B864C34A678052B48D4E660",1) -> =DISPIMG("ID_D6697A225B864C34A678052B48D4E660",1)
A2: 美国赔偿标准和免赔声明
A3: 一、时效赔付界定：以不同渠道时效说明为准
A4: 二、针对5H查验说明（新增）
A5: 1、散货货物，报价表已含5H查验退运费用，5H退运只包货物退运过程产生的费用，不包时效赔付，店铺绩效等费用。如果客户不接受，可以按表价-0.3/KG，一旦产生5H查验退运，按照实报实销原则，整柜退运产生的全部费用/70CBM，按照柜子里面客户订单的方数占比收取相应的费用； 举例：某个柜子退运产生了RMB140000费用，140000/70CBM=2000/CBM，客户在该柜子的占比是3CBM，则相应承担2000*3=RBM6000. 具体详情如下：关于5H查验，散货货物，使用我司Bond清关，报价包含5H查验退运费用的，5H退运只包货物退运过程产生的费用（如相关仓租、柜租、查验费、退运指定启运港的来回运费、但不包含FBA标签贴标费用、暂存仓租费、内箱SKU换标费且不含改派送地址的派送费，实际派送地址-原先派送地址，差价多退少补。 2.时效延误赔偿说明:凡因5H查验导致的时效延误，我司所有渠道均不承担任何延误赔偿责任，店铺绩效，瑕疵费等费用; 3.发货人责任约定:发货人不得因5H查验相关事宜弃货，亦不得要求我司赔偿货值损失及退运费，需要正常按照合同签署账期支付运费，不得以退运为由不付或少付运费。
A6: 2、整柜货物 a：正常报价，不包查验，如遇查验，所有费用实报实销； b：+1000美金，只包基础查验费（码头拖车费，海关查验，掏箱，装箱等杂费） c.+2000美金：包查验（包含补税，码头拖车费，海关查验，掏箱，装箱等杂费） d:+3800美金：包查验包退运（包含5H查验，包含补税，码头拖车费，海关查验，掏箱，装箱等杂费）
A7: 三、时效免赔说明
A8: 1、船公司船期/航线变更/延迟到港，自然灾害、天气原因，如台风、地震、洪水、冰雹,，暴风雪，雾；政府行为，社会异常事件包括战争，罢工等；
A9: 2、海关查验；
A10: 3、亚马逊拒收或更改预约时间，亚马逊爆仓导致预约困难；
A11: 4、客户FBA ID & 内部编码失误等相关原因；
A12: 5、客户要求扣货后派送或者因客户自身原因导致的延误；
A13: 6、由于疫情，国内仓库无法出货，船公司卸船效率慢，预约困难，拒收等不可抗力导致的延迟交仓,不在赔偿范围,此项如与具体渠道的时效赔付标准有区分，则与具体渠道的标准为准；
... A30: 1、请客户在签收后10个工作日内查询FBA后台是否上架，签收后30天内提供货物未上架后台截图(需带有电脑屏幕右下角当下真实时间)至我司方可进入索赔程序，超过60个工作日不予受理。

Sheet 渠道目录
A1: =_xlfn.DISPIMG("ID_D6697A225B864C34A678052B48D4E660",1) -> =DISPIMG("ID_D6697A225B864C34A678052B48D4E660",1)
A2: 渠道名称 | B2: 链接报价 | C2: 船期/渠道优势说明 | D2: 时效 | E2: 更新提示
A3: FBA渠道 | B3: 进入报价 | C3: 请查看报价表 | D3: 请查看报价表 | E3: 26日达上调0.6/kg
A4: 散货整柜直送 | B4: 进入报价 | C4: 直送渠道，性价比高 | D4: 30个自然日 | E4: 不变
A5: 易·12日达 | B5: 进入报价 | C5: 六截三开，超时赔付 | D5: 30个自然日 | E5: 不变
A6: 易·15日达 | B6: 进入报价 | C6: 六截三开，超时赔付 | D6: 29-31个自然日 | E6: 不变
A7: 易·17日达 | B7: 进入报价 | C7: 超时赔付 | D7: 请查看报价表 | E7: 不变
A8: 易·20日达 | B8: 进入报价 | C8: 中等快线，经济实惠 | D8: 请查看报价表 | E8: 不变
A9: 易·22日达 | B9: 进入报价 | C9: OA普船，舱位稳定，超时赔付 | D9: 请查看报价表 | E9: 不变
A10: 易·25日达 | B10: 进入报价 | C10: 普船统配，性价比高 | D10: 请查看报价表 | E10: 不变
A11: DG海卡 | B11: 进入报价 | C11: 请查看报价表 | D11: 请查看报价表 | E11: 不变
A12: 美西北专线 | B12: 进入报价 | C12: 请查看报价表 | D12: 35-40天 | E12: 不变
A13: 美中专线 | B13: 进入报价 | C13: 请查看报价表 | D13: 35-40天 | E13: 不变
... A27: 欧洲空派 | B27: 进入报价 | C27: 价格波动大，出货前请再确认运费 | D27: 8-10日提取 | E27: 不变
A28: 深圳总部公司地址：广东省深圳市龙华区民治街道民强社区宝山时代大厦2610-2616
A29: 东莞仓库地址（装柜仓库）：东莞市清溪镇九乡村新屋吓一路11号 | E29: 陈主管15118451410
A30: 广州仓库地址（装柜仓库）：广州市白云区太岗公路34号基实(广州)白云空港产业园A1栋4层02单元 | E30: 潘主管 19076062229
A31: 义乌仓库地址（装柜仓库）： 浙江省义乌市稠江街道同和路丰树产业园4G-1库（二楼）。(进大门50米右转，50米左转，直行上坡，二楼 4G-1库） | E31: 邵先生 17280936593
A32: 嘉兴仓库地址（装柜仓库）：嘉兴市嘉善县洪福东路718号丰树（姚庄）科技综合产业园1楼2C-2（进门右转150米） | E32: 李主管 18720007068
A33: 汕头仓库地址（中转仓库）：广东省汕头市澄海区凤翔街道金鸿大道澄海农村信用社南侧190米 | E33: 胡经理 13923475593
A34: 泉州仓库地址（中转仓库）：晋江市磁灶镇西园街道传化公路港k2仓库成翔物流 | E34: 李阿玲 158 6045 1181
A35: 厦门仓库地址（中转仓库）：厦门集美嘉晟物流园1期2栋110 | E35: 李没没 14760028777
A36: 中山仓库地址（中转仓库）：中山市小榄镇北部物流中心 | E36: 薛永波 18659507913

Sheet 美国发货须知
A1: =_xlfn.DISPIMG("ID_D6697A225B864C34A678052B48D4E660",1) -> =DISPIMG("ID_D6697A225B864C34A678052B48D4E660",1)
A2: 美国发货须知
A3: 1. 必须根据实际货物如实申报，货物信息要与发票资料一致，不可瞒报漏报和申报不符，如因申报不符导致海关扣货等后果及产生的所有费用由发货人承担，我司保留追究法律责任的权利.
A4: 2. 不要低价申报，如低价申报导致海关查验，反倾销，扣货，延期，我司不承担任何责任。建议不能低于货值的25%-35%申报。
A5: 3. 纸箱包装需硬朗方正，入亚马逊仓库货件需贴2个以上合格的FBA标签(必须条码字体 清晰、防潮湿耐磨损)，外箱和产品贴有“MADE IN CHINA”标签。如因包装及标签问题导致亚马逊仓库拒收或清关出现问题，所有责任及费用由发货人承担。
A6: 4.使用我司税号清关，税率以预收税率为准，我司不提供关税清单和税费截图；如客户要求清完关后凭税单及发票付关税，我司将收取关税代缴手续费（代缴关税总金额的5%）
A7: 5. 不接仿牌、侵权、反倾销、电子烟、纯电池、食品、药品、书籍、音像制品、带内容的光盘、地图、国旗、管制刀具、液体、粉末、颗粒、强磁、易燃易爆、毒性物质及腐蚀性、古董、货币等国家禁止出口及船司、航空公司、班列禁运物品；其他未列明产品请单询！
A8: 6. 以下情况，我司会协助处理，但不承担任何责任。 A.产品如需要FCC,CE,FDA,TSCA,DOT，CPSC,CPC，EPA等认证而客户无法提供有效证明及文件，导致海关扣货等后果，如因以上情况而产生的退运，销毁，仓租等一切费用，由发货方自行承担 ，例如a.蓝牙，UL，蓝牙类产品要有蓝牙证书，UL灯产品，要有UL证书，FCC,DOT等。 FDA管制的产品需要有MEDICAL DEVICE ID （FDA）: 跟人体接触类产品，医疗器械类需要做FDA申报， 有些产品不仅要FDA申报还需要FDA证书和FDA号码，如太阳镜，急救包，陶瓷制品，美容仪器，理疗产品等。 b.动植物类：产品需要卫生证书； c.木制类：产品和含木质框架的产品需要提供雷斯法案LACEY ACT申报。 d.玩具类：玩具到美国清关都需要提供TESTING REPORT,产品要贴玩具的TRACKING LABEL. 另外还需要做CPC证书 e.电器类，要有FCC认证，产品要贴CE LABEL.否则有可能清不了关，或者被退运。 f.存储类：如涉及知识产权保护法的商品,需提供授权信.如手机,有储存功能的摄录机,MP3，SD卡,HDMI等； g.鞋子/袜子类：请提供FOOTWARE FORM B.产品不符合美国当地法规的，如反倾销，侵权且无法提供有效证及及文件，导致海关扣货等后果
A9: 7. 材质是原木或带有原木的货物要求熏蒸，需要商检的货物：木家私，木制工艺品，木架，竹制品，藤制品，草制品，植物制品，洗发水，化妆品，户外游乐设施等（仅供参考）
A10: 8.每公斤申报价值大于10美金为高货值，10美金-30美金/公斤附加费+1，30美金-50美金/公斤附加费+2，50美金/公斤以上附加费+3。
A11: 9. 电商物流上架险收费标准：（此服务为我司的增值服务，我司代客户购买保险，保险最终解释权按保单说明与保险公司处理结果为准，我司协助客户处理保险事宜）
B12: 保险税率 | C12: 最低收费标准 | D12: 索赔周期
A13: 货值《=1500RMB | C13: RMB50/票 | D13: 预计45天左右
A14: 高货值单询 | B14: / | C14: / | D14: /

Sheet 船期表
A1: =_xlfn.DISPIMG("ID_D6697A225B864C34A678052B48D4E660",1) -> =DISPIMG("ID_D6697A225B864C34A678052B48D4E660",1)
A2: 周次 | B2: 国家 | C2: 渠道 | D2: 预配船司 | E2: 预配船名航次 | F2: ETD | G2: ETA | H2: 航程 | I2: POL | J2: POD | K2: 截单时间&截仓时间
K3: 华南 | S3: 华东
K4: 东莞 | L4: 广州 | M4: 中山 | N4: 汕头 | O4: 厦门 | P4: 泉州 | Q4: 武汉 | R4: 长沙 | S4: 义乌 | T4: 嘉兴
A5: WEEK23 | B5: 美国 | C5: 25日达 | D5: WHL | E5: 统配 | F5: 统配 | G5: 统配 | H5: 18 | I5: SK | J5: LA | K5: 周六 18：00 | L5: 周六 18：00 | M5: 周六18：00 | N5: 周六18：00 | O5: 周六18：00 | P5: 周六18：00 | Q5: 周五18：00 | R5: 周五18：00 | S5: 周六18：00 | T5: 周六18：00
C6: 22日达 | D6: COSCO | E6: OOCL VIOLET/010E | F6: 46205 | G6: 46220 | H6: 15 | I6: YT | J6: LB | K6: 周六 18：00 | L6: 周六 18：00 | M6: 周六 18：00 | N6: 周六 18：00 | O6: 周六 18：00 | P6: 周六 18：00 | Q6: 周五18：00 | R6: 周五18：00 | S6: 周六18：00 | T6: 周六18：00
D7: COSCO | E7: CSCL AUTUMN/073E | F7: 46204 | G7: 46218 | H7: 14 | I7: SH | J7: LA | K7: 周六 18：00 | L7: 周六 18：00 | M7: 周六 18：00 | N7: 周六 18：00 | O7: 周六 18：00 | P7: 周六 18：00 | Q7: 周五18：00 | R7: 周五18：00 | S7: 周六18：00 | T7: 周六18：00
D8: ZIM | E8: Pelican I (ZP1) / 14 / E | F8: 46203 | G8: 46217 | H8: 14 | I8: SH | J8: LA | K8: 周六 18：00 | L8: 周六 18：00 | M8: 周六 18：00 | N8: 周六 18：00 | O8: 周六 18：00 | P8: 周六 18：00 | Q8: 周五18：00 | R8: 周五18：00 | S8: 周六18：00 | T8: 周六18：00
C9: 17-20日达 | D9: ZIM | E9: Nestos (ZY6) / 17 / E | F9: 46204 | G9: 46217 | H9: 13 | I9: YT | J9: LA | K9: 周六 18：00 | L9: 周六 18：00 | M9: 周六 18：00 | N9: 周六 18：00 | O9: 周六 18：00 | P9: 周六 18：00 | Q9: 周五18：00 | R9: 周五18：00 | S9: 周六18：00 | T9: 周六18：00
D10: HEDE | E10: ADAMASTOS/2610E | F10: 46204 | G10: 46218 | H10: 14 | I10: NS | J10: LA | K10: 周六 18：00 | L10: 周六 18：00 | M10: 周六 18：00 | N10: 周六 18：00 | O10: 周六 18：00 | P10: 周六 18：00 | Q10: 周五18：00 | R10: 周五18：00 | S10: 周六18：00 | T10: 周六18：00
D11: HEDE | E11: POSEN /2606E | F11: 46205 | G11: 46218 | H11: 13 | I11: SH | J11: LA | K11: 周六 18：00 | L11: 周六 18：00 | M11: 周六 18：00 | N11: 周六 18：00 | O11: 周六 18：00 | P11: 周六 18：00 | Q11: 周五18：00 | R11: 周五18：00 | S11: 周六18：00 | T11: 周六18：00
C12: 12-15日达 | D12: Maston | E12: LURLINE 101E | F12: 46204 | G12: 46215 | H12: =G12-F12 -> 11 | I12: SH | J12: LB | K12: 周六 18：00 | L12: 周六 18：00 | M12: 周六 18：00 | N12: 周六 18：00 | O12: 周六 18：00 | P12: 周六 18：00 | Q12: 周五18：00 | R12: 周五18：00 | S12: 周六18：00 | T12: 周六18：00
C13: 奥克兰 | D13: EMC | E13: EVER MEMO/1461E | F13: 46209 | G13: 46230 | H13: 21 | I13: YT | J13: OAK | K13: 周六 18：00 | L13: 周六 18：00 | M13: 周六 18：00 | N13: 周六 18：00 | O13: 周六 18：00 | P13: 周六 18：00 | Q13: 周五18：00 | R13: 周五18：00 | S13: 周六18：00 | T13: 周六18：00
D14: COSCO | E14: ERVING/0M708E1MA | F14: 46208 | G14: 46230 | H14: 22 | I14: SH | J14: OAK | K14: 周六 18：00 | L14: 周六 18：00 | M14: 周六 18：00 | N14: 周六 18：00 | O14: 周六 18：00 | P14: 周六 18：00 | Q14: 周五18：00 | R14: 周五18：00 | S14: 周六18：00 | T14: 周六18：00
C15: 西雅图 | D15: COSCO | E15: 暂停 | F15: / | G15: / | H15: / | I15: YT | J15: SEA | K15: 周六 18：00 | L15: 周六 18：00 | M15: 周六 18：00 | N15: 周六 18：00 | O15: 周六 18：00 | P15: 周六 18：00 | Q15: 周五18：00 | R15: 周五18：00 | S15: 周六18：00 | T15: 周六18：00
D16: COSCO | E16: 暂停 | F16: / | G16: / | H16: / | I16: SH | J16: SEA | K16: 周六 18：00 | L16: 周六 18：00 | M16: 周六 18：00 | N16: 周六 18：00 | O16: 周六 18：00 | P16: 周六 18：00 | Q16: 周五18：00 | R16: 周五18：00 | S16: 周六18：00 | T16: 周六18：00
C17: 纽约 | D17: COSCO | E17: OOCL KAPOK/004E | F17: 46208 | G17: 46238 | H17: 30 | I17: YT | J17: NY | K17: 周六 18：00 | L17: 周六 18：00 | M17: 周六 18：00 | N17: 周六 18：00 | O17: 周六 18：00 | P17: 周六 18：00 | Q17: 周五18：00 | R17: 周五18：00 | S17: 周六18：00 | T17: 周六18：00
D18: ZIM | E18: ZIM Mount Fuji (ZF1) / 11 / E | F18: 46207 | G18: 46242 | H18: 35 | I18: YT | J18: NY | K18: 周六 18：00 | L18: 周六 18：00 | M18: 周六 18：00 | N18: 周六 18：00 | O18: 周六 18：00 | P18: 周六 18：00 | Q18: 周五18：00 | R18: 周五18：00 | S18: 周六18：00 | T18: 周六18：00
D19: COSCO | E19: OOCL MAGNOLIA/005E | F19: 46205 | G19: 46231 | H19: 26 | I19: SH | J19: NY | K19: 周六 18：00 | L19: 周六 18：00 | M19: 周六 18：00 | N19: 周六 18：00 | O19: 周六 18：00 | P19: 周六 18：00 | Q19: 周五18：00 | R19: 周五18：00 | S19: 周六18：00 | T19: 周六18：00
C20: 萨凡纳 | D20: COSCO | E20: OOCL KAPOK/004E | F20: 46208 | G20: 46243 | H20: 35 | I20: YT | J20: SAV | K20: 周六 18：00 | L20: 周六 18：00 | M20: 周六 18：00 | N20: 周六 18：00 | O20: 周六 18：00 | P20: 周六 18：00 | Q20: 周五18：00 | R20: 周五18：00 | S20: 周六18：00 | T20: 周六18：00
D21: ZIM | E21: ZIM Mount Fuji (ZF1) / 11 / E | F21: 46207 | G21: 46237 | H21: 30 | I21: YT | J21: SAV | K21: 周六 18：00 | L21: 周六 18：00 | M21: 周六 18：00 | N21: 周六 18：00 | O21: 周六 18：00 | P21: 周六 18：00 | Q21: 周五18：00 | R21: 周五18：00 | S21: 周六18：00 | T21: 周六18：00
D22: COSCO | E22: OOCL MAGNOLIA/005E | F22: 46205 | G22: 46236 | H22: 31 | I22: SH | J22: SAV | K22: 周六 18：00 | L22: 周六 18：00 | M22: 周六 18：00 | N22: 周六 18：00 | O22: 周六 18：00 | P22: 周六 18：00 | Q22: 周五18：00 | R22: 周五18：00 | S22: 周六18：00 | T22: 周六18：00
C23: 休斯顿 | D23: COSCO | E23: OOCL EUROPE/213E | F23: 46208 | G23: 46234 | H23: 26 | I23: YT | J23: HOU | K23: 周六 18：00 | L23: 周六 18：00 | M23: 周六 18：00 | N23: 周六 18：00 | O23: 周六 18：00 | P23: 周六 18：00 | Q23: 周五18：00 | R23: 周五18：00 | S23: 周六18：00 | T23: 周六18：00
D24: ZIM | E24: Rotterdam (ZTD) / 86 / E | F24: 46206 | G24: 46238 | H24: 32 | I24: YT | J24: HOU | K24: 周六 18：00 | L24: 周六 18：00 | M24: 周六 18：00 | N24: 周六 18：00 | O24: 周六 18：00 | P24: 周六 18：00 | Q24: 周五18：00 | R24: 周五18：00 | S24: 周六18：00 | T24: 周六18：00
D25: COSCO | E25: CMA CGM TANCREDI/0PGO3E1MA | F25: 46209 | G25: 46237 | H25: 28 | I25: SH | J25: HOU | K25: 周六 18：00 | L25: 周六 18：00 | M25: 周六 18：00 | N25: 周六 18：00 | O25: 周六 18：00 | P25: 周六 18：00 | Q25: 周五18：00 | R25: 周五18：00 | S25: 周六18：00 | T25: 周六18：00
C26: 芝加哥 | D26: COSCO | E26: OOCL VIOLET/010E | F26: 46205 | G26: 46234 | H26: 29 | I26: YT | J26: CHI | K26: 周六 18：00 | L26: 周六 18：00 | M26: 周六 18：00 | N26: 周六 18：00 | O26: 周六 18：00 | P26: 周六 18：00 | Q26: 周五18：00 | R26: 周五18：00 | S26: 周六18：00 | T26: 周六18：00
D27: COSCO | E27: CSCL AUTUMN/073E | F27: 46204 | G27: 46230 | H27: 26 | I27: SH | J27: CHI | K27: 周六 18：00 | L27: 周六 18：00 | M27: 周六 18：00 | N27: 周六 18：00 | O27: 周六 18：00 | P27: 周六 18：00 | Q27: 周五18：00 | R27: 周五18：00 | S27: 周六18：00 | T27: 周六18：00
B28: 英国 | C28: 英国海派 | D28: COSCO | E28: XIN LIAN YUN GANG 009A | F28: 46202 | G28: 46236 | H28: =_xlfn.DAYS(G28,F28) -> 34 | I28: YT | J28: FEL | K28: 周四18:00 | L28: 周四12:00 | M28: 周四12:00 | N28: 周三18:00 | O28: 周三18:00 | P28: 周三18:00 | Q28: 周二18:00 | R28: 周二18:00 | S28: - | T28: -
D29: COSCO | E29: OOCL ZEEBRUGGE 010W | F29: 46204 | G29: 46243 | H29: =_xlfn.DAYS(G29,F29) -> 39 | I29: NB | J29: FEL | K29: - | L29: - | M29: - | N29: - | O29: - | P29: - | Q29: - | R29: - | S29: 周五17:00 | T29: 周五12:00
B30: 欧洲 | C30: 欧洲海派 | D30: COSCO | E30: EVER ACE 1406-019W | F30: 46201 | G30: 46232 | H30: =_xlfn.DAYS(G30,F30) -> 31 | I30: YT | J30: ROT | K30: 周四12:00 | L30: 周四12:00 | M30: 周四12:00 | N30: 周三12:00 | O30: 周三12:00 | P30: 周三12:00 | Q30: 周二12:00 | R30: 周二12:00 | S30: - | T30: -
D31: COSCO | E31: EVER ART 1407-015W | F31: 46205 | G31: 46239 | H31: =_xlfn.DAYS(G31,F31) -> 34 | I31: NB | J31: ROT | K31: - | L31: - | M31: - | N31: - | O31: - | P31: - | Q31: - | R31: - | S31: 周四12:00 | T31: 周三18:00

Sheet 价格快速查询
A1: =_xlfn.DISPIMG("ID_D6697A225B864C34A678052B48D4E660",1) -> =DISPIMG("ID_D6697A225B864C34A678052B48D4E660",1)
C2: 渠道价格快速查询
C3: 派运方式 | D3: 国内地址 | E3: 仓库代码/地区选择 | F3: 计费标准
C4: 海运 | D4: 东莞/中山/广州 | E4: RDU2 | F4: 12KG+含税
A6: 系列 | B6: 具体渠道 | C6: 渠道单价(KG/CBM) | D6: 参考时效 (开船次日算起) | E6: 理赔时效 (开船次日开始算起) | F6: 送仓方式 | G6: 备选信息 | H6: 备注
A7: FBA渠道 | B7: FBA美西28日达 | C7: {=IF(C4="海运",IFERROR(INDEX(FBA渠道!$B$10:$I$25,MATCH(E4,FBA渠道!$A$10:$A$25,0),MATCH(F4,FBA渠道!$B$9:$I$9,0)+MATCH(D4,FBA渠道!$B$8:$I$8,0)-1),""),"")} | D7: =IF(C7="","",INDEX(FBA渠道!J10:J25,MATCH(E4,FBA渠道!A10:A25,0))) | G7: =IF(C7="","",FBA渠道!A63) | H7: 查看报价
B8: FBA美中南28日达 | C8: {=IF(C4="海运",IFERROR(INDEX(FBA渠道!$B$29:$I$34,MATCH(E4,FBA渠道!$A$29:$A$34,0),MATCH(F4,FBA渠道!$B$28:$I$28,0)+MATCH(D4,FBA渠道!$B$27:$I$27,0)-1),""),"")} | D8: =IF(C8="","",INDEX(FBA渠道!J29:J34,MATCH(E4,FBA渠道!A29:A34,0))) | G8: =IF(C8="","",FBA渠道!A63) | H8: 查看报价
B9: FBA美中北40日达 | C9: {=IF(C4="海运",IFERROR(INDEX(FBA渠道!$B$38:$I$43,MATCH(E4,FBA渠道!$A$38:$A$43,0),MATCH(F4,FBA渠道!$B$37:$I$37,0)+MATCH(D4,FBA渠道!$B$36:$I$36,0)-1),""),"")} | D9: =IF(C9="","",INDEX(FBA渠道!J38:J43,MATCH(E4,FBA渠道!A38:A43,0))) | G9: =IF(C9="","",FBA渠道!A63) | H9: 查看报价
B10: FBA美东南40日达 | C10: {=IF(C4="海运",IFERROR(INDEX(FBA渠道!$B$47:$I$50,MATCH(E4,FBA渠道!$A$47:$A$50,0),MATCH(F4,FBA渠道!$B$46:$I$46,0)+MATCH(D4,FBA渠道!$B$45:$I$45,0)-1),""),"")} -> 5.9 | D10: =IF(C10="","",INDEX(FBA渠道!J47:J50,MATCH(E4,FBA渠道!A47:A50,0))) -> 40-45自然日入仓 | G10: =IF(C10="","",FBA渠道!A63) -> 重货优惠：1：200 -0.2; 1：250 -0.5; 1：300 -0.7; 1：350 -1; 1：500 -1.5 | H10: 查看报价
B11: FBA美东北40日达 | C11: {=IF(C4="海运",IFERROR(INDEX(FBA渠道!$B$55:$I$62,MATCH(E4,FBA渠道!$A$55:$A$62,0),MATCH(F4,FBA渠道!$B$54:$I$54,0)+MATCH(D4,FBA渠道!$B$53:$I$53,0)-1),""),"")} | D11: =IF(C11="","",INDEX(FBA渠道!J55:J62,MATCH(E4,FBA渠道!A55:A62,0))) | G11: =IF(C11="","",FBA渠道!A63) | H11: 查看报价
A12: 美西专仓直送 | B12: 美国整柜直送 | C12: {=IF(C4="海运",IFERROR(INDEX(美西整柜直送!$B$6:$I$21,MATCH(E4,美西整柜直送!$A$6:$A$21,0),MATCH(F4,美西整柜直送!$B$5:$I$5,0)+MATCH(D4,美西整柜直送!$B$4:$I$4,0)-1),""),"")} | D12: =IF(C12="","","28-32") | E12: =IF(C12="","","-") | F12: =IF(C12="","","直送") | G12: =IF(C12="","",美西整柜直送!A22) | H12: 查看报价
A13: 美西22-25日达 | B13: 易·25日达卡派 | C13: {=IF(C4="海运",IFERROR(INDEX('美西22-25日达'!$L$6:$S$104,MATCH(E4,'美西22-25日达'!$A$6:$A$104,0),MATCH(F4,'美西22-25日达'!$L$5:$S$5,0)+MATCH(D4,'美西22-25日达'!$L$4:$S$4,0)-1),""),"")} -> 9.1 | D13: =IF(C13="","",INDEX('美西22-25日达'!T6:T104,MATCH(E4,'美西22-25日达'!A6:A104,0))) -> 28-35 | E13: =IF(C13="","",INDEX('美西22-25日达'!U6:U104,MATCH(E4,'美西22-25日达'!A6:A104,0))) -> - | F13: =IF(C13="","","拆派") -> 拆派 | G13: =IF(C13="","",'美西22-25日达'!A76) -> 重货优惠：1:200 -0.2; 1:250 -0.5，1:300 -1，1:400 -1.5，1:500 -2比重减重后最低1.2/KG。 | H13: 查看报价
B14: 易·22日达卡派 | C14: {=IF(C4="海运",IFERROR(INDEX('美西22-25日达'!$B$6:$I$104,MATCH(E4,'美西22-25日达'!$A$6:$A$104,0),MATCH(F4,'美西22-25日达'!$B$5:$I$5,0)+MATCH(D4,'美西22-25日达'!$B$4:$I$4,0)-1),""),"")} -> 9.5 | D14: =IF(C14="","",INDEX('美西22-25日达'!J6:J104,MATCH(E4,'美西22-25日达'!A6:A104,0))) -> 28-33 | E14: =IF(C14="","",INDEX('美西22-25日达'!K6:K104,MATCH(E4,'美西22-25日达'!A6:A104,0))) -> - | F14: =IF(C14="","","拆派") -> 拆派 | G14: =IF(C14="","",'美西22-25日达'!A76) -> 重货优惠：1:200 -0.2; 1:250 -0.5，1:300 -1，1:400 -1.5，1:500 -2比重减重后最低1.2/KG。 | H14: 查看报价
A15: 美西17-20日达 | B15: 易·20日达卡派 | C15: {=IF(C4="海运",IFERROR(INDEX('美西17-20日达'!$L$6:$S$104,MATCH(E4,'美西17-20日达'!$A$6:$A$104,0),MATCH(F4,'美西17-20日达'!$L$5:$S$5,0)+MATCH(D4,'美西17-20日达'!$L$4:$S$4,0)-1),""),"")} -> 10.3 | D15: {=IF(C15="","",INDEX('美西17-20日达'!T6:T104,MATCH(E4,'美西17-20日达'!A6:A104,0)))} -> 29-32 | E15: {=IF(C15="","",INDEX('美西17-20日达'!U6:U104,MATCH(E4,'美西17-20日达'!A6:A104,0)))} -> - | F15: =IF(C15="","","拆派") -> 拆派 | G15: =IF(C15="","",'美西17-20日达'!A76) -> 重货优惠：1：185-0.2 1：200-0.5 1：250-0.9 1：300-1.5 1.500-2比重减重后最低1.2/KG。 | H15: 查看报价
B16: 易·17日达卡派 | C16: {=IF(C4="海运",IFERROR(INDEX('美西17-20日达'!$B$6:$I$104,MATCH(E4,'美西17-20日达'!$A$6:$A$104,0),MATCH(F4,'美西17-20日达'!$B$5:$I$5,0)+MATCH(D4,'美西17-20日达'!$B$4:$I$4,0)-1),""),"")} -> 10.9 | D16: {=IF(C16="","",INDEX('美西17-20日达'!J7:J104,MATCH(E4,'美西17-20日达'!A7:A104,0)))} -> 27-30 | E16: {=IF(C16="","",INDEX('美西17-20日达'!K7:K104,MATCH(E4,'美西17-20日达'!A7:A104,0)))} -> - | F16: =IF(C16="","","拆派") -> 拆派 | G16: =IF(C16="","",'美西17-20日达'!A76) -> 重货优惠：1：185-0.2 1：200-0.5 1：250-0.9 1：300-1.5 1.500-2比重减重后最低1.2/KG。 | H16: 查看报价
A17: 美西12-15日达 | B17: 易·15日达卡派 | C17: {=IF(C4="海运",IFERROR(INDEX('美西12-15日达'!$H$6:$O$105,MATCH(E4,'美西12-15日达'!$A$6:$A$105,0),MATCH(F4,'美西12-15日达'!$H$5:$O$5,0)+MATCH(D4,'美西12-15日达'!$H$4:$O$4,0)-1),""),"")} -> 14.2 | D17: =IF(C17="","",INDEX('美西12-15日达'!P6:P105,MATCH(E4,'美西12-15日达'!A6:A105,0))) -> 22-27 | E17: =IF(C17="","",INDEX('美西12-15日达'!Q6:Q105,MATCH(E4,'美西12-15日达'!A6:A105,0))) -> - | F17: =IF(C17="","","拆派") -> 拆派 | G17: =IF(C17="","",'美西12-15日达'!A77) -> 重货优惠：1：185-0.2 1：200-0.5 1：250-0.9 1：300-1.5 1.500-2比重减重后最低1.2/KG。 | H17: 查看报价
B18: 易·12日达卡派 | C18: {=IF(C4="海运",IFERROR(INDEX('美西12-15日达'!$B$6:$E$105,MATCH(E4,'美西12-15日达'!$A$6:$A$105,0),MATCH(F4,'美西12-15日达'!$B$5:$E$5,0)+MATCH(D4,'美西12-15日达'!$B$4:$E$4,0)-1),""),"")} -> - | D18: =IF(C18="","",INDEX('美西12-15日达'!F6:F105,MATCH(E4,'美西12-15日达'!A6:A105,0))) -> - | E18: =IF(C18="","",INDEX('美西12-15日达'!G6:G105,MATCH(E4,'美西12-15日达'!A6:A105,0))) -> - | F18: =IF(C18="","","拆派") -> 拆派 | G18: =IF(C18="","",'美西12-15日达'!A77) -> 重货优惠：1：185-0.2 1：200-0.5 1：250-0.9 1：300-1.5 1.500-2比重减重后最低1.2/KG。 | H18: 查看报价
A19: 东部稳速达 | B19: MAX/ZIM带托架/合德快提-东部稳速达 | C19: {=IF(C4="海运",IFERROR(INDEX(FBA渠道!$B$11:$J$37,MATCH(E4,FBA渠道!$A$11:$A$37,0),MATCH(F4,FBA渠道!$B$10:$J$10,0)+MATCH(D4,FBA渠道!$B$9:$J$9,0)-1),""),"")} | D19: =IF(C19="","",INDEX(FBA渠道!#REF!,MATCH(E4,FBA渠道!A11:A37,0))) | E19: =IF(C19="","","-") | F19: =IF(C19="","","拆派") | G19: =IF(C19="","",FBA渠道!A38) | H19: 查看报价
B20: ZIM不带托/合德普提/OA-东部稳速达 | C20: {=IF(C4="海运",IFERROR(INDEX(FBA渠道!$K$11:$N$37,MATCH(E4,FBA渠道!$A$11:$A$37,0),MATCH(F4,FBA渠道!$K$10:$N$10,0)+MATCH(D4,FBA渠道!$K$9:$N$9,0)-1),""),"")} | D20: =IF(C20="","",INDEX(FBA渠道!#REF!,MATCH(E4,FBA渠道!A11:A37,0))) | E20: =IF(C20="","","-") | F20: =IF(C20="","","拆派") | G20: =IF(C20="","",FBA渠道!A38) | H20: 查看报价
B21: OA/MSC/ONE统配-东部稳速达 | C21: {=IF(C4="海运",IFERROR(INDEX(FBA渠道!$O$11:$U$37,MATCH(E4,FBA渠道!$A$11:$A$37,0),MATCH(F4,FBA渠道!$O$10:$U$10,0)+MATCH(D4,FBA渠道!$O$9:$U$9,0)-1),""),"")} | D21: =IF(C21="","",INDEX(FBA渠道!V11:V37,MATCH(E4,FBA渠道!A11:A37,0))) | E21: =IF(C21="","","-") | F21: =IF(C21="","","拆派") | G21: =IF(C21="","",FBA渠道!A38) | H21: 查看报价
A22: 美西北专线 | B22: 易·奥易达卡派 （OA/ONE/MSC/HMM统配) | C22: {=IF(C4="海运",IFERROR(INDEX(美西北专线!$B$6:$I$24,MATCH(E4,美西北专线!$A$6:$A$24,0),MATCH(F4,美西北专线!$B$5:$I$5,0)+MATCH(D4,美西北专线!$B$4:$I$4,0)-1),""),"")} | D22: =IF(C22="","",INDEX(美西北专线!J6:J24,MATCH(E4,美西北专线!A6:A24,0))) | E22: =IF(C22="","","-") | F22: =IF(C22="","","拆派") | G22: =IF(C22="","",美西北专线!A25) | H22: 查看报价
B23: 西雅图专线卡派（暂停） （OA/ONE/MSC/WHL统配） | C23: {=IF(C4="海运",IFERROR(INDEX(美西北专线!$K$6:$R$24,MATCH(E4,美西北专线!$A$6:$A$24,0),MATCH(F4,美西北专线!$K$5:$R$5,0)+MATCH(D4,美西北专线!$K$4:$R$4,0)-1),""),"")} | D23: =IF(C23="","",INDEX(美西北专线!S6:S24,MATCH(E4,美西北专线!A6:A24,0))) | E23: =IF(C23="","","-") | F23: =IF(C23="","","拆派") | G23: =IF(C23="","",美西北专线!A25) | H23: 查看报价
A24: 美中芝加哥卡派 | B24: 芝加哥经济线卡派 （OA/ZIM/MSC统配） | C24: {=IF(C4="海运",IFERROR(INDEX(芝加哥专线!$B$6:$I$33,MATCH(E4,芝加哥专线!$A$6:$A$33,0),MATCH(F4,芝加哥专线!$B$5:$I$5,0)+MATCH(D4,芝加哥专线!$B$4:$I$4,0)-1),""),"")} | D24: {=IF(C24="","",INDEX(芝加哥专线!J6:J33,MATCH(E4,芝加哥专线!A6:A33,0)))} | E24: =IF(C24="","","-") | F24: =IF(C24="","","拆派") | G24: =IF(C24="","",芝加哥专线!A35) | H24: 查看报价
A25: 美中休斯顿卡派 | B25: 休斯顿经济线卡派（OA/ONE/MSC/WHL统配） | C25: {=IF(C4="海运",IFERROR(INDEX(休斯顿专线!$B$6:$I$30,MATCH(E4,休斯顿专线!$A$6:$A$30,0),MATCH(F4,休斯顿专线!$B$5:$I$5,0)+MATCH(D4,休斯顿专线!$B$4:$I$4,0)-1),""),"")} | D25: {=IF(C25="","",INDEX(休斯顿专线!J6:J30,MATCH(E4,休斯顿专线!A6:A30,0)))} | E25: =IF(C25="","","-") | F25: =IF(C25="","","拆派") | G25: =IF(C25="","",休斯顿专线!A31) | H25: 查看报价
A26: 纽约专线 | B26: 美东纽约经济线卡派 (OA/ZIM/MSC统配) | C26: {=IF(C4="海运",IFERROR(INDEX(纽约专线!$B$6:$I$49,MATCH(E4,纽约专线!$A$6:$A$49,0),MATCH(F4,纽约专线!$B$5:$I$5,0)+MATCH(D4,纽约专线!$B$4:$I$4,0)-1),""),"")} -> 7.9 | D26: =IF(C26="","",INDEX(纽约专线!J6:J49,MATCH(E4,纽约专线!A6:A49,0))) -> 40-45 | E26: =IF(C26="","","-") -> - | F26: =IF(C26="","","拆派") -> 拆派 | G26: =IF(C26="","",纽约专线!A50) -> 重货优惠：1:200 -0.2; 1:250 -0.5，1:300 -1，1:400 -1.5，1:500 -2比重减重后最低1.2/KG。 | H26: 查看报价
A27: 萨凡纳专线卡派 | B27: 萨凡纳经济线卡派 (OA/ZIM/MSC/WHL统配) | C27: {=IF(C4="海运",IFERROR(INDEX(萨凡纳专线!$B$6:$I$33,MATCH(E4,萨凡纳专线!$A$6:$A$33,0),MATCH(F4,萨凡纳专线!$B$5:$I$5,0)+MATCH(D4,萨凡纳专线!$B$4:$I$4,0)-1),""),"")} -> 7.3 | D27: {=IF(C27="","",INDEX(萨凡纳专线!J6:J33,MATCH(E4,萨凡纳专线!A6:A33,0)))} -> 40-48 | E27: =IF(C27="","","-") -> - | F27: =IF(C27="","","拆派") -> 拆派 | G27: =IF(C27="","",萨凡纳专线!A34) -> 备注：本报价为人民币报价，价格适用于普货，包含头程运费、进出口买单报关费、文件费（不含出单费）、仓库卸货费、托盘费、目的港清关、派送等费用；不包含保险费、商检费、熏蒸费、因货物问题导致的进出口海关查验费、仓库增值服务费、超期费和仓储费等，如若产生，实报实销。 | H27: 查看报价
A28: 美国海派 | B28: 易·12日达海派 | C28: {=IF($C$4="海派",IFERROR(INDEX(美国海派!$B$6:$I$8,MATCH($E$4,美国海派!$A$6:$A$8,0),MATCH($F$4,美国海派!$B$5:$I$5,0)+MATCH($D$4,美国海派!$B$4:$I$4,0)-1),""),"")} | D28: =IF(C28="","","12-13") | E28: =IF(C28="","","-") | F28: =IF(C28="","","拆派") | G28: =IF(C28="","",美国海派!$A$18) | H28: 查看报价
B29: 易·15日达海派 | C29: {=IF($C$4="海派",IFERROR(INDEX(美国海派!$J$6:$Q$8,MATCH($E$4,美国海派!$A$6:$A$8,0),MATCH($F$4,美国海派!$J$5:$Q$5,0)+MATCH($D$4,美国海派!$J$4:$Q$4,0)-1),""),"")} | D29: =IF(C29="","","13-16") | E29: =IF(C29="","","-") | F29: =IF(C29="","","拆派") | G29: =IF(C29="","",美国海派!$A$18) | H29: 查看报价
B30: 易·17日达海派 | C30: {=IF($C$4="海派",IFERROR(INDEX(美国海派!$R$6:$Y$8,MATCH($E$4,美国海派!$A$6:$A$8,0),MATCH($F$4,美国海派!$R$5:$Y$5,0)+MATCH($D$4,美国海派!$R$4:$Y$4,0)-1),""),"")} | D30: =IF(C30="","","16-19") | E30: =IF(C30="","","-") | F30: =IF(C30="","","拆派") | G30: =IF(C30="","",美国海派!$A$18) | H30: 查看报价
B31: 易·20日达海派 | C31: {=IF($C$4="海派",IFERROR(INDEX(美国海派!$B$14:$I$16,MATCH($E$4,美国海派!$A$14:$A$16,0),MATCH($F$4,美国海派!$B$13:$I$13,0)+MATCH($D$4,美国海派!$B$12:$I$12,0)-1),""),"")} | D31: =IF(C31="","","18-21") | E31: =IF(C31="","","-") | F31: =IF(C31="","","拆派") | G31: =IF(C31="","",美国海派!$A$18) | H31: 查看报价
B32: 易·22日达海派 | C32: {=IF($C$4="海派",IFERROR(INDEX(美国海派!$J$14:$Q$16,MATCH($E$4,美国海派!$A$14:$A$16,0),MATCH($F$4,美国海派!$J$13:$Q$13,0)+MATCH($D$4,美国海派!$J$12:$Q$12,0)-1),""),"")} | D32: =IF(C32="","","20-25") | E32: =IF(C32="","","-") | F32: =IF(C32="","","拆派") | G32: =IF(C32="","",美国海派!$A$18) | H32: 查看报价
B33: 易·25日达海派 | C33: {=IF($C$4="海派",IFERROR(INDEX(美国海派!$R$14:$Y$16,MATCH($E$4,美国海派!$A$14:$A$16,0),MATCH($F$4,美国海派!$R$13:$Y$13,0)+MATCH($D$4,美国海派!$R$12:$Y$12,0)-1),""),"")} | D33: =IF(C33="","","26-30") | E33: =IF(C33="","","-") | F33: =IF(C33="","","拆派") | G33: =IF(C33="","",美国海派!$A$18) | H33: 查看报价

Sheet FBA渠道
A1: =_xlfn.DISPIMG("ID_D6697A225B864C34A678052B48D4E660",1) -> =DISPIMG("ID_D6697A225B864C34A678052B48D4E660",1)
A2: 本渠道有相关的要求和限制，请务必按相关条款执行，未按要求如实申报导致的异常不做任何赔付受理： 1.本渠道只接收亚马逊标准件规格产品，标准件定义：指单件商品（ASIN）尺寸18*14*8英寸（45*35*20CM）以内并且重量低于20磅（9.07KG） 2.本渠道出货前需按我司固定模板填写发票。必须提供详细品名，货件的FBA号，PO号，以及卖家标记信息等相关信息，不然会影响货物上架； 3.本渠道使用真实收货人抬头，可以有效降低5H查验退运风险； 4.本渠道只接FBA仓库货物，沃尔玛，商卡，私人地址不可下单本渠道； 5.同渠道仓库均可合并报关； 6.本渠道直送亚马逊仓库，无法做拦截处理；
A3: FBA全美26日达（OA/ZIM，靠洛杉矶港)
A4: 区域 | B4: 东莞/中山/广州 | D4: 嘉兴/义乌 | F4: 汕头/厦门/泉州 | H4: 武汉/长沙 | J4: 参考时效(开船后)
A5: 仓库代码 | B5: 12KG+含税 | C5: 1CBM+ 不含税 | D5: 12KG+含税 | E5: 1CBM+ 不含税 | F5: 12KG+含税 | G5: 1CBM+ 不含税 | H5: 12KG+含税 | I5: 1CBM+ 不含税
A6: 全美所有FBA仓库均可走本渠道 | B6: 9.1 | C6: =B6*150 -> 1365 | D6: =B6 -> 9.1 | E6: =D6*150 -> 1365 | F6: =B6+0.2 -> 9.3 | G6: =F6*150 -> 1395 | H6: =B6+0.5 -> 9.6 | I6: =H6*150 -> 1440 | J6: 26-28自然日入仓
A7: FBA美西28日达（OA/MSC/WHL统配，靠洛杉矶港)
A8: 区域 | B8: 东莞/中山/广州 | D8: 嘉兴/义乌 | F8: 汕头/厦门/泉州 | H8: 武汉/长沙 | J8: 参考时效(开船后)
A9: 仓库代码 | B9: 12KG+含税 | C9: 1CBM+ 不含税 | D9: 12KG+含税 | E9: 1CBM+ 不含税 | F9: 12KG+含税 | G9: 1CBM+ 不含税 | H9: 12KG+含税 | I9: 1CBM+ 不含税
A10: ONT8 | B10: 5.5 | C10: =B10*150 -> 825 | D10: =B10 -> 5.5 | E10: =D10*150 -> 825 | F10: =B10+0.2 -> 5.7 | G10: =F10*150 -> 855 | H10: =B10+0.5 -> 6 | I10: =H10*150 -> 900 | J10: 25-30自然日入仓
A11: LGB8 | B11: 5.5 | C11: =B11*150 -> 825 | D11: =B11 -> 5.5 | E11: =D11*150 -> 825 | F11: =B11+0.2 -> 5.7 | G11: =F11*150 -> 855 | H11: =B11+0.5 -> 6 | I11: =H11*150 -> 900 | J11: 25-30自然日入仓
A12: SBD1 | B12: 5.5 | C12: =B12*150 -> 825 | D12: =B12 -> 5.5 | E12: =D12*150 -> 825 | F12: =B12+0.2 -> 5.7 | G12: =F12*150 -> 855 | H12: =B12+0.5 -> 6 | I12: =H12*150 -> 900 | J12: 25-30自然日入仓
A13: SMF3 | B13: 5.5 | C13: =B13*150 -> 825 | D13: =B13 -> 5.5 | E13: =D13*150 -> 825 | F13: =B13+0.2 -> 5.7 | G13: =F13*150 -> 855 | H13: =B13+0.5 -> 6 | I13: =H13*150 -> 900 | J13: 25-30自然日入仓
A14: SCK4 | B14: 5.5 | C14: =B14*150 -> 825 | D14: =B14 -> 5.5 | E14: =D14*150 -> 825 | F14: =B14+0.2 -> 5.7 | G14: =F14*150 -> 855 | H14: =B14+0.5 -> 6 | I14: =H14*150 -> 900 | J14: 25-30自然日入仓
A15: MCC1 | B15: 5.5 | C15: =B15*150 -> 825 | D15: =B15 -> 5.5 | E15: =D15*150 -> 825 | F15: =B15+0.2 -> 5.7 | G15: =F15*150 -> 855 | H15: =B15+0.5 -> 6 | I15: =H15*150 -> 900 | J15: 25-30自然日入仓
A16: GEU2 | B16: 5.5 | C16: =B16*150 -> 825 | D16: =B16 -> 5.5 | E16: =D16*150 -> 825 | F16: =B16+0.2 -> 5.7 | G16: =F16*150 -> 855 | H16: =B16+0.5 -> 6 | I16: =H16*150 -> 900 | J16: 25-30自然日入仓
A17: GEU3 | B17: 5.5 | C17: =B17*150 -> 825 | D17: =B17 -> 5.5 | E17: =D17*150 -> 825 | F17: =B17+0.2 -> 5.7 | G17: =F17*150 -> 855 | H17: =B17+0.5 -> 6 | I17: =H17*150 -> 900 | J17: 25-30自然日入仓
A18: ABQ2 | B18: 5.5 | C18: =B18*150 -> 825 | D18: =B18 -> 5.5 | E18: =D18*150 -> 825 | F18: =B18+0.2 -> 5.7 | G18: =F18*150 -> 855 | H18: =B18+0.5 -> 6 | I18: =H18*150 -> 900 | J18: 25-30自然日入仓
A19: PSC2 | B19: 5.5 | C19: =B19*150 -> 825 | D19: =B19 -> 5.5 | E19: =D19*150 -> 825 | F19: =B19+0.2 -> 5.7 | G19: =F19*150 -> 855 | H19: =B19+0.5 -> 6 | I19: =H19*150 -> 900 | J19: 25-30自然日入仓
A20: POC1 | B20: 5.5 | C20: =B20*150 -> 825 | D20: =B20 -> 5.5 | E20: =D20*150 -> 825 | F20: =B20+0.2 -> 5.7 | G20: =F20*150 -> 855 | H20: =B20+0.5 -> 6 | I20: =H20*150 -> 900 | J20: 25-30自然日入仓
A21: POC2 | B21: 5.5 | C21: =B21*150 -> 825 | D21: =B21 -> 5.5 | E21: =D21*150 -> 825 | F21: =B21+0.2 -> 5.7 | G21: =F21*150 -> 855 | H21: =B21+0.5 -> 6 | I21: =H21*150 -> 900 | J21: 25-30自然日入仓
... A25: TCY2 | B25: 5.5 | C25: =B25*150 -> 825 | D25: =B25 -> 5.5 | E25: =D25*150 -> 825 | F25: =B25+0.2 -> 5.7 | G25: =F25*150 -> 855 | H25: =B25+0.5 -> 6 | I25: =H25*150 -> 900 | J25: 25-30自然日入仓
A26: FBA美中南28日达（OA/MSC/WHL统配，靠洛杉矶港)
A27: 区域 | B27: 东莞/中山/广州 | D27: 嘉兴/义乌 | F27: 汕头/厦门/泉州 | H27: 武汉/长沙 | J27: 参考时效(开船后)
A28: 仓库代码/起收量 | B28: 12KG+含税 | C28: 1CBM+ 不含税 | D28: 12KG+含税 | E28: 1CBM+ 不含税 | F28: 12KG+含税 | G28: 1CBM+ 不含税 | H28: 12KG+含税 | I28: 1CBM+ 不含税
A29: LAX9 | B29: 5.9 | C29: =B29*150 -> 885 | D29: =B29 -> 5.9 | E29: =D29*150 -> 885 | F29: =B29+0.2 -> 6.1 | G29: =F29*150 -> 915 | H29: =B29+0.5 -> 6.4 | I29: =H29*150 -> 960 | J29: 25-30自然日入仓
A30: GYR2 | B30: 5.9 | C30: =B30*150 -> 885 | D30: =B30 -> 5.9 | E30: =D30*150 -> 885 | F30: =B30+0.2 -> 6.1 | G30: =F30*150 -> 915 | H30: =B30+0.5 -> 6.4 | I30: =H30*150 -> 960 | J30: 25-30自然日入仓
A31: GYR3 | B31: 5.9 | C31: =B31*150 -> 885 | D31: =B31 -> 5.9 | E31: =D31*150 -> 885 | F31: =B31+0.2 -> 6.1 | G31: =F31*150 -> 915 | H31: =B31+0.5 -> 6.4 | I31: =H31*150 -> 960 | J31: 25-30自然日入仓
A32: PSP3 | B32: 5.9 | C32: =B32*150 -> 885 | D32: =B32 -> 5.9 | E32: =D32*150 -> 885 | F32: =B32+0.2 -> 6.1 | G32: =F32*150 -> 915 | H32: =B32+0.5 -> 6.4 | I32: =H32*150 -> 960 | J32: 25-30自然日入仓
A33: FTW1 | B33: 5.9 | C33: =B33*150 -> 885 | D33: =B33 -> 5.9 | E33: =D33*150 -> 885 | F33: =B33+0.2 -> 6.1 | G33: =F33*150 -> 915 | H33: =B33+0.5 -> 6.4 | I33: =H33*150 -> 960 | J33: 25-30自然日入仓
A34: IAH3 | B34: 5.9 | C34: =B34*150 -> 885 | D34: =B34 -> 5.9 | E34: =D34*150 -> 885 | F34: =B34+0.2 -> 6.1 | G34: =F34*150 -> 915 | H34: =B34+0.5 -> 6.4 | I34: =H34*150 -> 960 | J34: 25-30自然日入仓
A35: FBA美中北40日达（OA/MSC/WHL统配，靠纽约港)
A36: 区域 | B36: 东莞/中山/广州 | D36: 嘉兴/义乌 | F36: 汕头/厦门/泉州 | H36: 武汉/长沙 | J36: 参考时效(开船后)
A37: 仓库代码/起收量 | B37: 12KG+含税 | C37: 1CBM+ 不含税 | D37: 12KG+含税 | E37: 1CBM+ 不含税 | F37: 12KG+含税 | G37: 1CBM+ 不含税 | H37: 12KG+含税 | I37: 1CBM+ 不含税
A38: LAS1 | B38: 6.4 | C38: =B38*150 -> 960 | D38: =B38 -> 6.4 | E38: =D38*150 -> 960 | F38: =B38+0.2 -> 6.6 | G38: =F38*150 -> 990 | H38: =B38+0.5 -> 6.9 | I38: =H38*150 -> 1035 | J38: 40-45自然日入仓
A39: VGT2 | B39: 6.4 | C39: =B39*150 -> 960 | D39: =B39 -> 6.4 | E39: =D39*150 -> 960 | F39: =B39+0.2 -> 6.6 | G39: =F39*150 -> 990 | H39: =B39+0.5 -> 6.9 | I39: =H39*150 -> 1035 | J39: 40-45自然日入仓
A40: FWA4 | B40: 6.4 | C40: =B40*150 -> 960 | D40: =B40 -> 6.4 | E40: =D40*150 -> 960 | F40: =B40+0.2 -> 6.6 | G40: =F40*150 -> 990 | H40: =B40+0.5 -> 6.9 | I40: =H40*150 -> 1035 | J40: 40-45自然日入仓
A41: MDW2 | B41: 6.4 | C41: =B41*150 -> 960 | D41: =B41 -> 6.4 | E41: =D41*150 -> 960 | F41: =B41+0.2 -> 6.6 | G41: =F41*150 -> 990 | H41: =B41+0.5 -> 6.9 | I41: =H41*150 -> 1035 | J41: 40-45自然日入仓
A42: SWF2 | B42: 6.4 | C42: =B42*150 -> 960 | D42: =B42 -> 6.4 | E42: =D42*150 -> 960 | F42: =B42+0.2 -> 6.6 | G42: =F42*150 -> 990 | H42: =B42+0.5 -> 6.9 | I42: =H42*150 -> 1035 | J42: 40-45自然日入仓
A43: RFD2 | B43: 6.4 | C43: =B43*150 -> 960 | D43: =B43 -> 6.4 | E43: =D43*150 -> 960 | F43: =B43+0.2 -> 6.6 | G43: =F43*150 -> 990 | H43: =B43+0.5 -> 6.9 | I43: =H43*150 -> 1035 | J43: 40-45自然日入仓
...

Sheet 美西整柜直送
A1: =_xlfn.DISPIMG("ID_D6697A225B864C34A678052B48D4E660",1) -> =DISPIMG("ID_D6697A225B864C34A678052B48D4E660",1)
A2: 渠道名称 | B2: 美国整柜直送
A3: 船司 | B3: OA/MSC/ONE/WHL/SML船司，可能需要一周集货时间
A4: 交货仓库 | B4: 东莞/中山/广州 | D4: 嘉兴/义乌 | F4: 汕头/厦门/泉州 | H4: 武汉/长沙 | J4: 参考时效 （开船后自然日） | K4: 备注
A5: 仓库代码 | B5: 12KG+含税 | C5: 0.5CBM+不含税 | D5: 12KG+含税 | E5: 0.5CBM+不含税 | F5: 12KG+含税 | G5: 0.5CBM+不含税 | H5: 12KG+含税 | I5: 0.5CBM+不含税
A6: ONT8 | B6: 5.26 | C6: =B6*150 -> 789 | D6: =B6 -> 5.26 | E6: =D6*150 -> 789 | F6: =B6+0.2 -> 5.46 | G6: =F6*150 -> 819 | H6: =B6+0.5 -> 5.76 | I6: =H6*150 -> 864 | J6: 开船后28-30自然日入仓，无时效赔付） | K6: 此渠道出货后不接受拦截； 直送渠道，单件实重不超22.3KG，尺寸在 63.5*63.5*91厘米之内
A7: LGB8 | B7: 5.26 | C7: =B7*150 -> 789 | D7: =B7 -> 5.26 | E7: =D7*150 -> 789 | F7: =B7+0.2 -> 5.46 | G7: =F7*150 -> 819 | H7: =B7+0.5 -> 5.76 | I7: =H7*150 -> 864
A8: LAX9 | B8: 5.26 | C8: =B8*150 -> 789 | D8: =B8 -> 5.26 | E8: =D8*150 -> 789 | F8: =B8+0.2 -> 5.46 | G8: =F8*150 -> 819 | H8: =B8+0.5 -> 5.76 | I8: =H8*150 -> 864
A9: SBD1 | B9: 5.26 | C9: =B9*150 -> 789 | D9: =B9 -> 5.26 | E9: =D9*150 -> 789 | F9: =B9+0.2 -> 5.46 | G9: =F9*150 -> 819 | H9: =B9+0.5 -> 5.76 | I9: =H9*150 -> 864
A10: POC1 | B10: 5.46 | C10: =B10*150 -> 819 | D10: =B10 -> 5.46 | E10: =D10*150 -> 819 | F10: =B10+0.2 -> 5.66 | G10: =F10*150 -> 849 | H10: =B10+0.5 -> 5.96 | I10: =H10*150 -> 894
A11: POC3 | B11: 5.46 | C11: =B11*150 -> 819 | D11: =B11 -> 5.46 | E11: =D11*150 -> 819 | F11: =B11+0.2 -> 5.66 | G11: =F11*150 -> 849 | H11: =B11+0.5 -> 5.96 | I11: =H11*150 -> 894
A12: LAS1 | B12: 5.86 | C12: =B12*150 -> 879 | D12: =B12 -> 5.86 | E12: =D12*150 -> 879 | F12: =B12+0.2 -> 6.06 | G12: =F12*150 -> 909 | H12: =B12+0.5 -> 6.36 | I12: =H12*150 -> 954
A13: VGT2 | B13: 5.86 | C13: =B13*150 -> 879 | D13: =B13 -> 5.86 | E13: =D13*150 -> 879 | F13: =B13+0.2 -> 6.06 | G13: =F13*150 -> 909 | H13: =B13+0.5 -> 6.36 | I13: =H13*150 -> 954
A14: GYR2 | B14: 5.96 | C14: =B14*150 -> 894 | D14: =B14 -> 5.96 | E14: =D14*150 -> 894 | F14: =B14+0.2 -> 6.16 | G14: =F14*150 -> 924 | H14: =B14+0.5 -> 6.46 | I14: =H14*150 -> 969
A15: GYR3 | B15: 5.96 | C15: =B15*150 -> 894 | D15: =B15 -> 5.96 | E15: =D15*150 -> 894 | F15: =B15+0.2 -> 6.16 | G15: =F15*150 -> 924 | H15: =B15+0.5 -> 6.46 | I15: =H15*150 -> 969
A16: GEU2 | B16: 5.86 | C16: =B16*150 -> 879 | D16: =B16 -> 5.86 | E16: =D16*150 -> 879 | F16: =B16+0.2 -> 6.06 | G16: =F16*150 -> 909 | H16: =B16+0.5 -> 6.36 | I16: =H16*150 -> 954
A17: GEU3 | B17: 5.86 | C17: =B17*150 -> 879 | D17: =B17 -> 5.86 | E17: =D17*150 -> 879 | F17: =B17+0.2 -> 6.06 | G17: =F17*150 -> 909 | H17: =B17+0.5 -> 6.36 | I17: =H17*150 -> 954
A18: SMF3（奥克兰） | B18: 5.86 | C18: =B18*150 -> 879 | D18: =B18 -> 5.86 | E18: =D18*150 -> 879 | F18: =B18+0.2 -> 6.06 | G18: =F18*150 -> 909 | H18: =B18+0.5 -> 6.36 | I18: =H18*150 -> 954
... A20: ABQ2 | B20: 7 | C20: =B20*150 -> 1050 | D20: =B20 -> 7 | E20: =D20*150 -> 1050 | F20: =B20+0.2 -> 7.2 | G20: =F20*150 -> 1080 | H20: =B20+0.5 -> 7.5 | I20: =H20*150 -> 1125
A21: PSC2（西雅图）暂停 | B21: / | C21: / | D21: / | E21: / | F21: / | G21: / | H21: / | I21: /
A22: 重货优惠：1:200 -0.2; 1:250 -0.5，1:300 -1，1:400 -1.2 1:500 -1.5 比重减重后最低1.2/KG。
A23: 备注：本报价为人民币报价，价格适用于普货，包含头程运费、进出口买单报关费、文件费（不含出单费）、仓库卸货费、托盘费、目的港清关、派送等费用；不包含保险费、商检费、熏蒸费、因货物问题导致的进出口海关查验费、仓库增值服务费、超期费和仓储费等，如若产生，实报实销。
A24: 计重标准 | B24: 重量转体积：1CBM=334KG; 体积转重量：1CBM=167KG；托盘，木架，木箱等非纸箱货物出货，计费重需*1.1倍
A25: 报关费&续页费 | B25: 报关费：RMB220, 超6个品名续页费：RMB50/页（即第7个起算，每6个品名一页）
A26: 超品名费 | B26: 每一票单超过五个品名的，收取RMB30/个
A27: 商检费 & 熏蒸费 | B27: 单询
A28: 提单费（如需） | B28: RMB300/BILL
A29: 不含税渠道进口申报要求 | B29: 不含关税渠道，如遇国内和目的港查验，按体积比例承担相应的查验费； 不包税渠道最低申报不低于120USD/CBM；
A30: 产品附加 | B30: 箱包类、行李箱、收纳箱、包包、鞋子、服装等纺织品类、FDA申报类产品+0.5元/KG
B31: 木制品 无单证600/票 单证+RMB800/票
A32: 本渠道拒收产品 | B32: 仿牌、液体、粉末、食品、药品、易燃易爆、古董、货币等国家禁止出口及航空公司禁运物品
B33: 纯电池，移动电源，医疗激光产品，太阳能 （大于10*10），动植物， 化妆品，医疗类产品，铅笔，有医疗作用的牙刷
B34: 侵权产品：蓝牙标及包装有蓝牙字样及标识产品
B35: 反倾销产品：请查看附件
A36: 申报要求 | B36: 如实申报，单货一致；如有需要需如实提供每个产品对应的产品图片和有售价的真实销售链接，如新品链接没有售价，需要提供亚马逊后台定价截图；如因客户低申报或申报不符（海关编码和实物不符，数量不一致等）产生的相关查验费、仓租、调高后的税金、海关罚金需由客户承担.

Sheet 美国海派
A1: =_xlfn.DISPIMG("ID_D6697A225B864C34A678052B48D4E660",1) -> =DISPIMG("ID_D6697A225B864C34A678052B48D4E660",1)
A2: 下单渠道 | B2: 易·12日达海派 | J2: 易·15日达海派 | R2: 易·17日达海派
A3: 使用船司 | B3: 美森正班CLX | J3: 美森正班CLX | R3: EXX/以星带托架/合德快提统配
A4: 交货仓库 | B4: 东莞/中山/广州 | D4: 嘉兴/义乌 | F4: 汕头/厦门/泉州 | H4: 武汉/长沙 | J4: 东莞/中山/广州 | L4: 嘉兴/义乌 | N4: 汕头/厦门/泉州 | P4: 武汉/长沙 | R4: 东莞/中山/广州 | T4: 嘉兴/义乌 | V4: 汕头/厦门/泉州 | X4: 武汉/长沙
A5: 邮编分区/起收量 | B5: 12-50KG | C5: 50KG+ | D5: 12-50KG | E5: 50KG+ | F5: 12-50KG | G5: 50KG+ | H5: 12-50KG | I5: 50KG+ | J5: 12-50KG | K5: 50KG+ | L5: 12-50KG | M5: 50KG+ | N5: 12-50KG | O5: 50KG+ | P5: 12-50KG | Q5: 50KG+ | R5: 12-50KG | S5: 50KG+ | T5: 12-50KG | U5: 50KG+ | V5: 12-50KG | W5: 50KG+ | X5: 12-50KG | Y5: 50KG+
A6: 美国西岸(邮编8,9开头) | B6: 21.1 | C6: 18.1 | D6: 20.6 | E6: 17.6 | F6: 21.3 | G6: 18.3 | H6: 21.6 | I6: 18.6 | J6: 18.1 | K6: 15.1 | L6: 17.6 | M6: 14.6 | N6: 18.3 | O6: 15.3 | P6: 18.6 | Q6: 15.6 | R6: 14.5 | S6: 11.5 | T6: 14.5 | U6: 11.5 | V6: 14.7 | W6: 11.7 | X6: 15 | Y6: 12
A7: 美国中部(邮编4,5,6,7开头) | B7: 22.6 | C7: 19.6 | D7: 22.1 | E7: 19.1 | F7: 22.8 | G7: 19.8 | H7: 23.1 | I7: 20.1 | J7: 19.6 | K7: 16.6 | L7: 19.1 | M7: 16.1 | N7: 19.8 | O7: 16.8 | P7: 20.1 | Q7: 17.1 | R7: 16 | S7: 13 | T7: 16 | U7: 13 | V7: 16.2 | W7: 13.2 | X7: 16.5 | Y7: 13.5
A8: 美国东岸(邮编0,1,2,3开头) | B8: 23.6 | C8: 20.6 | D8: 23.1 | E8: 20.1 | F8: 23.8 | G8: 20.8 | H8: 24.1 | I8: 21.1 | J8: 20.6 | K8: 17.6 | L8: 20.1 | M8: 17.1 | N8: 20.8 | O8: 17.8 | P8: 21.1 | Q8: 18.1 | R8: 17.5 | S8: 14 | T8: 17.5 | U8: 14 | V8: 17.7 | W8: 14.2 | X8: 18 | Y8: 14.5
A9: 参考时效 | B9: 开船后第二天起算12-13天提取，超13天（不含)不提取，每个工作日赔1.5元/KG，时效延误最高赔偿6/KG | J9: 开船后13-16天提取，超过17天不提取，每个工作日赔0.5元/kg，直到运费抵完。 | R9: 开船后16-19天提取，超过20天不提取，每个工作日赔0.5元/kg，直到运费抵完。
A10: 下单渠道 | B10: 易·20日达海派 | J10: 易·22日达海派 | R10: 易·25日达海派
A11: 使用船司 | B11: 以星不带托架/合德普提/SEA3/CEN | J11: COSCO/OA | R11: OA/MSC/ONE/WHL/HMM/TSL普船统配
A12: 交货仓库 | B12: 东莞/中山/广州 | D12: 嘉兴/义乌 | F12: 汕头/厦门/泉州 | H12: 武汉/长沙 | J12: 东莞/中山/广州 | L12: 嘉兴/义乌 | N12: 汕头/厦门/泉州 | P12: 武汉/长沙 | R12: 东莞/中山/广州 | T12: 嘉兴/义乌 | V12: 汕头/厦门/泉州 | X12: 武汉/长沙
A13: 邮编分区/起收量 | B13: 12-50KG | C13: 50KG+ | D13: 12-50KG | E13: 50KG+ | F13: 12-50KG | G13: 50KG+ | H13: 12-50KG | I13: 50KG+ | J13: 12-50KG | K13: 50KG+ | L13: 12-50KG | M13: 50KG+ | N13: 12-50KG | O13: 50KG+ | P13: 12-50KG | Q13: 50KG+ | R13: 12-50KG | S13: 50KG+ | T13: 12-50KG | U13: 50KG+ | V13: 12-50KG | W13: 50KG+ | X13: 12-50KG | Y13: 50KG+
A14: 美国西岸(邮编8,9开头) | B14: 14 | C14: 11 | D14: 14 | E14: 11 | F14: 14.2 | G14: 11.2 | H14: 14.5 | I14: 11.5 | J14: 13 | K14: 10 | L14: 13 | M14: 10 | N14: 13.2 | O14: 10.2 | P14: 13.5 | Q14: 10.5 | R14: 12.6 | S14: 9.6 | T14: 12.8 | U14: 9.8 | V14: 13 | W14: 10 | X14: 13.3 | Y14: 10.3
A15: 美国中部(邮编4,5,6,7开头) | B15: 15.5 | C15: 12.5 | D15: 15.5 | E15: 12.5 | F15: 15.7 | G15: 12.7 | H15: 16 | I15: 13 | J15: 14.5 | K15: 11.5 | L15: 14.5 | M15: 11.5 | N15: 14.7 | O15: 11.7 | P15: 15 | Q15: 12 | R15: 14.1 | S15: 11.1 | T15: 14.3 | U15: 11.3 | V15: 14.5 | W15: 11.5 | X15: 14.8 | Y15: 11.8
A16: 美国东岸(邮编0,1,2,3开头) | B16: 16.5 | C16: 13.5 | D16: 16.5 | E16: 13.5 | F16: 16.7 | G16: 13.7 | H16: 17 | I16: 14 | J16: 15.5 | K16: 12.5 | L16: 15.5 | M16: 12.5 | N16: 15.7 | O16: 12.7 | P16: 16 | Q16: 13 | R16: 15.1 | S16: 12.1 | T16: 15.3 | U16: 12.3 | V16: 15.5 | W16: 12.5 | X16: 15.8 | Y16: 12.8
A17: 参考时效 | B17: 开船后18-21天提取，超过22天不提取，每个工作日赔0.5元/kg，直到运费抵完。 | J17: 开船后20-25天内提取，超过26天不提取，每个工作日赔0.5元/kg，直到运费抵完。 | R17: 开船后26-30天左右提取， 统配渠道无时效赔付
A18: 重货优惠：1:200 -0.2; 1:250 -0.5，1:300 -1，1:400 -1.5，1:500 -2比重减重后最低1.2/KG。
A19: 备注：本报价为人民币报价，价格适用于普货，包含头程运费、进出口买单报关费、文件费（不含出单费）、仓库卸货费、托盘费、目的港清关、派送等费用；不包含保险费、商检费、熏蒸费、因货物问题导致的进出口海关查验费、仓库增值服务费、超期费和仓储费等，如若产生，实报实销。
A20: UPS附加费用如下：
A21: 1.单件计费重量不得低于12KG，单件重量低于12KG按照12KG计费；货物重量的计算方式：长*宽*高CM/6000，实重与材积重取大值为计费重；
A22: 2.单边超120CM，第二长边超76CM，围长需在265CM≤（1长+2宽+2高）范围内 | N22: 加收180元/件，如多项超过需叠加
A23: 3.超长：265CM＜ 长+[2*(宽+高)]≤ 315CM | N23: 加收180元/件
A24: 4.超重：22KG＜实际重量＜40KG | N24: 加收235元/件
A25: 5.单件40KG以上，单边超230CM，或周长超315CM | N25: 拒收
A26: 6.私人地址和商业地址（非亚马逊地址） | N26: 加收1元/KG
A27: 7.私人住宅地址 | N27: 加收50元/箱
A28: 8.UPS偏远地区另需加收偏远费， UPS私人地址:UPS偏远RMB40/件，超偏远45/件。 | N28: 偏远加收40元/箱，超级偏远加45/箱 （如同时为私人地址费用将叠加收取）
A29: 9.提供UPS签收单 | N29: RMB35/件
A30: 10.如我司以打单的情况下更换派送方式以及退货，我司收取删单费 | N30: 1USD/件，最低消费100RMB/票
A31: 11.打单后退货需收操作费，如已装柜不接受退件 | N31: 加收100元/票
A32: 地址派送范围仅限于美国48洲,邮箱BOX,军方地址不收,及各岛屿美国不收、不接收邮编：006-009 PUERTO RICO AND VIRGIN LSLANDS 波多黎各、维尔京群岛，966-969 HAWAIIAND GUAM 夏威夷、关岛 995-999 ALASKA 阿拉斯加等！) | N32: 无服务地址
A33: 超品名费 | N33: 每一票单超过五个品名的，收取RMB30/个
A34: 产品附加 | E34: 箱包类、行李箱、收纳箱、包包、鞋子、服装等纺织品类、FDA申报类产品+0.5元/KG
E35: 木制品 无单证600/票 单证+RMB800/票
A36: 本渠道拒收产品 | E36: 仿牌、液体、粉末、食品、药品、易燃易爆、古董、货币等国家禁止出口及航空公司禁运物品
E37: 纯电池，移动电源，激光产品，太阳能 （大于10*10），动植物， 化妆品，医疗类产品，铅笔，有医疗作用的牙刷
E38: 侵权产品：蓝牙标及包装有蓝牙字样及标识产品
E39: 反倾销产品：请查看附件
A40: 申报要求 | E40: 如实申报，单货一致；如有需要需如实提供每个产品对应的产品图片和有售价的真实销售链接，如新品链接没有售价，需要提供亚马逊后台定价截图；如因客户低申报或申报不符（海关编码和实物不符，数量不一致等）产生的相关查验费、仓租、调高后的税金、海关罚金需由客户承担；

Sheet 美西12-15日达
A1: =_xlfn.DISPIMG("ID_D6697A225B864C34A678052B48D4E660",1) -> =DISPIMG("ID_D6697A225B864C34A678052B48D4E660",1)
A2: 渠道名称 | B2: 易·12日达卡派 | H2: 易·15日达卡派
A3: 使用船司 | B3: 美森正班CLX | H3: 美森正班CLX
A4: 交货仓库 | B4: 东莞/中山/广州 | C4: 嘉兴/义乌 | D4: 汕头/厦门/泉州 | E4: 武汉/长沙 | F4: 参考时效 （开船后自然日） | G4: 理赔时效 以工作日计赔付 1元/kg 最高赔偿5元/KG | H4: 东莞/中山/广州 | J4: 嘉兴/义乌 | L4: 汕头/厦门/泉州 | N4: 武汉/长沙 | P4: 参考时效 （开船后自然日） | Q4: 理赔时效 以工作日计赔付 0.5元/kg
A5: 仓库代码 | B5: 12KG+含税 | C5: 12KG+含税 | D5: 12KG+含税 | E5: 12KG+含税 | H5: 12KG+含税 | I5: 0.5CBM+不含税 | J5: 12KG+含税 | K5: 0.5CBM+不含税 | L5: 12KG+含税 | M5: 0.5CBM+不含税 | N5: 12KG+含税 | O5: 0.5CBM+不含税
A6: 海外仓自提 一件代发头程 | B6: 13.9 | C6: =B6-0.5 -> 13.4 | D6: =B6+0.2 -> 14.1 | E6: =B6+0.5 -> 14.4 | F6: 12自然日 | G6: 超13自然日 | H6: 10.9 | I6: =H6*165 -> 1798.5 | J6: =H6-0.5 -> 10.4 | K6: =J6*165 -> 1716 | L6: =H6+0.2 -> 11.1 | M6: =L6*165 -> 1831.5 | N6: =H6+0.5 -> 11.4 | O6: =N6*165 -> 1881 | P6: 13-15 | Q6: 超16自然日
A7: ONT8 | B7: 13.9 | C7: =B7-0.5 -> 13.4 | D7: =B7+0.2 -> 14.1 | E7: =B7+0.5 -> 14.4 | F7: 12自然日 | G7: 超13自然日 | H7: 10.9 | I7: =H7*165 -> 1798.5 | J7: =H7-0.5 -> 10.4 | K7: =J7*165 -> 1716 | L7: =H7+0.2 -> 11.1 | M7: =L7*165 -> 1831.5 | N7: =H7+0.5 -> 11.4 | O7: =N7*165 -> 1881 | P7: 13-15 | Q7: 超16自然日
A8: LGB8 | B8: 13.9 | C8: =B8-0.5 -> 13.4 | D8: =B8+0.2 -> 14.1 | E8: =B8+0.5 -> 14.4 | F8: 12自然日 | G8: 超13自然日 | H8: 10.9 | I8: =H8*165 -> 1798.5 | J8: =H8-0.5 -> 10.4 | K8: =J8*165 -> 1716 | L8: =H8+0.2 -> 11.1 | M8: =L8*165 -> 1831.5 | N8: =H8+0.5 -> 11.4 | O8: =N8*165 -> 1881 | P8: 13-15 | Q8: 超16自然日
A9: LAX9 | B9: 13.9 | C9: =B9-0.5 -> 13.4 | D9: =B9+0.2 -> 14.1 | E9: =B9+0.5 -> 14.4 | F9: 12自然日 | G9: 超13自然日 | H9: 10.9 | I9: =H9*165 -> 1798.5 | J9: =H9-0.5 -> 10.4 | K9: =J9*165 -> 1716 | L9: =H9+0.2 -> 11.1 | M9: =L9*165 -> 1831.5 | N9: =H9+0.5 -> 11.4 | O9: =N9*165 -> 1881 | P9: 13-15 | Q9: 超16自然日
A10: SBD1 | B10: 13.9 | C10: =B10-0.5 -> 13.4 | D10: =B10+0.2 -> 14.1 | E10: =B10+0.5 -> 14.4 | F10: 12自然日 | G10: 超13自然日 | H10: 10.9 | I10: =H10*165 -> 1798.5 | J10: =H10-0.5 -> 10.4 | K10: =J10*165 -> 1716 | L10: =H10+0.2 -> 11.1 | M10: =L10*165 -> 1831.5 | N10: =H10+0.5 -> 11.4 | O10: =N10*165 -> 1881 | P10: 13-15 | Q10: 超16自然日
A11: PSP3 | B11: - | C11: - | D11: - | E11: - | F11: - | G11: - | H11: 11.2 | I11: =H11*165 -> 1848 | J11: =H11-0.5 -> 10.7 | K11: =J11*165 -> 1765.5 | L11: =H11+0.2 -> 11.4 | M11: =L11*165 -> 1881 | N11: =H11+0.5 -> 11.7 | O11: =N11*165 -> 1930.5 | P11: 14-16 | Q11: -
A12: POC1 | B12: - | C12: - | D12: - | E12: - | F12: - | G12: - | H12: 11.2 | I12: =H12*165 -> 1848 | J12: =H12-0.5 -> 10.7 | K12: =J12*165 -> 1765.5 | L12: =H12+0.2 -> 11.4 | M12: =L12*165 -> 1881 | N12: =H12+0.5 -> 11.7 | O12: =N12*165 -> 1930.5 | P12: 14-16 | Q12: -
A13: POC2 | B13: - | C13: - | D13: - | E13: - | F13: - | G13: - | H13: 11.2 | I13: =H13*165 -> 1848 | J13: =H13-0.5 -> 10.7 | K13: =J13*165 -> 1765.5 | L13: =H13+0.2 -> 11.4 | M13: =L13*165 -> 1881 | N13: =H13+0.5 -> 11.7 | O13: =N13*165 -> 1930.5 | P13: 14-16 | Q13: -
A14: POC3 | B14: - | C14: - | D14: - | E14: - | F14: - | G14: - | H14: 11.2 | I14: =H14*165 -> 1848 | J14: =H14-0.5 -> 10.7 | K14: =J14*165 -> 1765.5 | L14: =H14+0.2 -> 11.4 | M14: =L14*165 -> 1881 | N14: =H14+0.5 -> 11.7 | O14: =N14*165 -> 1930.5 | P14: 14-16 | Q14: -
A15: LAX2T(沃尔玛) | B15: - | C15: - | D15: - | E15: - | F15: - | G15: - | H15: 11.2 | I15: =H15*165 -> 1848 | J15: =H15-0.5 -> 10.7 | K15: =J15*165 -> 1765.5 | L15: =H15+0.2 -> 11.4 | M15: =L15*165 -> 1881 | N15: =H15+0.5 -> 11.7 | O15: =N15*165 -> 1930.5 | P15: 14-16 | Q15: -
A16: IUSP | B16: - | C16: - | D16: - | E16: - | F16: - | G16: - | H16: 11.2 | I16: =H16*165 -> 1848 | J16: =H16-0.5 -> 10.7 | K16: =J16*165 -> 1765.5 | L16: =H16+0.2 -> 11.4 | M16: =L16*165 -> 1881 | N16: =H16+0.5 -> 11.7 | O16: =N16*165 -> 1930.5 | P16: 14-16 | Q16: -
A17: IUSJ | B17: - | C17: - | D17: - | E17: - | F17: - | G17: - | H17: 11.2 | I17: =H17*165 -> 1848 | J17: =H17-0.5 -> 10.7 | K17: =J17*165 -> 1765.5 | L17: =H17+0.2 -> 11.4 | M17: =L17*165 -> 1881 | N17: =H17+0.5 -> 11.7 | O17: =N17*165 -> 1930.5 | P17: 14-16 | Q17: -
A18: IUTI | B18: - | C18: - | D18: - | E18: - | F18: - | G18: - | H18: 11.2 | I18: =H18*165 -> 1848 | J18: =H18-0.5 -> 10.7 | K18: =J18*165 -> 1765.5 | L18: =H18+0.2 -> 11.4 | M18: =L18*165 -> 1881 | N18: =H18+0.5 -> 11.7 | O18: =N18*165 -> 1930.5 | P18: 14-16 | Q18: -
A19: IUSW | B19: - | C19: - | D19: - | E19: - | F19: - | G19: - | H19: 11.2 | I19: =H19*165 -> 1848 | J19: =H19-0.5 -> 10.7 | K19: =J19*165 -> 1765.5 | L19: =H19+0.2 -> 11.4 | M19: =L19*165 -> 1881 | N19: =H19+0.5 -> 11.7 | O19: =N19*165 -> 1930.5 | P19: 14-16 | Q19: -
A20: SNA4 | B20: - | C20: - | D20: - | E20: - | F20: - | G20: - | H20: 11.6 | I20: =H20*165 -> 1914 | J20: =H20-0.5 -> 11.1 | K20: =J20*165 -> 1831.5 | L20: =H20+0.2 -> 11.8 | M20: =L20*165 -> 1947 | N20: =H20+0.5 -> 12.1 | O20: =N20*165 -> 1996.5 | P20: 15-17 | Q20: -
A21: XLX7 | B21: - | C21: - | D21: - | E21: - | F21: - | G21: - | H21: 11.6 | I21: =H21*165 -> 1914 | J21: =H21-0.5 -> 11.1 | K21: =J21*165 -> 1831.5 | L21: =H21+0.2 -> 11.8 | M21: =L21*165 -> 1947 | N21: =H21+0.5 -> 12.1 | O21: =N21*165 -> 1996.5 | P21: 15-17 | Q21: -
A22: LAS1 | B22: - | C22: - | D22: - | E22: - | F22: - | G22: - | H22: 11.6 | I22: =H22*165 -> 1914 | J22: =H22-0.5 -> 11.1 | K22: =J22*165 -> 1831.5 | L22: =H22+0.2 -> 11.8 | M22: =L22*165 -> 1947 | N22: =H22+0.5 -> 12.1 | O22: =N22*165 -> 1996.5 | P22: 15-17 | Q22: -
A23: VGT2 | B23: - | C23: - | D23: - | E23: - | F23: - | G23: - | H23: 11.6 | I23: =H23*165 -> 1914 | J23: =H23-0.5 -> 11.1 | K23: =J23*165 -> 1831.5 | L23: =H23+0.2 -> 11.8 | M23: =L23*165 -> 1947 | N23: =H23+0.5 -> 12.1 | O23: =N23*165 -> 1996.5 | P23: 15-17 | Q23: -
A24: SMF3 | H24: 11.6 | I24: =H24*165 -> 1914 | J24: =H24-0.5 -> 11.1 | K24: =J24*165 -> 1831.5 | L24: =H24+0.2 -> 11.8 | M24: =L24*165 -> 1947 | N24: =H24+0.5 -> 12.1 | O24: =N24*165 -> 1996.5 | P24: 15-17 | Q24: 超21自然日
A25: SCK4 | B25: - | C25: - | D25: - | E25: - | F25: - | G25: - | H25: 11.6 | I25: =H25*165 -> 1914 | J25: =H25-0.5 -> 11.1 | K25: =J25*165 -> 1831.5 | L25: =H25+0.2 -> 11.8 | M25: =L25*165 -> 1947 | N25: =H25+0.5 -> 12.1 | O25: =N25*165 -> 1996.5 | P25: 15-17 | Q25: 超21自然日
A26: GEU2 | B26: - | C26: - | D26: - | E26: - | F26: - | G26: - | H26: 11.6 | I26: =H26*165 -> 1914 | J26: =H26-0.5 -> 11.1 | K26: =J26*165 -> 1831.5 | L26: =H26+0.2 -> 11.8 | M26: =L26*165 -> 1947 | N26: =H26+0.5 -> 12.1 | O26: =N26*165 -> 1996.5 | P26: 15-17 | Q26: 超21自然日
A27: GEU3 | B27: - | C27: - | D27: - | E27: - | F27: - | G27: - | H27: 11.6 | I27: =H27*165 -> 1914 | J27: =H27-0.5 -> 11.1 | K27: =J27*165 -> 1831.5 | L27: =H27+0.2 -> 11.8 | M27: =L27*165 -> 1947 | N27: =H27+0.5 -> 12.1 | O27: =N27*165 -> 1996.5 | P27: 15-17 | Q27: 超21自然日
A28: GYR2 | B28: - | C28: - | D28: - | E28: - | F28: - | G28: - | H28: 11.6 | I28: =H28*165 -> 1914 | J28: =H28-0.5 -> 11.1 | K28: =J28*165 -> 1831.5 | L28: =H28+0.2 -> 11.8 | M28: =L28*165 -> 1947 | N28: =H28+0.5 -> 12.1 | O28: =N28*165 -> 1996.5 | P28: 15-17 | Q28: 超21自然日
A29: GYR3 | B29: - | C29: - | D29: - | E29: - | F29: - | G29: - | H29: 11.6 | I29: =H29*165 -> 1914 | J29: =H29-0.5 -> 11.1 | K29: =J29*165 -> 1831.5 | L29: =H29+0.2 -> 11.8 | M29: =L29*165 -> 1947 | N29: =H29+0.5 -> 12.1 | O29: =N29*165 -> 1996.5 | P29: 15-17 | Q29: 超21自然日
A30: MIT2 | B30: - | C30: - | D30: - | E30: - | F30: - | G30: - | H30: 11.6 | I30: =H30*165 -> 1914 | J30: =H30-0.5 -> 11.1 | K30: =J30*165 -> 1831.5 | L30: =H30+0.2 -> 11.8 | M30: =L30*165 -> 1947 | N30: =H30+0.5 -> 12.1 | O30: =N30*165 -> 1996.5 | P30: 15-18 | Q30: -
A31: QZZ7 | B31: - | C31: - | D31: - | E31: - | F31: - | G31: - | H31: 11.6 | I31: =H31*165 -> 1914 | J31: =H31-0.5 -> 11.1 | K31: =J31*165 -> 1831.5 | L31: =H31+0.2 -> 11.8 | M31: =L31*165 -> 1947 | N31: =H31+0.5 -> 12.1 | O31: =N31*165 -> 1996.5 | P31: 15-18 | Q31: -
A32: TCY1 | B32: - | C32: - | D32: - | E32: - | F32: - | G32: - | H32: 11.9 | I32: =H32*165 -> 1963.5 | J32: =H32-0.5 -> 11.4 | K32: =J32*165 -> 1881 | L32: =H32+0.2 -> 12.1 | M32: =L32*165 -> 1996.5 | N32: =H32+0.5 -> 12.4 | O32: =N32*165 -> 2046 | P32: 15-18 | Q32: -
A33: TCY2 | B33: - | C33: - | D33: - | E33: - | F33: - | G33: - | H33: 11.9 | I33: =H33*165 -> 1963.5 | J33: =H33-0.5 -> 11.4 | K33: =J33*165 -> 1881 | L33: =H33+0.2 -> 12.1 | M33: =L33*165 -> 1996.5 | N33: =H33+0.5 -> 12.4 | O33: =N33*165 -> 2046 | P33: 15-17 | Q33: -
A34: HLI2 | B34: - | C34: - | D34: - | E34: - | F34: - | G34: - | H34: 11.9 | I34: =H34*165 -> 1963.5 | J34: =H34-0.5 -> 11.4 | K34: =J34*165 -> 1881 | L34: =H34+0.2 -> 12.1 | M34: =L34*165 -> 1996.5 | N34: =H34+0.5 -> 12.4 | O34: =N34*165 -> 2046 | P34: 15-18 | Q34: -
A35: QXY8 | B35: - | C35: - | D35: - | E35: - | F35: - | G35: - | H35: 11.9 | I35: =H35*165 -> 1963.5 | J35: =H35-0.5 -> 11.4 | K35: =J35*165 -> 1881 | L35: =H35+0.2 -> 12.1 | M35: =L35*165 -> 1996.5 | N35: =H35+0.5 -> 12.4 | O35: =N35*165 -> 2046 | P35: 15-18 | Q35: -
A36: IUTE | B36: - | C36: - | D36: - | E36: - | F36: - | G36: - | H36: 11.9 | I36: =H36*165 -> 1963.5 | J36: =H36-0.5 -> 11.4 | K36: =J36*165 -> 1881 | L36: =H36+0.2 -> 12.1 | M36: =L36*165 -> 1996.5 | N36: =H36+0.5 -> 12.4 | O36: =N36*165 -> 2046 | P36: 15-18 | Q36: -
... A76: ORF2 | B76: - | C76: - | D76: - | E76: - | F76: - | G76: - | H76: 14.7 | I76: =H76*165 -> 2425.5 | J76: =H76-0.5 -> 14.2 | K76: =J76*165 -> 2343 | L76: =H76+0.2 -> 14.9 | M76: =L76*165 -> 2458.5 | N76: =H76+0.5 -> 15.2 | O76: =N76*165 -> 2508 | P76: 22-27 | Q76: -
A77: 重货优惠：1：185-0.2 1：200-0.5 1：250-0.9 1：300-1.5 1.500-2比重减重后最低1.2/KG。
A78: 备注：本报价为人民币报价，价格适用于普货，包含头程运费、进出口买单报关费、文件费（不含出单费）、仓库卸货费、托盘费、目的港清关、派送等费用；不包含保险费、商检费、熏蒸费、因货物问题导致的进出口海关查验费、仓库增值服务费、超期费和仓储费等，如若产生，实报实销。
A79: 计重标准 | C79: 重量转体积：1CBM=334KG; 体积转重量：1CBM=167KG；托盘，木架，木箱等非纸箱货物出货，计费重需*1.1倍
...

Sheet 美西17-20日达
A1: =_xlfn.DISPIMG("ID_D6697A225B864C34A678052B48D4E660",1) -> =DISPIMG("ID_D6697A225B864C34A678052B48D4E660",1)
A2: 渠道名称 | B2: 易·17日达卡派 | L2: 易·20日达卡派
A3: 使用船司 | B3: EXX/以星带托架/合德快提统配（不接受指定船司） | L3: 以星不带托架/合德普提/SEA3定提/CEN（不接受指定船司）
A4: 交货仓库 | B4: 东莞/中山/广州 | D4: 嘉兴/义乌 | F4: 汕头/厦门/泉州 | H4: 武汉/长沙 | J4: 参考时效 （开船后自然日） | K4: 理赔时效 以工作日计赔付 0.5元/kg | L4: 东莞/中山/广州 | N4: 嘉兴/义乌 | P4: 汕头/厦门/泉州 | R4: 武汉/长沙 | T4: 参考时效 （开船后自然日） | U4: 理赔时效 以工作日计赔付 0.5元/kg
A5: 仓库代码 | B5: 12KG+含税 | C5: 0.5CBM+不含税 | D5: 12KG+含税 | E5: 0.5CBM+不含税 | F5: 12KG+含税 | G5: 0.5CBM+不含税 | H5: 12KG+含税 | I5: 0.5CBM+不含税 | L5: 12KG+含税 | M5: 0.5CBM+不含税 | N5: 12KG+含税 | O5: 0.5CBM+不含税 | P5: 12KG+含税 | Q5: 0.5CBM+不含税 | R5: 12KG+含税 | S5: 0.5CBM+不含税
A6: 海外仓自提 一件代发头程 | B6: 7.1 | C6: =B6*165 -> 1171.5 | D6: =B6 -> 7.1 | E6: =D6*165 -> 1171.5 | F6: =B6+0.2 -> 7.3 | G6: =F6*165 -> 1204.5 | H6: =B6+0.5 -> 7.6 | I6: =H6*165 -> 1254 | J6: 15-18 | K6: 超20自然日 | L6: 6.5 | M6: =L6*165 -> 1072.5 | N6: =L6 -> 6.5 | O6: =N6*165 -> 1072.5 | P6: =L6+0.2 -> 6.7 | Q6: =P6*165 -> 1105.5 | R6: =L6+0.5 -> 7 | S6: =R6*165 -> 1155 | T6: 17-20 | U6: 超23自然日
A7: ONT8 | B7: 7.1 | C7: =B7*165 -> 1171.5 | D7: =B7 -> 7.1 | E7: =D7*165 -> 1171.5 | F7: =B7+0.2 -> 7.3 | G7: =F7*165 -> 1204.5 | H7: =B7+0.5 -> 7.6 | I7: =H7*165 -> 1254 | J7: 15-18 | K7: 超20自然日 | L7: 6.5 | M7: =L7*165 -> 1072.5 | N7: =L7 -> 6.5 | O7: =N7*165 -> 1072.5 | P7: =L7+0.2 -> 6.7 | Q7: =P7*165 -> 1105.5 | R7: =L7+0.5 -> 7 | S7: =R7*165 -> 1155 | T7: 17-20 | U7: 超23自然日
A8: LGB8 | B8: 7.1 | C8: =B8*165 -> 1171.5 | D8: =B8 -> 7.1 | E8: =D8*165 -> 1171.5 | F8: =B8+0.2 -> 7.3 | G8: =F8*165 -> 1204.5 | H8: =B8+0.5 -> 7.6 | I8: =H8*165 -> 1254 | J8: 15-18 | K8: 超20自然日 | L8: 6.5 | M8: =L8*165 -> 1072.5 | N8: =L8 -> 6.5 | O8: =N8*165 -> 1072.5 | P8: =L8+0.2 -> 6.7 | Q8: =P8*165 -> 1105.5 | R8: =L8+0.5 -> 7 | S8: =R8*165 -> 1155 | T8: 17-20 | U8: 超23自然日
A9: LAX9 | B9: 7.1 | C9: =B9*165 -> 1171.5 | D9: =B9 -> 7.1 | E9: =D9*165 -> 1171.5 | F9: =B9+0.2 -> 7.3 | G9: =F9*165 -> 1204.5 | H9: =B9+0.5 -> 7.6 | I9: =H9*165 -> 1254 | J9: 15-18 | K9: 超20自然日 | L9: 6.5 | M9: =L9*165 -> 1072.5 | N9: =L9 -> 6.5 | O9: =N9*165 -> 1072.5 | P9: =L9+0.2 -> 6.7 | Q9: =P9*165 -> 1105.5 | R9: =L9+0.5 -> 7 | S9: =R9*165 -> 1155 | T9: 17-20 | U9: 超23自然日
A10: SBD1 | B10: 7.1 | C10: =B10*165 -> 1171.5 | D10: =B10 -> 7.1 | E10: =D10*165 -> 1171.5 | F10: =B10+0.2 -> 7.3 | G10: =F10*165 -> 1204.5 | H10: =B10+0.5 -> 7.6 | I10: =H10*165 -> 1254 | J10: 15-18 | K10: 超20自然日 | L10: 6.5 | M10: =L10*165 -> 1072.5 | N10: =L10 -> 6.5 | O10: =N10*165 -> 1072.5 | P10: =L10+0.2 -> 6.7 | Q10: =P10*165 -> 1105.5 | R10: =L10+0.5 -> 7 | S10: =R10*165 -> 1155 | T10: 17-20 | U10: 超23自然日
A11: PSP3 | B11: 7.1 | C11: =B11*165 -> 1171.5 | D11: =B11 -> 7.1 | E11: =D11*165 -> 1171.5 | F11: =B11+0.2 -> 7.3 | G11: =F11*165 -> 1204.5 | H11: =B11+0.5 -> 7.6 | I11: =H11*165 -> 1254 | J11: 15-18 | K11: - | L11: 6.5 | M11: =L11*165 -> 1072.5 | N11: =L11 -> 6.5 | O11: =N11*165 -> 1072.5 | P11: =L11+0.2 -> 6.7 | Q11: =P11*165 -> 1105.5 | R11: =L11+0.5 -> 7 | S11: =R11*165 -> 1155 | T11: 17-20 | U11: -
A12: POC1 | B12: 7.1 | C12: =B12*165 -> 1171.5 | D12: =B12 -> 7.1 | E12: =D12*165 -> 1171.5 | F12: =B12+0.2 -> 7.3 | G12: =F12*165 -> 1204.5 | H12: =B12+0.5 -> 7.6 | I12: =H12*165 -> 1254 | J12: 15-18 | K12: - | L12: 6.5 | M12: =L12*165 -> 1072.5 | N12: =L12 -> 6.5 | O12: =N12*165 -> 1072.5 | P12: =L12+0.2 -> 6.7 | Q12: =P12*165 -> 1105.5 | R12: =L12+0.5 -> 7 | S12: =R12*165 -> 1155 | T12: 17-20 | U12: -
A13: POC2 | B13: 7.1 | C13: =B13*165 -> 1171.5 | D13: =B13 -> 7.1 | E13: =D13*165 -> 1171.5 | F13: =B13+0.2 -> 7.3 | G13: =F13*165 -> 1204.5 | H13: =B13+0.5 -> 7.6 | I13: =H13*165 -> 1254 | J13: 15-18 | K13: - | L13: 6.5 | M13: =L13*165 -> 1072.5 | N13: =L13 -> 6.5 | O13: =N13*165 -> 1072.5 | P13: =L13+0.2 -> 6.7 | Q13: =P13*165 -> 1105.5 | R13: =L13+0.5 -> 7 | S13: =R13*165 -> 1155 | T13: 17-20 | U13: -
A14: POC3 | B14: 7.1 | C14: =B14*165 -> 1171.5 | D14: =B14 -> 7.1 | E14: =D14*165 -> 1171.5 | F14: =B14+0.2 -> 7.3 | G14: =F14*165 -> 1204.5 | H14: =B14+0.5 -> 7.6 | I14: =H14*165 -> 1254 | J14: 15-18 | K14: - | L14: 6.5 | M14: =L14*165 -> 1072.5 | N14: =L14 -> 6.5 | O14: =N14*165 -> 1072.5 | P14: =L14+0.2 -> 6.7 | Q14: =P14*165 -> 1105.5 | R14: =L14+0.5 -> 7 | S14: =R14*165 -> 1155 | T14: 17-20 | U14: -
A15: LAX2T(沃尔玛) | B15: 7.1 | C15: =B15*165 -> 1171.5 | D15: =B15 -> 7.1 | E15: =D15*165 -> 1171.5 | F15: =B15+0.2 -> 7.3 | G15: =F15*165 -> 1204.5 | H15: =B15+0.5 -> 7.6 | I15: =H15*165 -> 1254 | J15: 15-18 | K15: - | L15: 6.5 | M15: =L15*165 -> 1072.5 | N15: =L15 -> 6.5 | O15: =N15*165 -> 1072.5 | P15: =L15+0.2 -> 6.7 | Q15: =P15*165 -> 1105.5 | R15: =L15+0.5 -> 7 | S15: =R15*165 -> 1155 | T15: 17-20 | U15: -
A16: IUSP | B16: 7.3 | C16: =B16*165 -> 1204.5 | D16: =B16 -> 7.3 | E16: =D16*165 -> 1204.5 | F16: =B16+0.2 -> 7.5 | G16: =F16*165 -> 1237.5 | H16: =B16+0.5 -> 7.8 | I16: =H16*165 -> 1287 | J16: 15-18 | K16: - | L16: 6.7 | M16: =L16*165 -> 1105.5 | N16: =L16 -> 6.7 | O16: =N16*165 -> 1105.5 | P16: =L16+0.2 -> 6.9 | Q16: =P16*165 -> 1138.5 | R16: =L16+0.5 -> 7.2 | S16: =R16*165 -> 1188 | T16: 17-20 | U16: -
A17: IUSJ | B17: 7.3 | C17: =B17*165 -> 1204.5 | D17: =B17 -> 7.3 | E17: =D17*165 -> 1204.5 | F17: =B17+0.2 -> 7.5 | G17: =F17*165 -> 1237.5 | H17: =B17+0.5 -> 7.8 | I17: =H17*165 -> 1287 | J17: 15-18 | K17: - | L17: 6.7 | M17: =L17*165 -> 1105.5 | N17: =L17 -> 6.7 | O17: =N17*165 -> 1105.5 | P17: =L17+0.2 -> 6.9 | Q17: =P17*165 -> 1138.5 | R17: =L17+0.5 -> 7.2 | S17: =R17*165 -> 1188 | T17: 17-20 | U17: -
... A49: IAH3 | B49: 9.2 | C49: =B49*165 -> 1518 | D49: =B49 -> 9.2 | E49: =D49*165 -> 1518 | F49: =B49+0.2 -> 9.4 | G49: =F49*165 -> 1551 | H49: =B49+0.5 -> 9.7 | I49: =H49*165 -> 1600.5 | J49: 22-26 | K49: - | L49: 8.6 | M49: =L49*165 -> 1419 | N49: =L49 -> 8.6 | O49: =N49*165 -> 1419 | P49: =L49+0.2 -> 8.8 | Q49: =P49*165 -> 1452 | R49: =L49+0.5 -> 9.1 | S49: =R49*165 -> 1501.5 | T49: 24-28 | U49: -
A50: SAT1 | B50: 9.2 | C50: =B50*165 -> 1518 | D50: =B50 -> 9.2 | E50: =D50*165 -> 1518 | F50: =B50+0.2 -> 9.4 | G50: =F50*165 -> 1551 | H50: =B50+0.5 -> 9.7 | I50: =H50*165 -> 1600.5 | J50: 22-26 | L50: 8.6 | M50: =L50*165 -> 1419 | N50: =L50 -> 8.6 | O50: =N50*165 -> 1419 | P50: =L50+0.2 -> 8.8 | Q50: =P50*165 -> 1452 | R50: =L50+0.5 -> 9.1 | S50: =R50*165 -> 1501.5 | T50: 24-28 | U50: -
A51: SAT4 | B51: 9.2 | C51: =B51*165 -> 1518 | D51: =B51 -> 9.2 | E51: =D51*165 -> 1518 | F51: =B51+0.2 -> 9.4 | G51: =F51*165 -> 1551 | H51: =B51+0.5 -> 9.7 | I51: =H51*165 -> 1600.5 | J51: 22-26 | K51: - | L51: 8.6 | M51: =L51*165 -> 1419 | N51: =L51 -> 8.6 | O51: =N51*165 -> 1419 | P51: =L51+0.2 -> 8.8 | Q51: =P51*165 -> 1452 | R51: =L51+0.5 -> 9.1 | S51: =R51*165 -> 1501.5 | T51: 24-28 | U51: -
A52: IUSF | B52: 9.2 | C52: =B52*165 -> 1518 | D52: =B52 -> 9.2 | E52: =D52*165 -> 1518 | F52: =B52+0.2 -> 9.4 | G52: =F52*165 -> 1551 | H52: =B52+0.5 -> 9.7 | I52: =H52*165 -> 1600.5 | J52: 22-26 | K52: - | L52: 8.6 | M52: =L52*165 -> 1419 | N52: =L52 -> 8.6 | O52: =N52*165 -> 1419 | P52: =L52+0.2 -> 8.8 | Q52: =P52*165 -> 1452 | R52: =L52+0.5 -> 9.1 | S52: =R52*165 -> 1501.5 | T52: 24-28 | U52: -
A53: IUTH | B53: 9.2 | C53: =B53*165 -> 1518 | D53: =B53 -> 9.2 | E53: =D53*165 -> 1518 | F53: =B53+0.2 -> 9.4 | G53: =F53*165 -> 1551 | H53: =B53+0.5 -> 9.7 | I53: =H53*165 -> 1600.5 | J53: 22-26 | K53: - | L53: 8.6 | M53: =L53*165 -> 1419 | N53: =L53 -> 8.6 | O53: =N53*165 -> 1419 | P53: =L53+0.2 -> 8.8 | Q53: =P53*165 -> 1452 | R53: =L53+0.5 -> 9.1 | S53: =R53*165 -> 1501.5 | T53: 24-28 | U53: -
A54: STL3 | B54: 9.4 | C54: =B54*165 -> 1551 | D54: =B54 -> 9.4 | E54: =D54*165 -> 1551 | F54: =B54+0.2 -> 9.6 | G54: =F54*165 -> 1584 | H54: =B54+0.5 -> 9.9 | I54: =H54*165 -> 1633.5 | J54: 25-28 | K54: - | L54: 8.8 | M54: =L54*165 -> 1452 | N54: =L54 -> 8.8 | O54: =N54*165 -> 1452 | P54: =L54+0.2 -> 9 | Q54: =P54*165 -> 1485 | R54: =L54+0.5 -> 9.3 | S54: =R54*165 -> 1534.5 | T54: 27-30 | U54: -
A55: STL4 | B55: 9.4 | C55: =B55*165 -> 1551 | D55: =B55 -> 9.4 | E55: =D55*165 -> 1551 | F55: =B55+0.2 -> 9.6 | G55: =F55*165 -> 1584 | H55: =B55+0.5 -> 9.9 | I55: =H55*165 -> 1633.5 | J55: 25-28 | K55: - | L55: 8.8 | M55: =L55*165 -> 1452 | N55: =L55 -> 8.8 | O55: =N55*165 -> 1452 | P55: =L55+0.2 -> 9 | Q55: =P55*165 -> 1485 | R55: =L55+0.5 -> 9.3 | S55: =R55*165 -> 1534.5 | T55: 27-30 | U55: -
A56: PSC2 | B56: 9.4 | C56: =B56*165 -> 1551 | D56: =B56 -> 9.4 | E56: =D56*165 -> 1551 | F56: =B56+0.2 -> 9.6 | G56: =F56*165 -> 1584 | H56: =B56+0.5 -> 9.9 | I56: =H56*165 -> 1633.5 | J56: 25-28 | K56: - | L56: 8.8 | M56: =L56*165 -> 1452 | N56: =L56 -> 8.8 | O56: =N56*165 -> 1452 | P56: =L56+0.2 -> 9 | Q56: =P56*165 -> 1485 | R56: =L56+0.5 -> 9.3 | S56: =R56*165 -> 1534.5 | T56: 27-30 | U56: -
A57: PDX7 | B57: 9.4 | C57: =B57*165 -> 1551 | D57: =B57 -> 9.4 | E57: =D57*165 -> 1551 | F57: =B57+0.2 -> 9.6 | G57: =F57*165 -> 1584 | H57: =B57+0.5 -> 9.9 | I57: =H57*165 -> 1633.5 | J57: 25-28 | K57: - | L57: 8.8 | M57: =L57*165 -> 1452 | N57: =L57 -> 8.8 | O57: =N57*165 -> 1452 | P57: =L57+0.2 -> 9 | Q57: =P57*165 -> 1485 | R57: =L57+0.5 -> 9.3 | S57: =R57*165 -> 1534.5 | T57: 27-30 | U57: -
A58: BFI3 | B58: 9.4 | C58: =B58*165 -> 1551 | D58: =B58 -> 9.4 | E58: =D58*165 -> 1551 | F58: =B58+0.2 -> 9.6 | G58: =F58*165 -> 1584 | H58: =B58+0.5 -> 9.9 | I58: =H58*165 -> 1633.5 | J58: 25-28 | K58: - | L58: 8.8 | M58: =L58*165 -> 1452 | N58: =L58 -> 8.8 | O58: =N58*165 -> 1452 | P58: =L58+0.2 -> 9 | Q58: =P58*165 -> 1485 | R58: =L58+0.5 -> 9.3 | S58: =R58*165 -> 1534.5 | T58: 27-30 | U58: -
A59: DEN8 | B59: 9.4 | C59: =B59*165 -> 1551 | D59: =B59 -> 9.4 | E59: =D59*165 -> 1551 | F59: =B59+0.2 -> 9.6 | G59: =F59*165 -> 1584 | H59: =B59+0.5 -> 9.9 | I59: =H59*165 -> 1633.5 | J59: 25-28 | K59: - | L59: 8.8 | M59: =L59*165 -> 1452 | N59: =L59 -> 8.8 | O59: =N59*165 -> 1452 | P59: =L59+0.2 -> 9 | Q59: =P59*165 -> 1485 | R59: =L59+0.5 -> 9.3 | S59: =R59*165 -> 1534.5 | T59: 27-30 | U59: -
A60: IND9 | B60: 9.8 | C60: =B60*165 -> 1617 | D60: =B60 -> 9.8 | E60: =D60*165 -> 1617 | F60: =B60+0.2 -> 10 | G60: =F60*165 -> 1650 | H60: =B60+0.5 -> 10.3 | I60: =H60*165 -> 1699.5 | J60: 25-28 | K60: 超31自然日 | L60: 9.3 | M60: =L60*165 -> 1534.5 | N60: =L60 -> 9.3 | O60: =N60*165 -> 1534.5 | P60: =L60+0.2 -> 9.5 | Q60: =P60*165 -> 1567.5 | R60: =L60+0.5 -> 9.8 | S60: =R60*165 -> 1617 | T60: 27-30 | U60: 超33自然日
A61: MDW2 | B61: 9.8 | C61: =B61*165 -> 1617 | D61: =B61 -> 9.8 | E61: =D61*165 -> 1617 | F61: =B61+0.2 -> 10 | G61: =F61*165 -> 1650 | H61: =B61+0.5 -> 10.3 | I61: =H61*165 -> 1699.5 | J61: 25-28 | K61: 超31自然日 | L61: 9.3 | M61: =L61*165 -> 1534.5 | N61: =L61 -> 9.3 | O61: =N61*165 -> 1534.5 | P61: =L61+0.2 -> 9.5 | Q61: =P61*165 -> 1567.5 | R61: =L61+0.5 -> 9.8 | S61: =R61*165 -> 1617 | T61: 27-30 | U61: 超33自然日
A62: FWA4 | B62: 9.8 | C62: =B62*165 -> 1617 | D62: =B62 -> 9.8 | E62: =D62*165 -> 1617 | F62: =B62+0.2 -> 10 | G62: =F62*165 -> 1650 | H62: =B62+0.5 -> 10.3 | I62: =H62*165 -> 1699.5 | J62: 25-28 | K62: 超31自然日 | L62: 9.3 | M62: =L62*165 -> 1534.5 | N62: =L62 -> 9.3 | O62: =N62*165 -> 1534.5 | P62: =L62+0.2 -> 9.5 | Q62: =P62*165 -> 1567.5 | R62: =L62+0.5 -> 9.8 | S62: =R62*165 -> 1617 | T62: 27-30 | U62: 超33自然日
... A75: ORF2 | B75: 11.4 | C75: =B75*165 -> 1881 | D75: =B75 -> 11.4 | E75: =D75*165 -> 1881 | F75: =B75+0.2 -> 11.6 | G75: =F75*165 -> 1914 | H75: =B75+0.5 -> 11.9 | I75: =H75*165 -> 1963.5 | J75: 27-30 | K75: - | L75: 10.8 | M75: =L75*165 -> 1782 | N75: =L75 -> 10.8 | O75: =N75*165 -> 1782 | P75: =L75+0.2 -> 11 | Q75: =P75*165 -> 1815 | R75: =L75+0.5 -> 11.3 | S75: =R75*165 -> 1864.5 | T75: 29-32 | U75: -
A76: 重货优惠：1：185-0.2 1：200-0.5 1：250-0.9 1：300-1.5 1.500-2比重减重后最低1.2/KG。
A77: 备注：本报价为人民币报价，价格适用于普货，包含头程运费、进出口买单报关费、文件费（不含出单费）、仓库卸货费、托盘费、目的港清关、派送等费用；不包含保险费、商检费、熏蒸费、因货物问题导致的进出口海关查验费、仓库增值服务费、超期费和仓储费等，如若产生，实报实销。
A78: 计重标准 | C78: 重量转体积：1CBM=334KG; 体积转重量：1CBM=167KG；托盘，木架，木箱等非纸箱货物出货，计费重需*1.1倍
A79: 报关费&续页费 | C79: 报关费：RMB220, 超6个品名续页费：RMB50/页（即第7个起算，每6个品名一页）
A80: 超长附加费 | C80: 超过120-150CM附加费：+ RMB150/CBM(不含税)OR 1.2/KGS(含税), 超过150-200CM附加费：+ RMB200/CBM(不含税)OR 1.5/KGS(含税), 最长边限2米以内，超过2米以上或超重则需要case by case确认价格
A81: 超品名费 | C81: 每一票单超过五个品名的，收取RMB30/个
A82: 商检费 & 熏蒸费 | C82: 单询
A83: 提单费（如需） | C83: RMB300/BILL
...

Sheet 美西22-25日达
A1: =_xlfn.DISPIMG("ID_D6697A225B864C34A678052B48D4E660",1) -> =DISPIMG("ID_D6697A225B864C34A678052B48D4E660",1)
A2: 渠道名称 | B2: 易·22日达卡派 | L2: 易·25日达卡派
A3: 使用船司 | B3: COSCO/OA | L3: OA/MSC/ONE/WHL/HMM/TSL统配
