Workbook
Name _Loc1: [1]Request!$M$125
Name Testing: [2]欧洲UPS偏远表!#REF!
Name 美国: '[3]美国海运查询表 (2)'!$P$2:$P$1048576
Name 美国: '[3]美国海运查询表 (2)'!$P$2:$P$1048576
Name 美国: '美国海运查询表 (2)'!$P$2:$P$1048576
Name 英国: '[3]美国海运查询表 (2)'!$R$2:$R$1048576
Name 英国: '[3]美国海运查询表 (2)'!$R$2:$R$1048576
Name 英国: '美国海运查询表 (2)'!$R$2:$R$1048576

Sheet 价格查询表
D1: 天图通逊供应链有限公司 立志打造一家具有社会价值的百年跨境物流企业 | M1: {=_xlfn.LET(_xlpm.X,IFERROR(_wpsfn.REGEXP(_xlfn._xlws.FILTER(_xlfn.VSTACK(_xlfn.UNIQUE(INDIRECT("美西直送系列!A7:A"&COUNTA(美西直送系列!A:A)+6-1)),_xlfn.UNIQUE(INDIRECT("'美西-美森(12-17)'!A7:A"&COUNTA('美西-美森(12-17)'!A7:A130)+6-1)),_xlfn.UNIQUE(INDIRECT("'美西-以星&普船(17-26)'!A7:A"&COUNTA('美西-以星&普船(17-26)'!A:A)+6-1)),_xlfn.UNIQUE(INDIRECT("美西北!A7:A"&COUNTA(美西北!A:A)+6-1)),_xlfn.UNIQUE(INDIRECT("'美东-海铁系列'!A7:A"&COUNTA('美东-海铁系列'!A:A)+6-1)),_xlfn.UNIQUE(INDIRECT("美东南直航系列!A7:A"&COUNTA(美东南直航系列!A:A)+6-1)),_xlfn.UNIQUE(INDIRECT("'美中-休斯顿'!A7:A"&COUNTA('美中-休斯顿'!A:A)+6-1)),_xlfn.UNIQUE(INDIRECT("'美中-芝加哥'!A7:A"&COUNTA('美中-芝加哥'!A:A)+6-1)),_xlfn.UNIQUE(INDIRECT("美东南海陆系列!A7:A"&COUNTA(美东南海陆系列!A:A)+6-1))),IF(ISNUMBER(FIND("-直送特价",_xlfn.VSTACK(_xlfn.UNIQUE(INDIRECT("美西直送系列!A7:A"&COUNTA(美西直送系列!A:A)+6-1)),_xlfn.UNIQUE(INDIRECT("'美西-美森(12-17)'!A7:A"&COUNTA('美西-美森(12-17)'!A7:A130)+6-1)),_xlfn.UNIQUE(INDIRECT("'美西-以星&普船(17-26)'!A7:A"&COUNTA('美西-以星&普船(17-26)'!A:A)+6-1)),_xlfn.UNIQUE(INDIRECT("美西北!A7:A"&COUNTA(美西北!A:A)+6-1)),_xlfn.UNIQUE(INDIRECT("'美东-海铁&海陆系列'!A7:A"&COUNTA('美东-海铁系列'!A:A)+6-1)),_xlfn.UNIQUE(INDIRECT("美东南直航系列!A7:A"&COUNTA(美东南直航系列!A:A)+6-1)),_xlfn.UNIQUE(INDIRECT("'美中-休斯顿'!A7:A"&COUNTA('美中-休斯顿'!A:A)+6-1)),_xlfn.UNIQUE(INDIRECT("'美中-芝加哥'!A7:A"&COUNTA('美中-芝加哥'!A:A)+6-1)),_xlfn.UNIQUE(INDIRECT("'美东南海陆系列'!A7:A"&COUNTA(美东南海陆系列!A:A)+6-1))),1))=FALSE,TRUE,FALSE)),"[^一-龟]+"),""),_xlfn._xlws.FILTER(_xlpm.X,(_xlpm.X<>"0")*(_xlpm.X<>"")*(_xlpm.X<>CHAR(10)&"(")*(_xlpm.X<>CHAR(10))))} -> #VALUE! | N1: {=_xlfn.UNIQUE(_xlfn.VSTACK(INDIRECT("'美转加-普船系列'!A7:A"&COUNTA(#REF!)),INDIRECT("'美转加-合德系列'!A7:A"&COUNTA(#REF!)),INDIRECT("'美转加-EXX美森系列'!A7:A"&COUNTA(#REF!)),INDIRECT("'美转加-美森MAX系列'!A7:A"&COUNTA(#REF!)),INDIRECT("'美转加-美森CLX系列'!A7:A"&COUNTA(#REF!)),INDIRECT("'加拿大直航-普船系列'!A7:A"&COUNTA(#REF!))))} -> #REF! | P1: 其它 | Q1: 12KG+ | R1: 深圳 | S1: 华南
P2: {=_xlfn.UNIQUE(INDIRECT("'英国海运-卡派(23-40) '!A7:A"&COUNTA(#REF!)))} -> #REF! | Q2: 71KG+ | R2: 广州 | S2: 华南
D3: =IF(D6="加拿大","加拿大价格查询表",IF(D6="英国","英国价格查询表","美国海运价格查询表")) -> 加拿大价格查询表 | Q3: 100KG+ | R3: 中山 | S3: 华南
H4: 华南：深圳、广州、中山、东莞南城、惠州 华东：义乌、上海、宁波、苏州、杭州、绍兴 | Q4: 300KG+ | R4: 泉州 | S4: 厦门/泉州
D5: 国家 | E5: 目的仓 | F5: 国内仓 | G5: =IF(D3="英国价格查询表","公斤段","") | Q5: 15CBM+ | R5: 厦门 | S5: 厦门/泉州
D6: 加拿大 | E6: YYZ2 | F6: 义乌 | G6: 300KG+ | R6: 义乌 | S6: 华东
D7: 备注：（美国空运、快递派不在本查询中，具体详情请看报价表）；请根据你所查询的国家/仓库进行切换；非对应国家仓库价格不可参考；查询表仅供参考，实际以对应渠道报价为准！ | R7: 上海 | S7: 华东
B8: {=IF(D3="美国海运价格查询表",'价格查询表-间接版'!A7:$G$43,IF(D3="英国价格查询表",'价格查询表-间接版'!I7:O22,'价格查询表-间接版'!Q7:W35))} -> 默认送仓方式 | C8: 渠道类型 | D8: 包税 (100KG+) | E8: 不包税 (1CBM+) | F8: 签收时效 开船后-入仓时效 | G8: 延时赔付 开船后-不入仓时效 | H8: 备注 | I8: 偏远邮编查询 | R8: 福州 | S8: 厦门/泉州
B9: 直航 | C9: 加拿大加东直航30日达-卡派 | D9: - | E9: - | F9: - | G9: - | H9: 包税21-49KG:+1.5元/KG；50-99KG:+1元/KG | I9: 请输入邮编码： | J9: 21840 | R9: 汕头 | S9: 汕头
B10: 直航 | C10: 加拿大加东直航30日达-UPS派 | D10: - | E10: - | F10: - | G10: - | H10: 包税21-49KG:+1.5元/KG；50-99KG:+1元/KG | R10: 东莞南城 | S10: 华南
B11: 直航 | C11: 加拿大加西直航30日达-卡派 | D11: - | E11: - | F11: - | G11: - | H11: 包税21-49KG:+1.5元/KG；50-99KG:+1元/KG | I11: UPS | J11: =IFERROR(VLOOKUP(J9,偏远邮编库!B:C,2,0),"单询") -> 超偏远 | R11: 宁波 | S11: 华东
B12: 直航 | C12: 加拿大加西直航30日达-UPS派 | D12: - | E12: - | F12: - | G12: - | H12: 包税21-49KG:+1.5元/KG；50-99KG:+1元/KG | R12: 青岛 | S12: 青岛
B13: 直航 | C13: 加拿大加东直航33日达-卡派 | D13: - | E13: - | F13: - | G13: - | H13: 包税21-49KG:+1.5元/KG；50-99KG:+1元/KG | I13: Fedex | J13: =IFERROR(VLOOKUP(J9,偏远邮编库!F:G,2,0),"单询") -> 超偏远 | R13: 武汉 | S13: 武汉
B14: 直航 | C14: 加拿大加东直航33日达-UPS派 | D14: - | E14: - | F14: - | G14: - | H14: 包税21-49KG:+1.5元/KG；50-99KG:+1元/KG | R14: 长沙 | S14: 武汉
B15: 直航 | C15: 加拿大加西直航33日达-卡派 | D15: - | E15: - | F15: - | G15: - | H15: 包税21-49KG:+1.5元/KG；50-99KG:+1元/KG | R15: 郑州 | S15: 青岛
B16: 直航 | C16: 加拿大加西直航33日达-UPS派 | D16: - | E16: - | F16: - | G16: - | H16: 包税21-49KG:+1.5元/KG；50-99KG:+1元/KG | R16: 苏州 | S16: 华东
B17: 美转加 | C17: 美转加加东25日达-卡派（OA） | D17: - | E17: - | F17: - | G17: - | H17: 包税21-49KG:+1.5元/KG；50-99KG:+1元/KG | R17: 杭州仓 | S17: 华东
B18: 美转加 | C18: 美转加加东25日达-UPS派（OA） | D18: - | E18: - | F18: - | G18: - | H18: 包税21-49KG:+1.5元/KG；50-99KG:+1元/KG | R18: 绍兴 | S18: 华东
B19: 美转加 | C19: 美转加加西25日达-卡派（OA） | D19: - | E19: - | F19: - | G19: - | H19: 包税21-49KG:+1.5元/KG；50-99KG:+1元/KG | R19: 连云港 | S19: 青岛
B20: 美转加 | C20: 美转加加西25日达-UPS派（OA） | D20: - | E20: - | F20: - | G20: - | H20: 包税21-49KG:+1.5元/KG；50-99KG:+1元/KG | R20: 温州 | S20: 青岛
B21: 美转加 | C21: 美转加加东20日达-卡派（HD） | D21: - | E21: - | F21: - | G21: - | H21: 包税21-49KG:+1.5元/KG；50-99KG:+1元/KG | R21: 台州 | S21: 青岛
B22: 美转加 | C22: 美转加加东20日达-UPS派（HD） | D22: - | E22: - | F22: - | G22: - | H22: 包税21-49KG:+1.5元/KG；50-99KG:+1元/KG | R22: 重庆 | S22: 重庆
B23: 美转加 | C23: 美转加加西20日达-卡派（HD） | D23: - | E23: - | F23: - | G23: - | H23: 包税21-49KG:+1.5元/KG；50-99KG:+1元/KG | R23: 成都 | S23: 武汉
B24: 美转加 | C24: 美转加加西20日达-UPS派（HD） | D24: - | E24: - | F24: - | G24: - | H24: 包税21-49KG:+1.5元/KG；50-99KG:+1元/KG | R24: 天津 | S24: 天津/南昌/石家庄
B25: 美转加 | C25: 美转加加东19日达-卡派（EXX） | D25: - | E25: - | F25: - | G25: - | H25: 包税21-49KG:+1.5元/KG；50-99KG:+1元/KG | R25: 南昌 | S25: 天津/南昌/石家庄
... B33: 美转加 | C33: 美转加CLX加东16日达-卡派 | D33: - | E33: - | F33: 20-24日 | G33: 超26日 | H33: 快递派包税21-99KG:+1元/KG； | R33: 潍坊 | S33: 济南/潍坊
B34: 美转加 | C34: 美转加CLX加东16日达-UPS派 | D34: - | E34: - | F34: 18-22日 | G34: 超24日 | H34: 快递派包税21-99KG:+1元/KG；
B35: 美转加 | C35: 美转加CLX加西16日达-卡派 | D35: - | E35: - | F35: - | G35: - | H35: 快递派包税21-99KG:+1元/KG；
B36: 美转加 | C36: 美转加CLX加西16日达-UPS派 | D36: - | E36: - | F36: - | G36: - | H36: 快递派包税21-99KG:+1元/KG；

Sheet 价格查询表-间接版
A1: 天图通逊供应链有限公司 立志打造一家具有社会价值的百年跨境物流企业
A3: 美国海运价格快速查询栏 | I3: 英国价格快速查询栏 | Q3: 加拿大价格快速查询栏
A4: 备注： “英国”&“快递派”&“空运”渠道不在本快速查找范围，请查询报价表内页详情。 | C4: 目的仓 | D4: 国内仓 | E4: 注意事项如下 | G4: =TODAY() -> 46202 | I4: 备注： “美国”渠道不在本快速查找范围，请查询报价表内页详情。 | K4: 目的仓 | L4: 国内仓 | M4: 公斤段 | N4: 注意事项如下 | Q4: 备注： “英国”&“快递派”&“空运”渠道不在本快速查找范围，请查询报价表内页详情。 | S4: 目的仓 | T4: 国内仓 | U4: 注意事项如下 | AC4: 青岛 | AD4: 青岛/郑州/绍兴/苏州/杭州仓/连云港/温州/台州/南京/合肥
C5: =价格查询表!E6 -> YYZ2 | D5: =VLOOKUP(价格查询表!F6,价格查询表!R:S,2,0) -> 华东 | K5: =价格查询表!E6 -> YYZ2 | L5: =价格查询表!F6 -> 义乌 | M5: =价格查询表!G6 -> 300KG+ | S5: =价格查询表!E6 -> YYZ2 | T5: =VLOOKUP(价格查询表!F6,价格查询表!R:S,2,0) -> 华东 | AC5: 郑州 | AD5: 青岛/郑州/绍兴/苏州/杭州仓/连云港/温州/台州/南京/合肥
AC6: 绍兴 | AD6: 青岛/郑州/绍兴/苏州/杭州仓/连云港/温州/台州/南京/合肥
A7: 默认送仓方式 | B7: 渠道类型 | C7: =IF(LEFT(C5,3)="WM-","包税"&CHAR(10)&"(100kg+）","包税"&CHAR(10)&"(50kg+）") -> 包税 (50kg+） | D7: 不包税 (1CBM+) | E7: 签收时效 开船后-入仓时效 | F7: 延时赔付 开船后-不入仓时效 | G7: 备注 | I7: 运输方式 | J7: 渠道类型 | K7: 包税 | L7: 不包税 | M7: 签收时效 | N7: 延时赔付 | O7: 备注 | Q7: 默认送仓方式 | R7: 渠道类型 | S7: 包税 (100KG+) | T7: 不包税 (1CBM+) | U7: 签收时效 开船后-入仓时效 | V7: 延时赔付 开船后-不入仓时效 | W7: 备注 | AC7: 苏州 | AD7: 青岛/郑州/绍兴/苏州/杭州仓/连云港/温州/台州/南京/合肥
A8: 直送专线 | B8: 洛杉矶普船28日达直送 | C8: {=IFERROR(VLOOKUP($C$5,美西直送系列!$A:$DT,INDEX(定位!$A:$W,MATCH($B8,定位!$A:$A,0),MATCH("*"&$D$5&"*"&"-BS",定位!$1:$1,0)),FALSE),"-")} -> - | D8: {=IFERROR(VLOOKUP($C$5,美西直送系列!$A:$DT,INDEX(定位!$A:$W,MATCH($B8,定位!$A:$A,0),MATCH("*"&$D$5&"*"&"-NBS",定位!$1:$1,0)),FALSE),"-")} -> - | E8: =IFERROR(VLOOKUP($C$5,美西直送系列!$A:$DT,_xlfn.XLOOKUP($B8,定位!A:A,定位!V:V),FALSE),"-") -> - | F8: =IFERROR(VLOOKUP($C$5,美西直送系列!$A:$DT,_xlfn.XLOOKUP($B8,定位!A:A,定位!W:W),FALSE),"-") -> - | G8: =IF(LEFT($C$5,3)<>"WM-","FBA卡派包税:【10-49KG:+1元/KG】","沃尔玛卡派包税: 【21-49KG:+2元/KG】； 【50-99KG:+1元/KG】；") -> FBA卡派包税:【10-49KG:+1元/KG】 | I8: 陆运 | J8: 英国快铁25日达-卡派 | K8: {=IF(AND(AND(OR($K$5="LBA4",$K$5="BHX4",$K$5="BHX8"),$M$5<>"12-99KG"),AND(OR($K$5="LBA4",$K$5="BHX4",$K$5="BHX8"),$M$5<>"15CBM+")),INDEX(#REF!,MATCH("*"&$L$5&"*",#REF!,0)),"-")} -> - | L8: {=IF(AND(AND(OR($K$5="LBA4",$K$5="BHX4",$K$5="BHX8"),$M$5<>"12-99KG"),AND(OR($K$5="LBA4",$K$5="BHX4",$K$5="BHX8"),$M$5<>"15CBM+")),INDEX(#REF!,MATCH("*"&$L$5&"*",#REF!,0)),"-")} -> - | M8: {=IF(AND(AND(OR($K$5="LBA4",$K$5="BHX4",$K$5="BHX8"),$M$5<>"12-99KG"),AND(OR($K$5="LBA4",$K$5="BHX4",$K$5="BHX8"),$M$5<>"15CBM+")),INDEX(#REF!,MATCH("*"&$L$5&"*",#REF!,0)),"-")} -> - | N8: {=IF(AND(AND(OR($K$5="LBA4",$K$5="BHX4",$K$5="BHX8"),$M$5<>"12-99KG"),AND(OR($K$5="LBA4",$K$5="BHX4",$K$5="BHX8"),$M$5<>"15CBM+")),INDEX(#REF!,MATCH("*"&$L$5&"*",#REF!,0)),"-")} -> - | O8: =IF(OR(AND($M$5="12KG+",$N$8="-"),AND($M$5="71KG+",$N$8="-")),"100KG+起收",IF($M$5="15CBM+","KG价","")) | Q8: 直航 | R8: 加拿大加东直航30日达-卡派 | S8: {=IFERROR(VLOOKUP($S$5,#REF!,INDEX(定位!$A:$W,MATCH($R8,定位!$A:$A,0),MATCH("*"&$T$5&"*"&"-BS",定位!$1:$1,0)),FALSE),"-")} -> - | T8: {=IFERROR(VLOOKUP($S$5,#REF!,INDEX(定位!$A:$W,MATCH($R8,定位!$A:$A,0),MATCH("*"&$T$5&"*"&"-NBS",定位!$1:$1,0)),FALSE),"-")} -> - | U8: =IFERROR(VLOOKUP($C$5,#REF!,_xlfn.XLOOKUP($R8,定位!A:A,定位!V:V),FALSE),"-") -> - | V8: =IFERROR(VLOOKUP($C$5,#REF!,_xlfn.XLOOKUP($R8,定位!A:A,定位!W:W),FALSE),"-") -> - | W8: 包税21-49KG:+1.5元/KG；50-99KG:+1元/KG | AC8: 杭州仓 | AD8: 青岛/郑州/绍兴/苏州/杭州仓/连云港/温州/台州/南京/合肥
A9: 直送专线 | B9: 洛杉矶OA26日达直送 | C9: {=IFERROR(VLOOKUP($C$5,美西直送系列!$A:$DT,INDEX(定位!$A:$W,MATCH($B9,定位!$A:$A,0),MATCH("*"&$D$5&"*"&"-BS",定位!$1:$1,0)),FALSE),"-")} -> - | D9: {=IFERROR(VLOOKUP($C$5,美西直送系列!$A:$DT,INDEX(定位!$A:$W,MATCH($B9,定位!$A:$A,0),MATCH("*"&$D$5&"*"&"-NBS",定位!$1:$1,0)),FALSE),"-")} -> - | E9: =IFERROR(VLOOKUP($C$5,美西直送系列!$A:$DT,_xlfn.XLOOKUP($B9,定位!A:A,定位!V:V),FALSE),"-") -> - | F9: =IFERROR(VLOOKUP($C$5,美西直送系列!$A:$DT,_xlfn.XLOOKUP(B9,定位!A:A,定位!W:W),FALSE),"-") -> - | G9: =IF(LEFT($C$5,3)<>"WM-","FBA卡派包税:【10-49KG:+1元/KG】","沃尔玛卡派包税: 【21-49KG:+2元/KG】； 【50-99KG:+1元/KG】；") -> FBA卡派包税:【10-49KG:+1元/KG】 | I9: 陆运 | J9: 英国快铁25日达-DPD派 | K9: {=IF(AND($M$5<>"15CBM+",$M$5<>"12-99KG"),INDEX(#REF!,MATCH("*"&$L$5&"*",#REF!,0)),"-")} -> #REF! | L9: {=IF(AND($M$5<>"15CBM+",$M$5<>"12-99KG"),INDEX(#REF!,MATCH("*"&$L$5&"*",#REF!,0)),"-")} -> #REF! | M9: {=IF(AND($M$5<>"15CBM+",$M$5<>"12-99KG"),INDEX(#REF!,MATCH("*"&$L$5&"*",#REF!,0)),"-")} -> #REF! | N9: {=IF(AND($M$5<>"15CBM+",$M$5<>"12-99KG"),INDEX(#REF!,MATCH("*"&$L$5&"*",#REF!,0)),"-")} -> #REF! | O9: =IF($M$5="100KG+","12-70KG:+2元/KG；"&CHAR(10)&"71-99KG:+1元/KG；",IF($M$5="15CBM+","KG价","")) | Q9: 直航 | R9: 加拿大加东直航30日达-UPS派 | S9: {=IFERROR(VLOOKUP($S$5,#REF!,INDEX(定位!$A:$W,MATCH($R9,定位!$A:$A,0),MATCH("*"&$T$5&"*"&"-BS",定位!$1:$1,0)),FALSE),"-")} -> - | T9: {=IFERROR(VLOOKUP($S$5,#REF!,INDEX(定位!$A:$W,MATCH($R9,定位!$A:$A,0),MATCH("*"&$T$5&"*"&"-NBS",定位!$1:$1,0)),FALSE),"-")} -> - | U9: =IFERROR(VLOOKUP($C$5,#REF!,_xlfn.XLOOKUP($R9,定位!A:A,定位!V:V),FALSE),"-") -> - | V9: =IFERROR(VLOOKUP($C$5,#REF!,_xlfn.XLOOKUP($R9,定位!A:A,定位!W:W),FALSE),"-") -> - | W9: 包税21-49KG:+1.5元/KG；50-99KG:+1元/KG | AC9: 连云港 | AD9: 青岛/郑州/绍兴/苏州/杭州仓/连云港/温州/台州/南京/合肥
A10: 直送专线 | B10: 奥克兰OA29日达直送 | C10: {=IFERROR(VLOOKUP($C$5,美西直送系列!$A:$DT,INDEX(定位!$A:$W,MATCH($B10,定位!$A:$A,0),MATCH("*"&$D$5&"*"&"-BS",定位!$1:$1,0)),FALSE),"-")} -> - | D10: {=IFERROR(VLOOKUP($C$5,美西直送系列!$A:$DT,INDEX(定位!$A:$W,MATCH($B10,定位!$A:$A,0),MATCH("*"&$D$5&"*"&"-NBS",定位!$1:$1,0)),FALSE),"-")} -> - | E10: =IFERROR(VLOOKUP($C$5,美西直送系列!$A:$DT,_xlfn.XLOOKUP($B10,定位!A:A,定位!V:V),FALSE),"-") -> - | F10: =IFERROR(VLOOKUP($C$5,美西直送系列!$A:$DT,_xlfn.XLOOKUP(B10,定位!A:A,定位!W:W),FALSE),"-") -> - | G10: =IF(LEFT($C$5,3)<>"WM-","FBA卡派包税:【10-49KG:+1元/KG】","沃尔玛卡派包税: 【21-49KG:+2元/KG】； 【50-99KG:+1元/KG】；") -> FBA卡派包税:【10-49KG:+1元/KG】 | I10: 陆运 | J10: 英国中英铁卡-卡派（暂停） | K10: {=IF(AND(AND(OR($K$5="LBA4",$K$5="BHX4",$K$5="BHX8"),$M$5<>"12-99KG"),AND(OR($K$5="LBA4",$K$5="BHX4",$K$5="BHX8"),$M$5<>"15CBM+")),INDEX(#REF!,MATCH("*"&$L$5&"*",#REF!,0)),"-")} -> - | L10: {=IF(AND(AND(OR($K$5="LBA4",$K$5="BHX4",$K$5="BHX8"),$M$5<>"12-99KG"),AND(OR($K$5="LBA4",$K$5="BHX4",$K$5="BHX8"),$M$5<>"15CBM+")),INDEX(#REF!,MATCH("*"&$L$5&"*",#REF!,0)),"-")} -> - | M10: {=IF(AND(AND(OR($K$5="LBA4",$K$5="BHX4",$K$5="BHX8"),$M$5<>"12-99KG"),AND(OR($K$5="LBA4",$K$5="BHX4",$K$5="BHX8"),$M$5<>"15CBM+")),INDEX(#REF!,MATCH("*"&$L$5&"*",#REF!,0)),"-")} -> - | N10: {=IF(AND(AND(OR($K$5="LBA4",$K$5="BHX4",$K$5="BHX8"),$M$5<>"12-99KG"),AND(OR($K$5="LBA4",$K$5="BHX4",$K$5="BHX8"),$M$5<>"15CBM+")),INDEX(#REF!,MATCH("*"&$L$5&"*",#REF!,0)),"-")} -> - | O10: =IF(OR(AND($M$5="12KG+",$N$8="-"),AND($M$5="71KG+",$N$8="-")),"100KG+起收",IF($M$5="15CBM+","KG价","")) | Q10: 直航 | R10: 加拿大加西直航30日达-卡派 | S10: {=IFERROR(VLOOKUP($S$5,#REF!,INDEX(定位!$A:$W,MATCH($R10,定位!$A:$A,0),MATCH("*"&$T$5&"*"&"-BS",定位!$1:$1,0)),FALSE),"-")} -> - | T10: {=IFERROR(VLOOKUP($S$5,#REF!,INDEX(定位!$A:$W,MATCH($R10,定位!$A:$A,0),MATCH("*"&$T$5&"*"&"-NBS",定位!$1:$1,0)),FALSE),"-")} -> - | U10: =IFERROR(VLOOKUP($C$5,#REF!,_xlfn.XLOOKUP($R10,定位!A:A,定位!V:V),FALSE),"-") -> - | V10: =IFERROR(VLOOKUP($C$5,#REF!,_xlfn.XLOOKUP($R10,定位!A:A,定位!W:W),FALSE),"-") -> - | W10: 包税21-49KG:+1.5元/KG；50-99KG:+1元/KG | AC10: 温州 | AD10: 青岛/郑州/绍兴/苏州/杭州仓/连云港/温州/台州/南京/合肥
A11: 直送专线 | B11: 奥克兰普船36日达直送 | C11: {=IFERROR(VLOOKUP($C$5,美西直送系列!$A:$DT,INDEX(定位!$A:$W,MATCH($B11,定位!$A:$A,0),MATCH("*"&$D$5&"*"&"-BS",定位!$1:$1,0)),FALSE),"-")} -> - | D11: {=IFERROR(VLOOKUP($C$5,美西直送系列!$A:$DT,INDEX(定位!$A:$W,MATCH($B11,定位!$A:$A,0),MATCH("*"&$D$5&"*"&"-NBS",定位!$1:$1,0)),FALSE),"-")} -> - | E11: =IFERROR(VLOOKUP($C$5,美西直送系列!$A:$DT,_xlfn.XLOOKUP($B11,定位!A:A,定位!V:V),FALSE),"-") -> - | F11: =IFERROR(VLOOKUP($C$5,美西直送系列!$A:$DT,_xlfn.XLOOKUP(B11,定位!A:A,定位!W:W),FALSE),"-") -> - | G11: =IF(LEFT($C$5,3)<>"WM-","FBA卡派包税:【10-49KG:+1元/KG】","沃尔玛卡派包税: 【21-49KG:+2元/KG】； 【50-99KG:+1元/KG】；") -> FBA卡派包税:【10-49KG:+1元/KG】 | I11: 陆运 | J11: 英国中英铁卡-DPD派（暂停） | K11: {=IF(AND($M$5<>"15CBM+",$M$5<>"12-99KG"),INDEX(#REF!,MATCH("*"&$L$5&"*",#REF!,0)),"-")} -> #REF! | L11: {=IF(AND($M$5<>"15CBM+",$M$5<>"12-99KG"),INDEX(#REF!,MATCH("*"&$L$5&"*",#REF!,0)),"-")} -> #REF! | M11: {=IF(AND($M$5<>"15CBM+",$M$5<>"12-99KG"),INDEX(#REF!,MATCH("*"&$L$5&"*",#REF!,0)),"-")} -> #REF! | N11: {=IF(AND($M$5<>"15CBM+",$M$5<>"12-99KG"),INDEX(#REF!,MATCH("*"&$L$5&"*",#REF!,0)),"-")} -> #REF! | O11: =IF($M$5="100KG+","12-70KG:+2元/KG；"&CHAR(10)&"71-99KG:+1元/KG；",IF($M$5="15CBM+","KG价","")) | Q11: 直航 | R11: 加拿大加西直航30日达-UPS派 | S11: {=IFERROR(VLOOKUP($S$5,#REF!,INDEX(定位!$A:$W,MATCH($R11,定位!$A:$A,0),MATCH("*"&$T$5&"*"&"-BS",定位!$1:$1,0)),FALSE),"-")} -> - | T11: {=IFERROR(VLOOKUP($S$5,#REF!,INDEX(定位!$A:$W,MATCH($R11,定位!$A:$A,0),MATCH("*"&$T$5&"*"&"-NBS",定位!$1:$1,0)),FALSE),"-")} -> - | U11: =IFERROR(VLOOKUP($C$5,#REF!,_xlfn.XLOOKUP($R11,定位!A:A,定位!V:V),FALSE),"-") -> - | V11: =IFERROR(VLOOKUP($C$5,#REF!,_xlfn.XLOOKUP($R11,定位!A:A,定位!W:W),FALSE),"-") -> - | W11: 包税21-49KG:+1.5元/KG；50-99KG:+1元/KG | AC11: 台州 | AD11: 青岛/郑州/绍兴/苏州/杭州仓/连云港/温州/台州/南京/合肥
A12: 直送专线 | B12: 纽约直航42日达直送特价 | C12: {=IFERROR(VLOOKUP($C$5&"-直送特价",美东直航系列!$A:$CT,INDEX(定位!$A:$W,MATCH($B12,定位!$A:$A,0),MATCH("*"&$D$5&"*"&"-BS",定位!$1:$1,0)),FALSE),"-")} -> - | D12: {=IFERROR(VLOOKUP($C$5&"-直送特价",美东直航系列!$A:$CT,INDEX(定位!$A:$W,MATCH($B12,定位!$A:$A,0),MATCH("*"&$D$5&"*"&"-NBS",定位!$1:$1,0)),FALSE),"-")} -> - | E12: =IFERROR(VLOOKUP($C$5&"-直送特价",美东直航系列!$A:$CT,_xlfn.XLOOKUP($B12,定位!A:A,定位!V:V),FALSE),"-") -> - | F12: =IFERROR(VLOOKUP($C$5&"-直送特价",美东直航系列!$A:$CT,_xlfn.XLOOKUP($B12,定位!A:A,定位!W:W),FALSE),"-") -> - | G12: =IF(LEFT($C$5,3)<>"WM-","FBA卡派包税:【10-49KG:+1元/KG】","沃尔玛卡派包税: 【21-49KG:+2元/KG】； 【50-99KG:+1元/KG】；") -> FBA卡派包税:【10-49KG:+1元/KG】 | I12: 陆运 | J12: 苏新号-中英卡航20日达-卡派 | K12: {=IF(AND(AND(OR($K$5="LBA4",$K$5="BHX4",$K$5="BHX8"),$M$5<>"12-99KG"),AND(OR($K$5="LBA4",$K$5="BHX4",$K$5="BHX8"),$M$5<>"15CBM+")),INDEX(#REF!,MATCH("*"&$L$5&"*",#REF!,0)),"-")} -> - | L12: {=IF(AND(AND(OR($K$5="LBA4",$K$5="BHX4",$K$5="BHX8"),$M$5<>"12-99KG"),AND(OR($K$5="LBA4",$K$5="BHX4",$K$5="BHX8"),$M$5<>"15CBM+")),INDEX(#REF!,MATCH("*"&$L$5&"*",#REF!,0)),"-")} -> - | M12: {=IF(AND(AND(OR($K$5="LBA4",$K$5="BHX4",$K$5="BHX8"),$M$5<>"12-99KG"),AND(OR($K$5="LBA4",$K$5="BHX4",$K$5="BHX8"),$M$5<>"15CBM+")),INDEX(#REF!,MATCH("*"&$L$5&"*",#REF!,0)),"-")} -> - | N12: {=IF(AND(AND(OR($K$5="LBA4",$K$5="BHX4",$K$5="BHX8"),$M$5<>"12-99KG"),AND(OR($K$5="LBA4",$K$5="BHX4",$K$5="BHX8"),$M$5<>"15CBM+")),INDEX(#REF!,MATCH("*"&$L$5&"*",#REF!,0)),"-")} -> - | O12: =IF(OR(AND($M$5="12KG+",$N$8="-"),AND($M$5="71KG+",$N$8="-")),"100KG+起收",IF($M$5="15CBM+","KG价","")) | Q12: 直航 | R12: 加拿大加东直航33日达-卡派 | S12: {=IFERROR(VLOOKUP($S$5,#REF!,INDEX(定位!$A:$W,MATCH($R12,定位!$A:$A,0),MATCH("*"&$T$5&"*"&"-BS",定位!$1:$1,0)),FALSE),"-")} -> - | T12: {=IFERROR(VLOOKUP($S$5,#REF!,INDEX(定位!$A:$W,MATCH($R12,定位!$A:$A,0),MATCH("*"&$T$5&"*"&"-NBS",定位!$1:$1,0)),FALSE),"-")} -> - | U12: =IFERROR(VLOOKUP($C$5,#REF!,_xlfn.XLOOKUP($R12,定位!A:A,定位!V:V),FALSE),"-") -> - | V12: =IFERROR(VLOOKUP($C$5,#REF!,_xlfn.XLOOKUP($R12,定位!A:A,定位!W:W),FALSE),"-") -> - | W12: 包税21-49KG:+1.5元/KG；50-99KG:+1元/KG | AC12: 广州 | AD12: 广州/深圳/东莞南城
A13: 直送专线 | B13: 纽约直航38日达直送特价 | C13: {=IFERROR(VLOOKUP($C$5&"-直送特价",美东直航系列!$A:$CT,INDEX(定位!$A:$W,MATCH($B13,定位!$A:$A,0),MATCH("*"&$D$5&"*"&"-BS",定位!$1:$1,0)),FALSE),"-")} -> - | D13: {=IFERROR(VLOOKUP($C$5&"-直送特价",美东直航系列!$A:$CT,INDEX(定位!$A:$W,MATCH($B13,定位!$A:$A,0),MATCH("*"&$D$5&"*"&"-NBS",定位!$1:$1,0)),FALSE),"-")} -> - | E13: =IFERROR(VLOOKUP($C$5&"-直送特价",美东直航系列!$A:$CT,_xlfn.XLOOKUP($B13,定位!A:A,定位!V:V),FALSE),"-") -> - | F13: =IFERROR(VLOOKUP($C$5&"-直送特价",美东直航系列!$A:$CT,_xlfn.XLOOKUP($B13,定位!A:A,定位!W:W),FALSE),"-") -> - | G13: =IF(LEFT($C$5,3)<>"WM-","FBA卡派包税:【10-49KG:+1元/KG】","沃尔玛卡派包税: 【21-49KG:+2元/KG】； 【50-99KG:+1元/KG】；") -> FBA卡派包税:【10-49KG:+1元/KG】 | I13: 陆运 | J13: 苏新号-中英卡航20日达-DPD派 | K13: {=IF(AND($M$5<>"15CBM+",$M$5<>"12-99KG"),INDEX(#REF!,MATCH("*"&$L$5&"*",#REF!,0)),"-")} -> #REF! | L13: {=IF(AND($M$5<>"15CBM+",$M$5<>"12-99KG"),INDEX(#REF!,MATCH("*"&$L$5&"*",#REF!,0)),"-")} -> #REF! | M13: {=IF(AND($M$5<>"15CBM+",$M$5<>"12-99KG"),INDEX(#REF!,MATCH("*"&$L$5&"*",#REF!,0)),"-")} -> #REF! | N13: {=IF(AND($M$5<>"15CBM+",$M$5<>"12-99KG"),INDEX(#REF!,MATCH("*"&$L$5&"*",#REF!,0)),"-")} -> #REF! | O13: =IF($M$5="100KG+","12-70KG:+2元/KG；"&CHAR(10)&"71-99KG:+1元/KG；",IF($M$5="15CBM+","KG价","")) | Q13: 直航 | R13: 加拿大加东直航33日达-UPS派 | S13: {=IFERROR(VLOOKUP($S$5,#REF!,INDEX(定位!$A:$W,MATCH($R13,定位!$A:$A,0),MATCH("*"&$T$5&"*"&"-BS",定位!$1:$1,0)),FALSE),"-")} -> - | T13: {=IFERROR(VLOOKUP($S$5,#REF!,INDEX(定位!$A:$W,MATCH($R13,定位!$A:$A,0),MATCH("*"&$T$5&"*"&"-NBS",定位!$1:$1,0)),FALSE),"-")} -> - | U13: =IFERROR(VLOOKUP($C$5,#REF!,_xlfn.XLOOKUP($R13,定位!A:A,定位!V:V),FALSE),"-") -> - | V13: =IFERROR(VLOOKUP($C$5,#REF!,_xlfn.XLOOKUP($R13,定位!A:A,定位!W:W),FALSE),"-") -> - | W13: 包税21-49KG:+1.5元/KG；50-99KG:+1元/KG | AC13: 深圳 | AD13: 广州/深圳/东莞南城
A14: 直送专线 | B14: 萨凡纳直航36日达直送 | C14: {=IFERROR(VLOOKUP($C$5&"-直送特价",美东南直航系列!$A:$CT,INDEX(定位!$A:$W,MATCH($B14,定位!$A:$A,0),MATCH("*"&$D$5&"*"&"-BS",定位!$1:$1,0)),FALSE),"-")} -> - | D14: {=IFERROR(VLOOKUP($C$5&"-直送特价",美东南直航系列!$A:$CT,INDEX(定位!$A:$W,MATCH($B14,定位!$A:$A,0),MATCH("*"&$D$5&"*"&"-NBS",定位!$1:$1,0)),FALSE),"-")} -> - | E14: =IFERROR(VLOOKUP($C$5&"-直送特价",美东南直航系列!$A:$CT,_xlfn.XLOOKUP($B14,定位!A:A,定位!V:V),FALSE),"-") -> - | F14: =IFERROR(VLOOKUP($C$5&"-直送特价",美东南直航系列!$A:$CT,_xlfn.XLOOKUP($B14,定位!A:A,定位!W:W),FALSE),"-") -> - | G14: =IF(LEFT($C$5,3)<>"WM-","FBA卡派包税:【10-49KG:+1元/KG】","沃尔玛卡派包税: 【21-49KG:+2元/KG】； 【50-99KG:+1元/KG】；") -> FBA卡派包税:【10-49KG:+1元/KG】 | I14: 陆运 | J14: 中英专车-卡派 | K14: - | L14: - | M14: - | N14: - | O14: =IF(OR(AND($M$5="12KG+",$N$8="-"),AND($M$5="71KG+",$N$8="-")),"100KG+起收",IF($M$5="15CBM+","KG价","")) | Q14: 直航 | R14: 加拿大加西直航33日达-卡派 | S14: {=IFERROR(VLOOKUP($S$5,#REF!,INDEX(定位!$A:$W,MATCH($R14,定位!$A:$A,0),MATCH("*"&$T$5&"*"&"-BS",定位!$1:$1,0)),FALSE),"-")} -> - | T14: {=IFERROR(VLOOKUP($S$5,#REF!,INDEX(定位!$A:$W,MATCH($R14,定位!$A:$A,0),MATCH("*"&$T$5&"*"&"-NBS",定位!$1:$1,0)),FALSE),"-")} -> - | U14: =IFERROR(VLOOKUP($C$5,#REF!,_xlfn.XLOOKUP($R14,定位!A:A,定位!V:V),FALSE),"-") -> - | V14: =IFERROR(VLOOKUP($C$5,#REF!,_xlfn.XLOOKUP($R14,定位!A:A,定位!W:W),FALSE),"-") -> - | W14: 包税21-49KG:+1.5元/KG；50-99KG:+1元/KG | AC14: 东莞南城 | AD14: 广州/深圳/东莞南城
A15: 直送专线 | B15: 萨凡纳直航48日达直送 | C15: {=IFERROR(VLOOKUP($C$5&"-直送特价",美东南直航系列!$A:$CT,INDEX(定位!$A:$W,MATCH($B15,定位!$A:$A,0),MATCH("*"&$D$5&"*"&"-BS",定位!$1:$1,0)),FALSE),"-")} -> - | D15: {=IFERROR(VLOOKUP($C$5&"-直送特价",美东南直航系列!$A:$CT,INDEX(定位!$A:$W,MATCH($B15,定位!$A:$A,0),MATCH("*"&$D$5&"*"&"-NBS",定位!$1:$1,0)),FALSE),"-")} -> - | E15: =IFERROR(VLOOKUP($C$5&"-直送特价",美东南直航系列!$A:$CT,_xlfn.XLOOKUP($B15,定位!A:A,定位!V:V),FALSE),"-") -> - | F15: =IFERROR(VLOOKUP($C$5&"-直送特价",美东南直航系列!$A:$CT,_xlfn.XLOOKUP($B15,定位!A:A,定位!W:W),FALSE),"-") -> - | G15: =IF(LEFT($C$5,3)<>"WM-","FBA卡派包税:【10-49KG:+1元/KG】","沃尔玛卡派包税: 【21-49KG:+2元/KG】； 【50-99KG:+1元/KG】；") -> FBA卡派包税:【10-49KG:+1元/KG】 | I15: 陆运 | J15: 中英专车-DPD派 | K15: - | L15: - | M15: - | N15: - | O15: =IF(M5="100KG+","12-70KG：+2元/KG；"&CHAR(10)&"71-99KG：+1元/KG；",IF(M5="15CBM+","KG价","")) | Q15: 直航 | R15: 加拿大加西直航33日达-UPS派 | S15: {=IFERROR(VLOOKUP($S$5,#REF!,INDEX(定位!$A:$W,MATCH($R15,定位!$A:$A,0),MATCH("*"&$T$5&"*"&"-BS",定位!$1:$1,0)),FALSE),"-")} -> - | T15: {=IFERROR(VLOOKUP($S$5,#REF!,INDEX(定位!$A:$W,MATCH($R15,定位!$A:$A,0),MATCH("*"&$T$5&"*"&"-NBS",定位!$1:$1,0)),FALSE),"-")} -> - | U15: =IFERROR(VLOOKUP($C$5,#REF!,_xlfn.XLOOKUP($R15,定位!A:A,定位!V:V),FALSE),"-") -> - | V15: =IFERROR(VLOOKUP($C$5,#REF!,_xlfn.XLOOKUP($R15,定位!A:A,定位!W:W),FALSE),"-") -> - | W15: 包税21-49KG:+1.5元/KG；50-99KG:+1元/KG | AC15: 中山 | AD15: 中山/汕头
A16: 直送专线 | B16: 休斯顿直航38日达直送特价 | C16: {=IFERROR(VLOOKUP($C$5&"-直送特价",'美中-休斯顿'!$A:$BT,INDEX(定位!$A:$W,MATCH($B16,定位!$A:$A,0),MATCH("*"&$D$5&"*"&"-BS",定位!$1:$1,0)),FALSE),"-")} -> - | D16: {=IFERROR(VLOOKUP($C$5&"-直送特价",'美中-休斯顿'!$A:$BT,INDEX(定位!$A:$W,MATCH($B16,定位!$A:$A,0),MATCH("*"&$D$5&"*"&"-NBS",定位!$1:$1,0)),FALSE),"-")} -> - | E16: =IFERROR(VLOOKUP($C$5&"-直送特价",'美中-休斯顿'!$A:$BT,_xlfn.XLOOKUP($B16,定位!A:A,定位!V:V),FALSE),"-") -> - | F16: =IFERROR(VLOOKUP($C$5&"-直送特价",'美中-休斯顿'!$A:$BT,_xlfn.XLOOKUP($B16,定位!A:A,定位!W:W),FALSE),"-") -> - | G16: =IF(LEFT($C$5,3)<>"WM-","FBA卡派包税:【10-49KG:+1元/KG】","沃尔玛卡派包税: 【21-49KG:+2元/KG】； 【50-99KG:+1元/KG】；") -> FBA卡派包税:【10-49KG:+1元/KG】 | I16: 陆运 | J16: 中英专车快卡-卡派 | K16: - | L16: - | M16: - | N16: - | O16: =IF(OR(AND($M$5="12KG+",$N$8="-"),AND($M$5="71KG+",$N$8="-")),"100KG+起收",IF($M$5="15CBM+","KG价","")) | Q16: 美转加 | R16: 美转加加东25日达-卡派（OA） | S16: {=IFERROR(VLOOKUP($S$5,#REF!,INDEX(定位!$A:$W,MATCH($R16,定位!$A:$A,0),MATCH("*"&$T$5&"*"&"-BS",定位!$1:$1,0)),FALSE),"-")} -> - | T16: {=IFERROR(VLOOKUP($S$5,#REF!,INDEX(定位!$A:$W,MATCH($R16,定位!$A:$A,0),MATCH("*"&$T$5&"*"&"-NBS",定位!$1:$1,0)),FALSE),"-")} -> - | U16: =IFERROR(VLOOKUP($C$5,#REF!,_xlfn.XLOOKUP($R16,定位!A:A,定位!V:V),FALSE),"-") -> - | V16: =IFERROR(VLOOKUP($C$5,#REF!,_xlfn.XLOOKUP($R16,定位!A:A,定位!W:W),FALSE),"-") -> - | W16: 包税21-49KG:+1.5元/KG；50-99KG:+1元/KG | AC16: 汕头 | AD16: 中山/汕头
A17: 直送专线 | B17: 芝加哥海铁28日达直送特价 | C17: {=IFERROR(VLOOKUP($C$5&"-直送特价",'美中-芝加哥'!$A:$CX,INDEX(定位!$A:$W,MATCH($B17,定位!$A:$A,0),MATCH("*"&$D$5&"*"&"-BS",定位!$1:$1,0)),FALSE),"-")} -> - | D17: {=IFERROR(VLOOKUP($C$5&"-直送特价",'美中-芝加哥'!$A:$CX,INDEX(定位!$A:$W,MATCH($B17,定位!$A:$A,0),MATCH("*"&$D$5&"*"&"-NBS",定位!$1:$1,0)),FALSE),"-")} -> - | E17: =IFERROR(VLOOKUP($C$5&"-直送特价",'美中-芝加哥'!$A:$CX,_xlfn.XLOOKUP($B17,定位!A:A,定位!V:V),FALSE),"-") -> - | F17: =IFERROR(VLOOKUP($C$5&"-直送特价",'美中-芝加哥'!$A:$CX,_xlfn.XLOOKUP($B17,定位!A:A,定位!W:W),FALSE),"-") -> - | G17: =IF(LEFT($C$5,3)<>"WM-","FBA卡派包税:【10-49KG:+1元/KG】","沃尔玛卡派包税: 【21-49KG:+2元/KG】； 【50-99KG:+1元/KG】；") -> FBA卡派包税:【10-49KG:+1元/KG】 | I17: 陆运 | J17: 中英专车快卡-DPD派 | K17: - | L17: - | M17: - | N17: - | O17: =IF(M5="100KG+","12-70KG：+2元/KG；"&CHAR(10)&"71-99KG：+1元/KG；",IF(M5="15CBM+","KG价","")) | Q17: 美转加 | R17: 美转加加东25日达-UPS派（OA） | S17: {=IFERROR(VLOOKUP($S$5,#REF!,INDEX(定位!$A:$W,MATCH($R17,定位!$A:$A,0),MATCH("*"&$T$5&"*"&"-BS",定位!$1:$1,0)),FALSE),"-")} -> - | T17: {=IFERROR(VLOOKUP($S$5,#REF!,INDEX(定位!$A:$W,MATCH($R17,定位!$A:$A,0),MATCH("*"&$T$5&"*"&"-NBS",定位!$1:$1,0)),FALSE),"-")} -> - | U17: =IFERROR(VLOOKUP($C$5,#REF!,_xlfn.XLOOKUP($R17,定位!A:A,定位!V:V),FALSE),"-") -> - | V17: =IFERROR(VLOOKUP($C$5,#REF!,_xlfn.XLOOKUP($R17,定位!A:A,定位!W:W),FALSE),"-") -> - | W17: 包税21-49KG:+1.5元/KG；50-99KG:+1元/KG | AC17: 厦门 | AD17: 厦门/泉州/福州
A18: 直送专线 | B18: 芝加哥海铁32日达直送特价 | C18: {=IFERROR(VLOOKUP($C$5&"-直送特价",'美中-芝加哥'!$A:$CX,INDEX(定位!$A:$W,MATCH($B18,定位!$A:$A,0),MATCH("*"&$D$5&"*"&"-BS",定位!$1:$1,0)),FALSE),"-")} -> - | D18: {=IFERROR(VLOOKUP($C$5&"-直送特价",'美中-芝加哥'!$A:$CX,INDEX(定位!$A:$W,MATCH($B18,定位!$A:$A,0),MATCH("*"&$D$5&"*"&"-NBS",定位!$1:$1,0)),FALSE),"-")} -> - | E18: =IFERROR(VLOOKUP($C$5&"-直送特价",'美中-芝加哥'!$A:$CX,_xlfn.XLOOKUP($B18,定位!A:A,定位!V:V),FALSE),"-") -> - | F18: =IFERROR(VLOOKUP($C$5&"-直送特价",'美中-芝加哥'!$A:$CX,_xlfn.XLOOKUP($B18,定位!A:A,定位!W:W),FALSE),"-") -> - | G18: =IF(LEFT($C$5,3)<>"WM-","FBA卡派包税:【10-49KG:+1元/KG】","沃尔玛卡派包税: 【21-49KG:+2元/KG】； 【50-99KG:+1元/KG】；") -> FBA卡派包税:【10-49KG:+1元/KG】 | I18: 海运 | J18: 英国海卡(特价）-KG价 | K18: =IFERROR(IF(M5<>"15CBM+",_xlfn.LET(_xlpm.X,#REF!,_xlpm.Y,2,IF(VLOOKUP(L5,AC:AD,2,0)="广州/深圳/东莞南城",VLOOKUP(K5,_xlpm.X,_xlpm.Y,0),IF(VLOOKUP(L5,AC:AD,2,0)="重庆",VLOOKUP(K5,_xlpm.X,_xlpm.Y+1,0),IF(VLOOKUP(L5,AC:AD,2,0)="中山/汕头",VLOOKUP(K5,_xlpm.X,_xlpm.Y+3,0),IF(VLOOKUP(L5,AC:AD,2,0)="厦门/泉州/福州",VLOOKUP(K5,_xlpm.X,_xlpm.Y+4,0),IF(VLOOKUP(L5,AC:AD,2,0)="义乌",VLOOKUP(K5,_xlpm.X,_xlpm.Y+5,0),IF(VLOOKUP(L5,AC:AD,2,0)="上海/宁波",VLOOKUP(K5,_xlpm.X,_xlpm.Y+6,0),IF(VLOOKUP(L5,AC:AD,2,0)="青岛/郑州/绍兴/苏州/杭州仓/连云港/温州/台州/南京/合肥",VLOOKUP(K5,_xlpm.X,_xlpm.Y+7,0),IF(VLOOKUP(L5,AC:AD,2,0)="武汉/长沙/成都",VLOOKUP(K5,_xlpm.X,_xlpm.Y+8,0),IF(VLOOKUP(L5,AC:AD,2,0)="天津/南昌/石家庄",VLOOKUP(K5,_xlpm.X,_xlpm.Y+8,0),IF(VLOOKUP(L5,AC:AD,2,0)="西安",VLOOKUP(K5,_xlpm.X,_xlpm.Y+2,0),IF(VLOOKUP(L5,AC:AD,2,0)="济南/潍坊",VLOOKUP(K5,_xlpm.X,_xlpm.Y+9,0),IF(VLOOKUP(L5,AC:AD,2,0)="沧州/保定",VLOOKUP(K5,_xlpm.X,_xlpm.Y+10,0)))))))))))))),"-"),"-") -> - | L18: =IFERROR(IF(M5<>"15CBM+",_xlfn.LET(_xlpm.X,#REF!,_xlpm.Y,14,IF(VLOOKUP(L5,AC:AD,2,0)="广州/深圳/东莞南城",VLOOKUP(K5,_xlpm.X,_xlpm.Y,0),IF(VLOOKUP(L5,AC:AD,2,0)="重庆",VLOOKUP(K5,_xlpm.X,_xlpm.Y+1,0),IF(VLOOKUP(L5,AC:AD,2,0)="中山/汕头",VLOOKUP(K5,_xlpm.X,_xlpm.Y+3,0),IF(VLOOKUP(L5,AC:AD,2,0)="厦门/泉州/福州",VLOOKUP(K5,_xlpm.X,_xlpm.Y+4,0),IF(VLOOKUP(L5,AC:AD,2,0)="义乌",VLOOKUP(K5,_xlpm.X,_xlpm.Y+5,0),IF(VLOOKUP(L5,AC:AD,2,0)="上海/宁波",VLOOKUP(K5,_xlpm.X,_xlpm.Y+6,0),IF(VLOOKUP(L5,AC:AD,2,0)="青岛/郑州/绍兴/苏州/杭州仓/连云港/温州/台州/南京/合肥",VLOOKUP(K5,_xlpm.X,_xlpm.Y+7,0),IF(VLOOKUP(L5,AC:AD,2,0)="武汉/长沙/成都",VLOOKUP(K5,_xlpm.X,_xlpm.Y+8,0),IF(VLOOKUP(L5,AC:AD,2,0)="天津/南昌/石家庄",VLOOKUP(K5,_xlpm.X,_xlpm.Y+8,0),IF(VLOOKUP(L5,AC:AD,2,0)="西安",VLOOKUP(K5,_xlpm.X,_xlpm.Y+2,0),IF(VLOOKUP(L5,AC:AD,2,0)="济南/潍坊",VLOOKUP(K5,_xlpm.X,_xlpm.Y+9,0),IF(VLOOKUP(L5,AC:AD,2,0)="沧州/保定",VLOOKUP(K5,_xlpm.X,_xlpm.Y+10,0)))))))))))))),"-"),"-") -> - | M18: =IFERROR(IF(M5<>"15CBM+",_xlfn.LET(_xlpm.X,#REF!,_xlpm.Y,26,IF(VLOOKUP(L5,AC:AD,2,0)="广州/深圳/东莞南城",VLOOKUP(K5,_xlpm.X,_xlpm.Y,0),IF(VLOOKUP(L5,AC:AD,2,0)="重庆",VLOOKUP(K5,_xlpm.X,_xlpm.Y,0),IF(VLOOKUP(L5,AC:AD,2,0)="中山/汕头",VLOOKUP(K5,_xlpm.X,_xlpm.Y,0),IF(VLOOKUP(L5,AC:AD,2,0)="厦门/泉州/福州",VLOOKUP(K5,_xlpm.X,_xlpm.Y,0),IF(VLOOKUP(L5,AC:AD,2,0)="义乌",VLOOKUP(K5,_xlpm.X,_xlpm.Y,0),IF(VLOOKUP(L5,AC:AD,2,0)="上海/宁波",VLOOKUP(K5,_xlpm.X,_xlpm.Y,0),IF(VLOOKUP(L5,AC:AD,2,0)="青岛/郑州/绍兴/苏州/杭州仓/连云港/温州/台州/南京/合肥",VLOOKUP(K5,_xlpm.X,_xlpm.Y,0),IF(VLOOKUP(L5,AC:AD,2,0)="武汉/长沙/成都",VLOOKUP(K5,_xlpm.X,_xlpm.Y,0),IF(VLOOKUP(L5,AC:AD,2,0)="天津/南昌/石家庄",VLOOKUP(K5,_xlpm.X,_xlpm.Y,0),IF(VLOOKUP(L5,AC:AD,2,0)="西安",VLOOKUP(K5,_xlpm.X,_xlpm.Y,0),IF(VLOOKUP(L5,AC:AD,2,0)="济南/潍坊",VLOOKUP(K5,_xlpm.X,_xlpm.Y,0),IF(VLOOKUP(L5,AC:AD,2,0)="沧州/保定",VLOOKUP(K5,_xlpm.X,_xlpm.Y,0)))))))))))))),"-"),"-") -> - | N18: =IFERROR(IF(M5<>"15CBM+",_xlfn.LET(_xlpm.X,#REF!,_xlpm.Y,27,IF(VLOOKUP(L5,AC:AD,2,0)="广州/深圳/东莞南城",VLOOKUP(K5,_xlpm.X,_xlpm.Y,0),IF(VLOOKUP(L5,AC:AD,2,0)="重庆",VLOOKUP(K5,_xlpm.X,_xlpm.Y,0),IF(VLOOKUP(L5,AC:AD,2,0)="中山/汕头",VLOOKUP(K5,_xlpm.X,_xlpm.Y,0),IF(VLOOKUP(L5,AC:AD,2,0)="厦门/泉州/福州",VLOOKUP(K5,_xlpm.X,_xlpm.Y,0),IF(VLOOKUP(L5,AC:AD,2,0)="义乌",VLOOKUP(K5,_xlpm.X,_xlpm.Y,0),IF(VLOOKUP(L5,AC:AD,2,0)="上海/宁波",VLOOKUP(K5,_xlpm.X,_xlpm.Y,0),IF(VLOOKUP(L5,AC:AD,2,0)="青岛/郑州/绍兴/苏州/杭州仓/连云港/温州/台州/南京/合肥",VLOOKUP(K5,_xlpm.X,_xlpm.Y,0),IF(VLOOKUP(L5,AC:AD,2,0)="武汉/长沙/成都",VLOOKUP(K5,_xlpm.X,_xlpm.Y,0),IF(VLOOKUP(L5,AC:AD,2,0)="天津/南昌/石家庄",VLOOKUP(K5,_xlpm.X,_xlpm.Y,0),IF(VLOOKUP(L5,AC:AD,2,0)="西安",VLOOKUP(K5,_xlpm.X,_xlpm.Y,0),IF(VLOOKUP(L5,AC:AD,2,0)="济南/潍坊",VLOOKUP(K5,_xlpm.X,_xlpm.Y,0),IF(VLOOKUP(L5,AC:AD,2,0)="沧州/保定",VLOOKUP(K5,_xlpm.X,_xlpm.Y,0)))))))))))))),"-"),"-") -> - | O18: =IF(M5="100KG+","12-70KG：+2元/KG；"&CHAR(10)&"71-99KG：+1元/KG；",IF(M5="15CBM+","KG价","")) | Q18: 美转加 | R18: 美转加加西25日达-卡派（OA） | S18: {=IFERROR(VLOOKUP($S$5,#REF!,INDEX(定位!$A:$W,MATCH($R18,定位!$A:$A,0),MATCH("*"&$T$5&"*"&"-BS",定位!$1:$1,0)),FALSE),"-")} -> - | T18: {=IFERROR(VLOOKUP($S$5,#REF!,INDEX(定位!$A:$W,MATCH($R18,定位!$A:$A,0),MATCH("*"&$T$5&"*"&"-NBS",定位!$1:$1,0)),FALSE),"-")} -> - | U18: =IFERROR(VLOOKUP($C$5,#REF!,_xlfn.XLOOKUP($R18,定位!A:A,定位!V:V),FALSE),"-") -> - | V18: =IFERROR(VLOOKUP($C$5,#REF!,_xlfn.XLOOKUP($R18,定位!A:A,定位!W:W),FALSE),"-") -> - | W18: 包税21-49KG:+1.5元/KG；50-99KG:+1元/KG | AC18: 泉州 | AD18: 厦门/泉州/福州
A19: 直送专线 | B19: 芝加哥海铁22日达直送特价 | C19: {=IFERROR(VLOOKUP($C$5&"-直送特价",'美中-芝加哥'!$A:$CX,INDEX(定位!$A:$W,MATCH($B19,定位!$A:$A,0),MATCH("*"&$D$5&"*"&"-BS",定位!$1:$1,0)),FALSE),"-")} -> - | D19: {=IFERROR(VLOOKUP($C$5&"-直送特价",'美中-芝加哥'!$A:$CX,INDEX(定位!$A:$W,MATCH($B19,定位!$A:$A,0),MATCH("*"&$D$5&"*"&"-NBS",定位!$1:$1,0)),FALSE),"-")} -> - | E19: =IFERROR(VLOOKUP($C$5&"-直送特价",'美中-芝加哥'!$A:$CX,_xlfn.XLOOKUP($B19,定位!A:A,定位!V:V),FALSE),"-") -> - | F19: =IFERROR(VLOOKUP($C$5&"-直送特价",'美中-芝加哥'!$A:$CX,_xlfn.XLOOKUP($B19,定位!A:A,定位!W:W),FALSE),"-") -> - | G19: =IF(LEFT($C$5,3)<>"WM-","FBA卡派包税:【10-49KG:+1元/KG】","沃尔玛卡派包税: 【21-49KG:+2元/KG】； 【50-99KG:+1元/KG】；") -> FBA卡派包税:【10-49KG:+1元/KG】 | I19: 海运 | J19: 英国海卡-CBM价 | K19: - | L19: =IFERROR(IF(M5="15CBM+",_xlfn.LET(_xlpm.X,#REF!,_xlpm.Y,28,IF(VLOOKUP(L5,AC:AD,2,0)="广州/深圳/东莞南城",VLOOKUP(K5,_xlpm.X,_xlpm.Y,0),IF(VLOOKUP(L5,AC:AD,2,0)="重庆",VLOOKUP(K5,_xlpm.X,_xlpm.Y+1,0),IF(VLOOKUP(L5,AC:AD,2,0)="中山/汕头",VLOOKUP(K5,_xlpm.X,_xlpm.Y+3,0),IF(VLOOKUP(L5,AC:AD,3,0)="厦门/泉州/福州",VLOOKUP(K5,_xlpm.X,_xlpm.Y+4,0),IF(VLOOKUP(L5,AC:AD,2,0)="义乌",VLOOKUP(K5,_xlpm.X,_xlpm.Y+5,0),IF(VLOOKUP(L5,AC:AD,2,0)="上海/宁波",VLOOKUP(K5,_xlpm.X,_xlpm.Y+6,0),IF(VLOOKUP(L5,AC:AD,2,0)="青岛/郑州/绍兴/苏州/杭州仓/连云港/温州/台州/南京/合肥",VLOOKUP(K5,_xlpm.X,_xlpm.Y+7,0),IF(VLOOKUP(L5,AC:AD,2,0)="武汉/长沙/成都",VLOOKUP(K5,_xlpm.X,_xlpm.Y+8,0),IF(VLOOKUP(L5,AC:AD,2,0)="天津/南昌/石家庄",VLOOKUP(K5,_xlpm.X,_xlpm.Y+8,0),IF(VLOOKUP(L5,AC:AD,2,0)="西安",VLOOKUP(K5,_xlpm.X,_xlpm.Y+2,0),IF(VLOOKUP(L5,AC:AD,2,0)="济南/潍坊",VLOOKUP(K5,_xlpm.X,_xlpm.Y+9,0),IF(VLOOKUP(L5,AC:AD,2,0)="沧州/保定",VLOOKUP(K5,_xlpm.X,_xlpm.Y+10,0)))))))))))))),"-"),"-") -> - | M19: =IFERROR(IF(M5="15CBM+",_xlfn.LET(_xlpm.X,#REF!,_xlpm.Y,40,IF(VLOOKUP(L5,AC:AD,2,0)="广州/深圳/东莞南城",VLOOKUP(K5,_xlpm.X,_xlpm.Y,0),IF(VLOOKUP(L5,AC:AD,2,0)="重庆",VLOOKUP(K5,_xlpm.X,_xlpm.Y,0),IF(VLOOKUP(L5,AC:AD,2,0)="中山/汕头",VLOOKUP(K5,_xlpm.X,_xlpm.Y,0),IF(VLOOKUP(L5,AC:AD,3,0)="厦门/泉州/福州",VLOOKUP(K5,_xlpm.X,_xlpm.Y,0),IF(VLOOKUP(L5,AC:AD,2,0)="义乌",VLOOKUP(K5,_xlpm.X,_xlpm.Y,0),IF(VLOOKUP(L5,AC:AD,2,0)="上海/宁波",VLOOKUP(K5,_xlpm.X,_xlpm.Y,0),IF(VLOOKUP(L5,AC:AD,2,0)="青岛/郑州/绍兴/苏州/杭州仓/连云港/温州/台州/南京/合肥",VLOOKUP(K5,_xlpm.X,_xlpm.Y,0),IF(VLOOKUP(L5,AC:AD,2,0)="武汉/长沙/成都",VLOOKUP(K5,_xlpm.X,_xlpm.Y,0),IF(VLOOKUP(L5,AC:AD,2,0)="天津/南昌/石家庄",VLOOKUP(K5,_xlpm.X,_xlpm.Y,0),IF(VLOOKUP(L5,AC:AD,2,0)="西安",VLOOKUP(K5,_xlpm.X,_xlpm.Y,0),IF(VLOOKUP(L5,AC:AD,2,0)="济南/潍坊",VLOOKUP(K5,_xlpm.X,_xlpm.Y,0),IF(VLOOKUP(L5,AC:AD,2,0)="沧州/保定",VLOOKUP(K5,_xlpm.X,_xlpm.Y,0)))))))))))))),"-"),"单询") -> - | N19: =IFERROR(IF(M5="15CBM+",_xlfn.LET(_xlpm.X,#REF!,_xlpm.Y,41,IF(VLOOKUP(L5,AC:AD,2,0)="广州/深圳/东莞南城",VLOOKUP(K5,_xlpm.X,_xlpm.Y,0),IF(VLOOKUP(L5,AC:AD,2,0)="重庆",VLOOKUP(K5,_xlpm.X,_xlpm.Y,0),IF(VLOOKUP(L5,AC:AD,2,0)="中山/汕头",VLOOKUP(K5,_xlpm.X,_xlpm.Y,0),IF(VLOOKUP(L5,AC:AD,3,0)="厦门/泉州/福州",VLOOKUP(K5,_xlpm.X,_xlpm.Y,0),IF(VLOOKUP(L5,AC:AD,2,0)="义乌",VLOOKUP(K5,_xlpm.X,_xlpm.Y,0),IF(VLOOKUP(L5,AC:AD,2,0)="上海/宁波",VLOOKUP(K5,_xlpm.X,_xlpm.Y,0),IF(VLOOKUP(L5,AC:AD,2,0)="青岛/郑州/绍兴/苏州/杭州仓/连云港/温州/台州/南京/合肥",VLOOKUP(K5,_xlpm.X,_xlpm.Y,0),IF(VLOOKUP(L5,AC:AD,2,0)="武汉/长沙/成都",VLOOKUP(K5,_xlpm.X,_xlpm.Y,0),IF(VLOOKUP(L5,AC:AD,2,0)="天津/南昌/石家庄",VLOOKUP(K5,_xlpm.X,_xlpm.Y,0),IF(VLOOKUP(L5,AC:AD,2,0)="西安",VLOOKUP(K5,_xlpm.X,_xlpm.Y,0),IF(VLOOKUP(L5,AC:AD,2,0)="济南/潍坊",VLOOKUP(K5,_xlpm.X,_xlpm.Y,0),IF(VLOOKUP(L5,AC:AD,2,0)="沧州/保定",VLOOKUP(K5,_xlpm.X,_xlpm.Y,0)))))))))))))),"-"),"单询") -> - | O19: =IF(N19="单询","单询",IF(AND(M5<>"15CBM+",N19="-"),"立方价","【1-4.9CBM：+60元/CBM】; "&CHAR(10)&"【5-9.9CBM：+40元/CBM】; "&CHAR(10)&"【10-14.9CBM：+20元/CBM】; ")) -> 立方价 | Q19: 美转加 | R19: 美转加加西25日达-UPS派（OA） | S19: {=IFERROR(VLOOKUP($S$5,#REF!,INDEX(定位!$A:$W,MATCH($R19,定位!$A:$A,0),MATCH("*"&$T$5&"*"&"-BS",定位!$1:$1,0)),FALSE),"-")} -> - | T19: {=IFERROR(VLOOKUP($S$5,#REF!,INDEX(定位!$A:$W,MATCH($R19,定位!$A:$A,0),MATCH("*"&$T$5&"*"&"-NBS",定位!$1:$1,0)),FALSE),"-")} -> - | U19: =IFERROR(VLOOKUP($C$5,#REF!,_xlfn.XLOOKUP($R19,定位!A:A,定位!V:V),FALSE),"-") -> - | V19: =IFERROR(VLOOKUP($C$5,#REF!,_xlfn.XLOOKUP($R19,定位!A:A,定位!W:W),FALSE),"-") -> - | W19: 包税21-49KG:+1.5元/KG；50-99KG:+1元/KG | AC19: 福州 | AD19: 厦门/泉州/福州
A20: 拆派 | B20: 美森极速12日达 | C20: {=IFERROR(VLOOKUP($C$5,'美西-美森(12-17)'!$A:$DF,INDEX(定位!$A:$W,MATCH($B20,定位!$A:$A,0),MATCH("*"&$D$5&"*"&"-BS",定位!$1:$1,0)),FALSE),"-")} -> - | D20: {=IFERROR(VLOOKUP($C$5,'美西-美森(12-17)'!$A:$DF,INDEX(定位!$A:$W,MATCH($B20,定位!$A:$A,0),MATCH("*"&$D$5&"*"&"-NBS",定位!$1:$1,0)),FALSE),"-")} -> - | E20: =IFERROR(VLOOKUP($C$5,'美西-美森(12-17)'!$A:$DF,_xlfn.XLOOKUP($B20,定位!A:A,定位!V:V),FALSE),"-") -> - | F20: =IFERROR(VLOOKUP($C$5,'美西-美森(12-17)'!$A:$DF,_xlfn.XLOOKUP($B20,定位!A:A,定位!W:W),FALSE),"-") -> - | G20: =IF(LEFT($C$5,3)<>"WM-","FBA卡派包税:【10-49KG:+1元/KG】","沃尔玛卡派包税: 【21-49KG:+2元/KG】； 【50-99KG:+1元/KG】；") -> FBA卡派包税:【10-49KG:+1元/KG】 | I20: 海运 | J20: 英国海派-DPD派 | K20: {=IF(M5<>"15CBM+",_xlfn.LET(_xlpm.X,#REF!,IFERROR(_xlfn._xlws.FILTER(_xlpm.X,(ISNUMBER(FIND(L5,#REF!,1)))),"-")),"-")} -> - | L20: {=IF(M5<>"15CBM+",_xlfn.LET(_xlpm.X,#REF!,IFERROR(_xlfn._xlws.FILTER(_xlpm.X,(ISNUMBER(FIND(L5,#REF!,1)))),"-")),"-")} -> - | M20: {=IF(M5<>"15CBM+",_xlfn.LET(_xlpm.X,#REF!,IFERROR(_xlfn._xlws.FILTER(_xlpm.X,(ISNUMBER(FIND(L5,#REF!,1)))),"-")),"-")} -> - | N20: {=IF(M5<>"15CBM+",_xlfn.LET(_xlpm.X,#REF!,IFERROR(_xlfn._xlws.FILTER(_xlpm.X,(ISNUMBER(FIND(L5,#REF!,1)))),"-")),"-")} -> - | O20: =IF(M5="15CBM+","KG价","") | Q20: 美转加 | R20: 美转加加东20日达-卡派（HD） | S20: {=IFERROR(VLOOKUP($S$5,#REF!,INDEX(定位!$A:$W,MATCH($R20,定位!$A:$A,0),MATCH("*"&$T$5&"*"&"-BS",定位!$1:$1,0)),FALSE),"-")} -> - | T20: {=IFERROR(VLOOKUP($S$5,#REF!,INDEX(定位!$A:$W,MATCH($R20,定位!$A:$A,0),MATCH("*"&$T$5&"*"&"-NBS",定位!$1:$1,0)),FALSE),"-")} -> - | U20: =IFERROR(VLOOKUP($C$5,#REF!,_xlfn.XLOOKUP($R20,定位!A:A,定位!V:V),FALSE),"-") -> - | V20: =IFERROR(VLOOKUP($C$5,#REF!,_xlfn.XLOOKUP($R20,定位!A:A,定位!W:W),FALSE),"-") -> - | W20: 包税21-49KG:+1.5元/KG；50-99KG:+1元/KG | AC20: 义乌 | AD20: 义乌
A21: 拆派 | B21: 洛杉矶CLX13日达 | C21: {=IFERROR(VLOOKUP($C$5,'美西-美森(12-17)'!$A:$DF,INDEX(定位!$A:$W,MATCH($B21,定位!$A:$A,0),MATCH("*"&$D$5&"*"&"-BS",定位!$1:$1,0)),FALSE),"-")} -> - | D21: {=IFERROR(VLOOKUP($C$5,'美西-美森(12-17)'!$A:$DF,INDEX(定位!$A:$W,MATCH($B21,定位!$A:$A,0),MATCH("*"&$D$5&"*"&"-NBS",定位!$1:$1,0)),FALSE),"-")} -> - | E21: =IFERROR(VLOOKUP($C$5,'美西-美森(12-17)'!$A:$DF,_xlfn.XLOOKUP($B21,定位!A:A,定位!V:V),FALSE),"-") -> - | F21: =IFERROR(VLOOKUP($C$5,'美西-美森(12-17)'!$A:$DF,_xlfn.XLOOKUP(B21,定位!A:A,定位!W:W),FALSE),"-") -> - | G21: =IF(LEFT($C$5,3)<>"WM-","FBA卡派包税:【10-49KG:+1元/KG】","沃尔玛卡派包税: 【21-49KG:+2元/KG】； 【50-99KG:+1元/KG】；") -> FBA卡派包税:【10-49KG:+1元/KG】 | I21: 海运 | J21: 英国海派AEU1-DPD派(暂停) | K21: {=IF(M5<>"15CBM+",_xlfn.LET(_xlpm.X,#REF!,IFERROR(_xlfn._xlws.FILTER(_xlpm.X,(ISNUMBER(FIND(L5,#REF!,1)))),"-")),"-")} -> - | L21: {=IF(M5<>"15CBM+",_xlfn.LET(_xlpm.X,#REF!,IFERROR(_xlfn._xlws.FILTER(_xlpm.X,(ISNUMBER(FIND(L5,#REF!,1)))),"-")),"-")} -> - | M21: {=IF(M5<>"15CBM+",_xlfn.LET(_xlpm.X,#REF!,IFERROR(_xlfn._xlws.FILTER(_xlpm.X,(ISNUMBER(FIND(L5,#REF!,1)))),"-")),"-")} -> - | N21: {=IF(M5<>"15CBM+",_xlfn.LET(_xlpm.X,#REF!,IFERROR(_xlfn._xlws.FILTER(_xlpm.X,(ISNUMBER(FIND(L5,#REF!,1)))),"-")),"-")} -> - | O21: =IF(M5="15CBM+","KG价","") | Q21: 美转加 | R21: 美转加加东20日达-UPS派（HD） | S21: {=IFERROR(VLOOKUP($S$5,#REF!,INDEX(定位!$A:$W,MATCH($R21,定位!$A:$A,0),MATCH("*"&$T$5&"*"&"-BS",定位!$1:$1,0)),FALSE),"-")} -> - | T21: {=IFERROR(VLOOKUP($S$5,#REF!,INDEX(定位!$A:$W,MATCH($R21,定位!$A:$A,0),MATCH("*"&$T$5&"*"&"-NBS",定位!$1:$1,0)),FALSE),"-")} -> - | U21: =IFERROR(VLOOKUP($C$5,#REF!,_xlfn.XLOOKUP($R21,定位!A:A,定位!V:V),FALSE),"-") -> - | V21: =IFERROR(VLOOKUP($C$5,#REF!,_xlfn.XLOOKUP($R21,定位!A:A,定位!W:W),FALSE),"-") -> - | W21: 包税21-49KG:+1.5元/KG；50-99KG:+1元/KG | AC21: 上海 | AD21: 上海/宁波
A22: 拆派 | B22: 洛杉矶MAX14日达 | C22: {=IFERROR(VLOOKUP($C$5,'美西-美森(12-17)'!$A:$DF,INDEX(定位!$A:$W,MATCH($B22,定位!$A:$A,0),MATCH("*"&$D$5&"*"&"-BS",定位!$1:$1,0)),FALSE),"-")} -> - | D22: {=IFERROR(VLOOKUP($C$5,'美西-美森(12-17)'!$A:$DF,INDEX(定位!$A:$W,MATCH($B22,定位!$A:$A,0),MATCH("*"&$D$5&"*"&"-NBS",定位!$1:$1,0)),FALSE),"-")} -> - | E22: =IFERROR(VLOOKUP($C$5,'美西-美森(12-17)'!$A:$DF,_xlfn.XLOOKUP($B22,定位!A:A,定位!V:V),FALSE),"-") -> - | F22: =IFERROR(VLOOKUP($C$5,'美西-美森(12-17)'!$A:$DF,_xlfn.XLOOKUP(B22,定位!A:A,定位!W:W),FALSE),"-") -> - | G22: =IF(LEFT($C$5,3)<>"WM-","FBA卡派包税:【10-49KG:+1元/KG】","沃尔玛卡派包税: 【21-49KG:+2元/KG】； 【50-99KG:+1元/KG】；") -> FBA卡派包税:【10-49KG:+1元/KG】 | I22: 海运 | J22: 英国海派限时达 | K22: {=IF(M5<>"15CBM+",_xlfn.LET(_xlpm.X,#REF!,IFERROR(_xlfn._xlws.FILTER(_xlpm.X,(ISNUMBER(FIND(L5,#REF!,1)))),"-")),"-")} -> - | L22: {=IF(M5<>"15CBM+",_xlfn.LET(_xlpm.X,#REF!,IFERROR(_xlfn._xlws.FILTER(_xlpm.X,(ISNUMBER(FIND(L5,#REF!,1)))),"-")),"-")} -> - | M22: {=IF(M5<>"15CBM+",_xlfn.LET(_xlpm.X,#REF!,IFERROR(_xlfn._xlws.FILTER(_xlpm.X,(ISNUMBER(FIND(L5,#REF!,1)))),"-")),"-")} -> - | N22: {=IF(M5<>"15CBM+",_xlfn.LET(_xlpm.X,#REF!,IFERROR(_xlfn._xlws.FILTER(_xlpm.X,(ISNUMBER(FIND(L5,#REF!,1)))),"-")),"-")} -> - | O22: =IF(M5="15CBM+","KG价","") | Q22: 美转加 | R22: 美转加加西20日达-卡派（HD） | S22: {=IFERROR(VLOOKUP($S$5,#REF!,INDEX(定位!$A:$W,MATCH($R22,定位!$A:$A,0),MATCH("*"&$T$5&"*"&"-BS",定位!$1:$1,0)),FALSE),"-")} -> - | T22: {=IFERROR(VLOOKUP($S$5,#REF!,INDEX(定位!$A:$W,MATCH($R22,定位!$A:$A,0),MATCH("*"&$T$5&"*"&"-NBS",定位!$1:$1,0)),FALSE),"-")} -> - | U22: =IFERROR(VLOOKUP($C$5,#REF!,_xlfn.XLOOKUP($R22,定位!A:A,定位!V:V),FALSE),"-") -> - | V22: =IFERROR(VLOOKUP($C$5,#REF!,_xlfn.XLOOKUP($R22,定位!A:A,定位!W:W),FALSE),"-") -> - | W22: 包税21-49KG:+1.5元/KG；50-99KG:+1元/KG | AC22: 宁波 | AD22: 上海/宁波
A23: 拆派 | B23: 洛杉矶EXX16日达 | C23: {=IFERROR(VLOOKUP($C$5,'美西-美森(12-17)'!$A:$DF,INDEX(定位!$A:$W,MATCH($B23,定位!$A:$A,0),MATCH("*"&$D$5&"*"&"-BS",定位!$1:$1,0)),FALSE),"-")} -> - | D23: {=IFERROR(VLOOKUP($C$5,'美西-美森(12-17)'!$A:$DF,INDEX(定位!$A:$W,MATCH($B23,定位!$A:$A,0),MATCH("*"&$D$5&"*"&"-NBS",定位!$1:$1,0)),FALSE),"-")} -> - | E23: =IFERROR(VLOOKUP($C$5,'美西-美森(12-17)'!$A:$DF,_xlfn.XLOOKUP($B23,定位!A:A,定位!V:V),FALSE),"-") -> - | F23: =IFERROR(VLOOKUP($C$5,'美西-美森(12-17)'!$A:$DF,_xlfn.XLOOKUP(B23,定位!A:A,定位!W:W),FALSE),"-") -> - | G23: =IF(LEFT($C$5,3)<>"WM-","FBA卡派包税:【10-49KG:+1元/KG】","沃尔玛卡派包税: 【21-49KG:+2元/KG】； 【50-99KG:+1元/KG】；") -> FBA卡派包税:【10-49KG:+1元/KG】 | Q23: 美转加 | R23: 美转加加西20日达-UPS派（HD） | S23: {=IFERROR(VLOOKUP($S$5,#REF!,INDEX(定位!$A:$W,MATCH($R23,定位!$A:$A,0),MATCH("*"&$T$5&"*"&"-BS",定位!$1:$1,0)),FALSE),"-")} -> - | T23: {=IFERROR(VLOOKUP($S$5,#REF!,INDEX(定位!$A:$W,MATCH($R23,定位!$A:$A,0),MATCH("*"&$T$5&"*"&"-NBS",定位!$1:$1,0)),FALSE),"-")} -> - | U23: =IFERROR(VLOOKUP($C$5,#REF!,_xlfn.XLOOKUP($R23,定位!A:A,定位!V:V),FALSE),"-") -> - | V23: =IFERROR(VLOOKUP($C$5,#REF!,_xlfn.XLOOKUP($R23,定位!A:A,定位!W:W),FALSE),"-") -> - | W23: 包税21-49KG:+1.5元/KG；50-99KG:+1元/KG | AC23: 武汉 | AD23: 武汉/长沙/成都
A24: 拆派 | B24: 洛杉矶17日达 | C24: {=IFERROR(VLOOKUP($C$5,'美西-美森(12-17)'!$A:$DF,INDEX(定位!$A:$W,MATCH($B24,定位!$A:$A,0),MATCH("*"&$D$5&"*"&"-BS",定位!$1:$1,0)),FALSE),"-")} -> - | D24: {=IFERROR(VLOOKUP($C$5,'美西-美森(12-17)'!$A:$DF,INDEX(定位!$A:$W,MATCH($B24,定位!$A:$A,0),MATCH("*"&$D$5&"*"&"-NBS",定位!$1:$1,0)),FALSE),"-")} -> - | E24: =IFERROR(VLOOKUP($C$5,'美西-美森(12-17)'!$A:$DF,_xlfn.XLOOKUP($B24,定位!A:A,定位!V:V),FALSE),"-") -> - | F24: =IFERROR(VLOOKUP($C$5,'美西-美森(12-17)'!$A:$DF,_xlfn.XLOOKUP(B24,定位!A:A,定位!W:W),FALSE),"-") -> - | G24: =IF(LEFT($C$5,3)<>"WM-","FBA卡派包税:【10-49KG:+1元/KG】","沃尔玛卡派包税: 【21-49KG:+2元/KG】； 【50-99KG:+1元/KG】；") -> FBA卡派包税:【10-49KG:+1元/KG】 | Q24: 美转加 | R24: 美转加加东19日达-卡派（EXX） | S24: {=IFERROR(VLOOKUP($S$5,#REF!,INDEX(定位!$A:$W,MATCH($R24,定位!$A:$A,0),MATCH("*"&$T$5&"*"&"-BS",定位!$1:$1,0)),FALSE),"-")} -> - | T24: {=IFERROR(VLOOKUP($S$5,#REF!,INDEX(定位!$A:$W,MATCH($R24,定位!$A:$A,0),MATCH("*"&$T$5&"*"&"-NBS",定位!$1:$1,0)),FALSE),"-")} -> - | U24: =IFERROR(VLOOKUP($C$5,#REF!,_xlfn.XLOOKUP($R24,定位!A:A,定位!V:V),FALSE),"-") -> - | V24: =IFERROR(VLOOKUP($C$5,#REF!,_xlfn.XLOOKUP($R24,定位!A:A,定位!W:W),FALSE),"-") -> - | W24: 包税21-49KG:+1.5元/KG；50-99KG:+1元/KG | AC24: 长沙 | AD24: 武汉/长沙/成都
A25: 拆派 | B25: 洛杉矶20日达 | C25: {=IFERROR(VLOOKUP($C$5,'美西-以星&普船(17-26)'!$A:$BP,INDEX(定位!$A:$W,MATCH($B25,定位!$A:$A,0),MATCH("*"&$D$5&"*"&"-BS",定位!$1:$1,0)),FALSE),"-")} -> - | D25: {=IFERROR(VLOOKUP($C$5,'美西-以星&普船(17-26)'!$A:$BP,INDEX(定位!$A:$W,MATCH($B25,定位!$A:$A,0),MATCH("*"&$D$5&"*"&"-NBS",定位!$1:$1,0)),FALSE),"-")} -> - | E25: =IFERROR(VLOOKUP($C$5,'美西-以星&普船(17-26)'!$A:$BP,_xlfn.XLOOKUP($B25,定位!A:A,定位!V:V),FALSE),"-") -> - | F25: =IFERROR(VLOOKUP($C$5,'美西-以星&普船(17-26)'!$A:$BP,_xlfn.XLOOKUP($B25,定位!A:A,定位!W:W),FALSE),"-") -> - | G25: =IF(LEFT($C$5,3)<>"WM-","FBA卡派包税:【10-49KG:+1元/KG】","沃尔玛卡派包税: 【21-49KG:+2元/KG】； 【50-99KG:+1元/KG】；") -> FBA卡派包税:【10-49KG:+1元/KG】 | Q25: 美转加 | R25: 美转加加东19日达-UPS派（EXX） | S25: {=IFERROR(VLOOKUP($S$5,#REF!,INDEX(定位!$A:$W,MATCH($R25,定位!$A:$A,0),MATCH("*"&$T$5&"*"&"-BS",定位!$1:$1,0)),FALSE),"-")} -> - | T25: {=IFERROR(VLOOKUP($S$5,#REF!,INDEX(定位!$A:$W,MATCH($R25,定位!$A:$A,0),MATCH("*"&$T$5&"*"&"-NBS",定位!$1:$1,0)),FALSE),"-")} -> - | U25: =IFERROR(VLOOKUP($C$5,#REF!,_xlfn.XLOOKUP($R25,定位!A:A,定位!V:V),FALSE),"-") -> - | V25: =IFERROR(VLOOKUP($C$5,#REF!,_xlfn.XLOOKUP($R25,定位!A:A,定位!W:W),FALSE),"-") -> - | W25: 包税21-49KG:+1.5元/KG；50-99KG:+1元/KG | AC25: 成都 | AD25: 武汉/长沙/成都
A26: 拆派 | B26: 洛杉矶22日达 | C26: {=IFERROR(VLOOKUP($C$5,'美西-以星&普船(17-26)'!$A:$BP,INDEX(定位!$A:$W,MATCH($B26,定位!$A:$A,0),MATCH("*"&$D$5&"*"&"-BS",定位!$1:$1,0)),FALSE),"-")} -> - | D26: {=IFERROR(VLOOKUP($C$5,'美西-以星&普船(17-26)'!$A:$BP,INDEX(定位!$A:$W,MATCH($B26,定位!$A:$A,0),MATCH("*"&$D$5&"*"&"-NBS",定位!$1:$1,0)),FALSE),"-")} -> - | E26: =IFERROR(VLOOKUP($C$5,'美西-以星&普船(17-26)'!$A:$BP,_xlfn.XLOOKUP($B26,定位!A:A,定位!V:V),FALSE),"-") -> - | F26: =IFERROR(VLOOKUP($C$5,'美西-以星&普船(17-26)'!$A:$BP,_xlfn.XLOOKUP(B26,定位!A:A,定位!W:W),FALSE),"-") -> - | G26: =IF(LEFT($C$5,3)<>"WM-","FBA卡派包税:【10-49KG:+1元/KG】","沃尔玛卡派包税: 【21-49KG:+2元/KG】； 【50-99KG:+1元/KG】；") -> FBA卡派包税:【10-49KG:+1元/KG】 | Q26: 美转加 | R26: 美转加加西19日达-卡派（EXX） | S26: {=IFERROR(VLOOKUP($S$5,#REF!,INDEX(定位!$A:$W,MATCH($R26,定位!$A:$A,0),MATCH("*"&$T$5&"*"&"-BS",定位!$1:$1,0)),FALSE),"-")} -> - | T26: {=IFERROR(VLOOKUP($S$5,#REF!,INDEX(定位!$A:$W,MATCH($R26,定位!$A:$A,0),MATCH("*"&$T$5&"*"&"-NBS",定位!$1:$1,0)),FALSE),"-")} -> - | U26: =IFERROR(VLOOKUP($C$5,#REF!,_xlfn.XLOOKUP($R26,定位!A:A,定位!V:V),FALSE),"-") -> - | V26: =IFERROR(VLOOKUP($C$5,#REF!,_xlfn.XLOOKUP($R26,定位!A:A,定位!W:W),FALSE),"-") -> - | W26: 包税21-49KG:+1.5元/KG；50-99KG:+1元/KG | AC26: 重庆 | AD26: 重庆
A27: 拆派 | B27: 洛杉矶26日达 | C27: {=IFERROR(VLOOKUP($C$5,'美西-以星&普船(17-26)'!$A:$BP,INDEX(定位!$A:$W,MATCH($B27,定位!$A:$A,0),MATCH("*"&$D$5&"*"&"-BS",定位!$1:$1,0)),FALSE),"-")} -> - | D27: {=IFERROR(VLOOKUP($C$5,'美西-以星&普船(17-26)'!$A:$BP,INDEX(定位!$A:$W,MATCH($B27,定位!$A:$A,0),MATCH("*"&$D$5&"*"&"-NBS",定位!$1:$1,0)),FALSE),"-")} -> - | E27: =IFERROR(VLOOKUP($C$5,'美西-以星&普船(17-26)'!$A:$BP,_xlfn.XLOOKUP($B27,定位!A:A,定位!V:V),FALSE),"-") -> - | F27: =IFERROR(VLOOKUP($C$5,'美西-以星&普船(17-26)'!$A:$BP,_xlfn.XLOOKUP(B27,定位!A:A,定位!W:W),FALSE),"-") -> - | G27: =IF(LEFT($C$5,3)<>"WM-","FBA卡派包税:【10-49KG:+1元/KG】","沃尔玛卡派包税: 【21-49KG:+2元/KG】； 【50-99KG:+1元/KG】；") -> FBA卡派包税:【10-49KG:+1元/KG】 | Q27: 美转加 | R27: 美转加加西19日达-UPS派（EXX） | S27: {=IFERROR(VLOOKUP($S$5,#REF!,INDEX(定位!$A:$W,MATCH($R27,定位!$A:$A,0),MATCH("*"&$T$5&"*"&"-BS",定位!$1:$1,0)),FALSE),"-")} -> - | T27: {=IFERROR(VLOOKUP($S$5,#REF!,INDEX(定位!$A:$W,MATCH($R27,定位!$A:$A,0),MATCH("*"&$T$5&"*"&"-NBS",定位!$1:$1,0)),FALSE),"-")} -> - | U27: =IFERROR(VLOOKUP($C$5,#REF!,_xlfn.XLOOKUP($R27,定位!A:A,定位!V:V),FALSE),"-") -> - | V27: =IFERROR(VLOOKUP($C$5,#REF!,_xlfn.XLOOKUP($R27,定位!A:A,定位!W:W),FALSE),"-") -> - | W27: 包税21-49KG:+1.5元/KG；50-99KG:+1元/KG | AC27: 天津 | AD27: 天津/南昌/石家庄
A28: 拆派 | B28: 奥克兰直航26日达 | C28: {=IFERROR(VLOOKUP($C$5,美西北!$A:$DP,INDEX(定位!$A:$W,MATCH($B28,定位!$A:$A,0),MATCH("*"&$D$5&"*"&"-BS",定位!$1:$1,0)),FALSE),"-")} -> - | D28: {=IFERROR(VLOOKUP($C$5,美西北!$A:$DP,INDEX(定位!$A:$W,MATCH($B28,定位!$A:$A,0),MATCH("*"&$D$5&"*"&"-NBS",定位!$1:$1,0)),FALSE),"-")} -> - | E28: =IFERROR(VLOOKUP($C$5,美西北!$A:$DP,_xlfn.XLOOKUP($B28,定位!A:A,定位!V:V),FALSE),"-") -> - | F28: =IFERROR(VLOOKUP($C$5,美西北!$A:$DP,_xlfn.XLOOKUP($B28,定位!A:A,定位!W:W),FALSE),"-") -> - | G28: =IF(LEFT($C$5,3)<>"WM-","FBA卡派包税:【10-49KG:+1元/KG】","沃尔玛卡派包税: 【21-49KG:+2元/KG】； 【50-99KG:+1元/KG】；") -> FBA卡派包税:【10-49KG:+1元/KG】 | Q28: 美转加 | R28: 美转加MAX加东17日达-卡派 | S28: {=IFERROR(VLOOKUP($S$5,#REF!,INDEX(定位!$A:$W,MATCH($R28,定位!$A:$A,0),MATCH("*"&$T$5&"*"&"-BS",定位!$1:$1,0)),FALSE),"-")} -> - | T28: {=IFERROR(VLOOKUP($S$5,#REF!,INDEX(定位!$A:$W,MATCH($R28,定位!$A:$A,0),MATCH("*"&$T$5&"*"&"-NBS",定位!$1:$1,0)),FALSE),"-")} -> - | U28: =IFERROR(VLOOKUP($C$5,#REF!,_xlfn.XLOOKUP($R28,定位!A:A,定位!V:V),FALSE),"-") -> - | V28: =IFERROR(VLOOKUP($C$5,#REF!,_xlfn.XLOOKUP($R28,定位!A:A,定位!W:W),FALSE),"-") -> - | W28: 包税21-49KG:+1.5元/KG；50-99KG:+1元/KG | AC28: 南昌 | AD28: 天津/南昌/石家庄
A29: 拆派 | B29: 奥克兰直航32日达 | C29: {=IFERROR(VLOOKUP($C$5,美西北!$A:$DP,INDEX(定位!$A:$W,MATCH($B29,定位!$A:$A,0),MATCH("*"&$D$5&"*"&"-BS",定位!$1:$1,0)),FALSE),"-")} -> - | D29: {=IFERROR(VLOOKUP($C$5,美西北!$A:$DP,INDEX(定位!$A:$W,MATCH($B29,定位!$A:$A,0),MATCH("*"&$D$5&"*"&"-NBS",定位!$1:$1,0)),FALSE),"-")} -> - | E29: =IFERROR(VLOOKUP($C$5,美西北!$A:$DP,_xlfn.XLOOKUP($B29,定位!A:A,定位!V:V),FALSE),"-") -> - | F29: =IFERROR(VLOOKUP($C$5,美西北!$A:$DP,_xlfn.XLOOKUP($B29,定位!A:A,定位!W:W),FALSE),"-") -> - | G29: =IF(LEFT($C$5,3)<>"WM-","FBA卡派包税:【10-49KG:+1元/KG】","沃尔玛卡派包税: 【21-49KG:+2元/KG】； 【50-99KG:+1元/KG】；") -> FBA卡派包税:【10-49KG:+1元/KG】 | Q29: 美转加 | R29: 美转加MAX加东17日达-UPS派 | S29: {=IFERROR(VLOOKUP($S$5,#REF!,INDEX(定位!$A:$W,MATCH($R29,定位!$A:$A,0),MATCH("*"&$T$5&"*"&"-BS",定位!$1:$1,0)),FALSE),"-")} -> - | T29: {=IFERROR(VLOOKUP($S$5,#REF!,INDEX(定位!$A:$W,MATCH($R29,定位!$A:$A,0),MATCH("*"&$T$5&"*"&"-NBS",定位!$1:$1,0)),FALSE),"-")} -> - | U29: =IFERROR(VLOOKUP($C$5,#REF!,_xlfn.XLOOKUP($R29,定位!A:A,定位!V:V),FALSE),"-") -> - | V29: =IFERROR(VLOOKUP($C$5,#REF!,_xlfn.XLOOKUP($R29,定位!A:A,定位!W:W),FALSE),"-") -> - | W29: 包税21-49KG:+1.5元/KG；50-99KG:+1元/KG | AC29: 石家庄 | AD29: 天津/南昌/石家庄
A30: 拆派 | B30: 西雅图直航29日达 | C30: {=IFERROR(VLOOKUP($C$5,美西北!$A:$DP,INDEX(定位!$A:$W,MATCH($B30,定位!$A:$A,0),MATCH("*"&$D$5&"*"&"-BS",定位!$1:$1,0)),FALSE),"-")} -> - | D30: {=IFERROR(VLOOKUP($C$5,美西北!$A:$DP,INDEX(定位!$A:$W,MATCH($B30,定位!$A:$A,0),MATCH("*"&$D$5&"*"&"-NBS",定位!$1:$1,0)),FALSE),"-")} -> - | E30: =IFERROR(VLOOKUP($C$5,美西北!$A:$DP,_xlfn.XLOOKUP($B30,定位!A:A,定位!V:V),FALSE),"-") -> - | F30: =IFERROR(VLOOKUP($C$5,美西北!$A:$DP,_xlfn.XLOOKUP(B30,定位!A:A,定位!W:W),FALSE),"-") -> - | G30: =IF(LEFT($C$5,3)<>"WM-","FBA卡派包税:【10-49KG:+1元/KG】","沃尔玛卡派包税: 【21-49KG:+2元/KG】； 【50-99KG:+1元/KG】；") -> FBA卡派包税:【10-49KG:+1元/KG】 | Q30: 美转加 | R30: 美转加MAX加西17日达-卡派 | S30: {=IFERROR(VLOOKUP($S$5,#REF!,INDEX(定位!$A:$W,MATCH($R30,定位!$A:$A,0),MATCH("*"&$T$5&"*"&"-BS",定位!$1:$1,0)),FALSE),"-")} -> - | T30: {=IFERROR(VLOOKUP($S$5,#REF!,INDEX(定位!$A:$W,MATCH($R30,定位!$A:$A,0),MATCH("*"&$T$5&"*"&"-NBS",定位!$1:$1,0)),FALSE),"-")} -> - | U30: =IFERROR(VLOOKUP($C$5,#REF!,_xlfn.XLOOKUP($R30,定位!A:A,定位!V:V),FALSE),"-") -> - | V30: =IFERROR(VLOOKUP($C$5,#REF!,_xlfn.XLOOKUP($R30,定位!A:A,定位!W:W),FALSE),"-") -> - | W30: 包税21-49KG:+1.5元/KG；50-99KG:+1元/KG | AC30: 沧州 | AD30: 沧州/保定
A31: 拆派 | B31: 纽约直航42日达 | C31: {=IFERROR(VLOOKUP($C$5,美东直航系列!$A:$CT,INDEX(定位!$A:$W,MATCH($B31,定位!$A:$A,0),MATCH("*"&$D$5&"*"&"-BS",定位!$1:$1,0)),FALSE),"-")} -> - | D31: {=IFERROR(VLOOKUP($C$5,美东直航系列!$A:$CT,INDEX(定位!$A:$W,MATCH($B31,定位!$A:$A,0),MATCH("*"&$D$5&"*"&"-NBS",定位!$1:$1,0)),FALSE),"-")} -> - | E31: =IFERROR(VLOOKUP($C$5,美东直航系列!$A:$CT,_xlfn.XLOOKUP($B31,定位!A:A,定位!V:V),FALSE),"-") -> - | F31: =IFERROR(VLOOKUP($C$5,美东直航系列!$A:$CT,_xlfn.XLOOKUP($B31,定位!A:A,定位!W:W),FALSE),"-") -> - | G31: =IF(LEFT($C$5,3)<>"WM-","FBA卡派包税:【10-49KG:+1元/KG】","沃尔玛卡派包税: 【21-49KG:+2元/KG】； 【50-99KG:+1元/KG】；") -> FBA卡派包税:【10-49KG:+1元/KG】 | Q31: 美转加 | R31: 美转加MAX加西17日达-UPS派 | S31: {=IFERROR(VLOOKUP($S$5,#REF!,INDEX(定位!$A:$W,MATCH($R31,定位!$A:$A,0),MATCH("*"&$T$5&"*"&"-BS",定位!$1:$1,0)),FALSE),"-")} -> - | T31: {=IFERROR(VLOOKUP($S$5,#REF!,INDEX(定位!$A:$W,MATCH($R31,定位!$A:$A,0),MATCH("*"&$T$5&"*"&"-NBS",定位!$1:$1,0)),FALSE),"-")} -> - | U31: =IFERROR(VLOOKUP($C$5,#REF!,_xlfn.XLOOKUP($R31,定位!A:A,定位!V:V),FALSE),"-") -> - | V31: =IFERROR(VLOOKUP($C$5,#REF!,_xlfn.XLOOKUP($R31,定位!A:A,定位!W:W),FALSE),"-") -> - | W31: 包税21-49KG:+1.5元/KG；50-99KG:+1元/KG | AC31: 保定 | AD31: 沧州/保定
A32: 拆派 | B32: 纽约直航38日达 | C32: {=IFERROR(VLOOKUP($C$5,美东直航系列!$A:$CT,INDEX(定位!$A:$W,MATCH($B32,定位!$A:$A,0),MATCH("*"&$D$5&"*"&"-BS",定位!$1:$1,0)),FALSE),"-")} -> - | D32: {=IFERROR(VLOOKUP($C$5,美东直航系列!$A:$CT,INDEX(定位!$A:$W,MATCH($B32,定位!$A:$A,0),MATCH("*"&$D$5&"*"&"-NBS",定位!$1:$1,0)),FALSE),"-")} -> - | E32: =IFERROR(VLOOKUP($C$5,美东直航系列!$A:$CT,_xlfn.XLOOKUP($B32,定位!A:A,定位!V:V),FALSE),"-") -> - | F32: =IFERROR(VLOOKUP($C$5,美东直航系列!$A:$CT,_xlfn.XLOOKUP(B32,定位!A:A,定位!W:W),FALSE),"-") -> - | G32: =IF(LEFT($C$5,3)<>"WM-","FBA卡派包税:【10-49KG:+1元/KG】","沃尔玛卡派包税: 【21-49KG:+2元/KG】； 【50-99KG:+1元/KG】；") -> FBA卡派包税:【10-49KG:+1元/KG】 | Q32: 美转加 | R32: 美转加CLX加东16日达-卡派 | S32: {=IFERROR(VLOOKUP($S$5,#REF!,INDEX(定位!$A:$W,MATCH($R32,定位!$A:$A,0),MATCH("*"&$T$5&"*"&"-BS",定位!$1:$1,0)),FALSE),"-")} -> - | T32: {=IFERROR(VLOOKUP($S$5,#REF!,INDEX(定位!$A:$W,MATCH($R32,定位!$A:$A,0),MATCH("*"&$T$5&"*"&"-NBS",定位!$1:$1,0)),FALSE),"-")} -> - | U32: =IFERROR(VLOOKUP($C$5,'[4]美转加-美森CLX系列'!$A:$BQ,_xlfn.XLOOKUP($R32,[4]定位!A:A,[4]定位!V:V),FALSE),"-") -> 20-24日 | V32: =IFERROR(VLOOKUP($C$5,'[4]美转加-美森CLX系列'!$A:$BQ,_xlfn.XLOOKUP($R32,[4]定位!A:A,[4]定位!W:W),FALSE),"-") -> 超26日 | W32: 快递派包税21-99KG:+1元/KG； | AC32: 潍坊 | AD32: 济南/潍坊
A33: 拆派 | B33: 纽约海铁24日达 | C33: {=IFERROR(VLOOKUP($C$5,'美东-海铁系列'!$A:$CX,INDEX(定位!$A:$W,MATCH($B33,定位!$A:$A,0),MATCH("*"&$D$5&"*"&"-BS",定位!$1:$1,0)),FALSE),"-")} -> - | D33: {=IFERROR(VLOOKUP($C$5,'美东-海铁系列'!$A:$CX,INDEX(定位!$A:$W,MATCH($B33,定位!$A:$A,0),MATCH("*"&$D$5&"*"&"-NBS",定位!$1:$1,0)),FALSE),"-")} -> - | E33: =IFERROR(VLOOKUP($C$5,'美东-海铁系列'!$A:$CX,_xlfn.XLOOKUP($B33,定位!A:A,定位!V:V),FALSE),"-") -> - | F33: =IFERROR(VLOOKUP($C$5,'美东-海铁系列'!$A:$CX,_xlfn.XLOOKUP($B33,定位!A:A,定位!W:W),FALSE),"-") -> - | G33: =IF(LEFT($C$5,3)<>"WM-","FBA卡派包税:【10-49KG:+1元/KG】","沃尔玛卡派包税: 【21-49KG:+2元/KG】； 【50-99KG:+1元/KG】；") -> FBA卡派包税:【10-49KG:+1元/KG】 | Q33: 美转加 | R33: 美转加CLX加东16日达-UPS派 | S33: {=IFERROR(VLOOKUP($S$5,#REF!,INDEX(定位!$A:$W,MATCH($R33,定位!$A:$A,0),MATCH("*"&$T$5&"*"&"-BS",定位!$1:$1,0)),FALSE),"-")} -> - | T33: {=IFERROR(VLOOKUP($S$5,#REF!,INDEX(定位!$A:$W,MATCH($R33,定位!$A:$A,0),MATCH("*"&$T$5&"*"&"-NBS",定位!$1:$1,0)),FALSE),"-")} -> - | U33: =IFERROR(VLOOKUP($C$5,'[4]美转加-美森CLX系列'!$A:$BQ,_xlfn.XLOOKUP($R33,[4]定位!A:A,[4]定位!V:V),FALSE),"-") -> 18-22日 | V33: =IFERROR(VLOOKUP($C$5,'[4]美转加-美森CLX系列'!$A:$BQ,_xlfn.XLOOKUP($R33,[4]定位!A:A,[4]定位!W:W),FALSE),"-") -> 超24日 | W33: 快递派包税21-99KG:+1元/KG； | AC33: 西安 | AD33: 西安
A34: 拆派 | B34: 纽约MAX海铁22日达 | C34: {=IFERROR(VLOOKUP($C$5,'美东-海铁系列'!$A:$CX,INDEX(定位!$A:$W,MATCH($B34,定位!$A:$A,0),MATCH("*"&$D$5&"*"&"-BS",定位!$1:$1,0)),FALSE),"-")} -> - | D34: {=IFERROR(VLOOKUP($C$5,'美东-海铁系列'!$A:$CX,INDEX(定位!$A:$W,MATCH($B34,定位!$A:$A,0),MATCH("*"&$D$5&"*"&"-NBS",定位!$1:$1,0)),FALSE),"-")} -> - | E34: =IFERROR(VLOOKUP($C$5,'美东-海铁系列'!$A:$CX,_xlfn.XLOOKUP($B34,定位!A:A,定位!V:V),FALSE),"-") -> - | F34: =IFERROR(VLOOKUP($C$5,'美东-海铁系列'!$A:$CX,_xlfn.XLOOKUP(B34,定位!A:A,定位!W:W),FALSE),"-") -> - | G34: =IF(LEFT($C$5,3)<>"WM-","FBA卡派包税:【10-49KG:+1元/KG】","沃尔玛卡派包税: 【21-49KG:+2元/KG】； 【50-99KG:+1元/KG】；") -> FBA卡派包税:【10-49KG:+1元/KG】 | Q34: 美转加 | R34: 美转加CLX加西16日达-卡派 | S34: {=IFERROR(VLOOKUP($S$5,#REF!,INDEX(定位!$A:$W,MATCH($R34,定位!$A:$A,0),MATCH("*"&$T$5&"*"&"-BS",定位!$1:$1,0)),FALSE),"-")} -> - | T34: {=IFERROR(VLOOKUP($S$5,#REF!,INDEX(定位!$A:$W,MATCH($R34,定位!$A:$A,0),MATCH("*"&$T$5&"*"&"-NBS",定位!$1:$1,0)),FALSE),"-")} -> - | U34: =IFERROR(VLOOKUP($C$5,'[4]美转加-美森CLX系列'!$A:$BQ,_xlfn.XLOOKUP($R34,[4]定位!A:A,[4]定位!V:V),FALSE),"-") -> - | V34: =IFERROR(VLOOKUP($C$5,'[4]美转加-美森CLX系列'!$A:$BQ,_xlfn.XLOOKUP($R34,[4]定位!A:A,[4]定位!W:W),FALSE),"-") -> - | W34: 快递派包税21-99KG:+1元/KG； | AC34: 济南 | AD34: 济南/潍坊
A35: 拆派 | B35: 纽约海铁30日达 | C35: {=IFERROR(VLOOKUP($C$5,'美东-海铁系列'!$A:$CX,INDEX(定位!$A:$W,MATCH($B35,定位!$A:$A,0),MATCH("*"&$D$5&"*"&"-BS",定位!$1:$1,0)),FALSE),"-")} -> - | D35: {=IFERROR(VLOOKUP($C$5,'美东-海铁系列'!$A:$CX,INDEX(定位!$A:$W,MATCH($B35,定位!$A:$A,0),MATCH("*"&$D$5&"*"&"-NBS",定位!$1:$1,0)),FALSE),"-")} -> - | E35: =IFERROR(VLOOKUP($C$5,'美东-海铁系列'!$A:$CX,_xlfn.XLOOKUP($B35,定位!A:A,定位!V:V),FALSE),"-") -> - | F35: =IFERROR(VLOOKUP($C$5,'美东-海铁系列'!$A:$CX,_xlfn.XLOOKUP(B35,定位!A:A,定位!W:W),FALSE),"-") -> - | G35: =IF(LEFT($C$5,3)<>"WM-","FBA卡派包税:【10-49KG:+1元/KG】","沃尔玛卡派包税: 【21-49KG:+2元/KG】； 【50-99KG:+1元/KG】；") -> FBA卡派包税:【10-49KG:+1元/KG】 | Q35: 美转加 | R35: 美转加CLX加西16日达-UPS派 | S35: {=IFERROR(VLOOKUP($S$5,#REF!,INDEX(定位!$A:$W,MATCH($R35,定位!$A:$A,0),MATCH("*"&$T$5&"*"&"-BS",定位!$1:$1,0)),FALSE),"-")} -> - | T35: {=IFERROR(VLOOKUP($S$5,#REF!,INDEX(定位!$A:$W,MATCH($R35,定位!$A:$A,0),MATCH("*"&$T$5&"*"&"-NBS",定位!$1:$1,0)),FALSE),"-")} -> - | U35: =IFERROR(VLOOKUP($C$5,'[4]美转加-美森CLX系列'!$A:$BQ,_xlfn.XLOOKUP($R35,[4]定位!A:A,[4]定位!V:V),FALSE),"-") -> - | V35: =IFERROR(VLOOKUP($C$5,'[4]美转加-美森CLX系列'!$A:$BQ,_xlfn.XLOOKUP($R35,[4]定位!A:A,[4]定位!W:W),FALSE),"-") -> - | W35: 快递派包税21-99KG:+1元/KG； | AC35: 南京 | AD35: 青岛/郑州/绍兴/苏州/杭州仓/连云港/温州/台州/南京/合肥
A36: 拆派 | B36: 萨凡纳直航36日达 | C36: {=IFERROR(VLOOKUP($C$5,美东南直航系列!$A:$CT,INDEX(定位!$A:$W,MATCH($B36,定位!$A:$A,0),MATCH("*"&$D$5&"*"&"-BS",定位!$1:$1,0)),FALSE),"-")} -> - | D36: {=IFERROR(VLOOKUP($C$5,美东南直航系列!$A:$CT,INDEX(定位!$A:$W,MATCH($B36,定位!$A:$A,0),MATCH("*"&$D$5&"*"&"-NBS",定位!$1:$1,0)),FALSE),"-")} -> - | E36: =IFERROR(VLOOKUP($C$5,美东南直航系列!$A:$CT,_xlfn.XLOOKUP($B36,定位!A:A,定位!V:V),FALSE),"-") -> - | F36: =IFERROR(VLOOKUP($C$5,美东南直航系列!$A:$CT,_xlfn.XLOOKUP($B36,定位!A:A,定位!W:W),FALSE),"-") -> - | G36: =IF(LEFT($C$5,3)<>"WM-","FBA卡派包税:【10-49KG:+1元/KG】","沃尔玛卡派包税: 【21-49KG:+2元/KG】； 【50-99KG:+1元/KG】；") -> FBA卡派包税:【10-49KG:+1元/KG】 | AC36: 合肥 | AD36: 青岛/郑州/绍兴/苏州/杭州仓/连云港/温州/台州/南京/合肥
A37: 拆派 | B37: 萨凡纳直航48日达 | C37: {=IFERROR(VLOOKUP($C$5,美东南直航系列!$A:$CT,INDEX(定位!$A:$W,MATCH($B37,定位!$A:$A,0),MATCH("*"&$D$5&"*"&"-BS",定位!$1:$1,0)),FALSE),"-")} -> - | D37: {=IFERROR(VLOOKUP($C$5,美东南直航系列!$A:$CT,INDEX(定位!$A:$W,MATCH($B37,定位!$A:$A,0),MATCH("*"&$D$5&"*"&"-NBS",定位!$1:$1,0)),FALSE),"-")} -> - | E37: =IFERROR(VLOOKUP($C$5,美东南直航系列!$A:$CT,_xlfn.XLOOKUP($B37,定位!A:A,定位!V:V),FALSE),"-") -> - | F37: =IFERROR(VLOOKUP($C$5,美东南直航系列!$A:$CT,_xlfn.XLOOKUP(B37,定位!A:A,定位!W:W),FALSE),"-") -> - | G37: =IF(LEFT($C$5,3)<>"WM-","FBA卡派包税:【10-49KG:+1元/KG】","沃尔玛卡派包税: 【21-49KG:+2元/KG】； 【50-99KG:+1元/KG】；") -> FBA卡派包税:【10-49KG:+1元/KG】
A38: 拆派 | B38: 萨凡纳海陆24日达 | C38: {=IFERROR(VLOOKUP($C$5,美东南海陆系列!$A:$CP,INDEX(定位!$A:$W,MATCH($B38,定位!$A:$A,0),MATCH("*"&$D$5&"*"&"-BS",定位!$1:$1,0)),FALSE),"-")} -> - | D38: {=IFERROR(VLOOKUP($C$5,美东南海陆系列!$A:$CP,INDEX(定位!$A:$W,MATCH($B38,定位!$A:$A,0),MATCH("*"&$D$5&"*"&"-NBS",定位!$1:$1,0)),FALSE),"-")} -> - | E38: =IFERROR(VLOOKUP($C$5,美东南海陆系列!$A:$CP,_xlfn.XLOOKUP($B38,定位!A:A,定位!V:V),FALSE),"-") -> - | F38: =IFERROR(VLOOKUP($C$5,美东南海陆系列!$A:$CP,_xlfn.XLOOKUP(B38,定位!A:A,定位!W:W),FALSE),"-") -> - | G38: =IF(LEFT($C$5,3)<>"WM-","FBA卡派包税:【10-49KG:+1元/KG】","沃尔玛卡派包税: 【21-49KG:+2元/KG】； 【50-99KG:+1元/KG】；") -> FBA卡派包税:【10-49KG:+1元/KG】
A39: 拆派 | B39: 休斯顿海铁23日达 | C39: {=IFERROR(VLOOKUP($C$5,'美中-休斯顿'!$A:$BT,INDEX(定位!$A:$W,MATCH($B39,定位!$A:$A,0),MATCH("*"&$D$5&"*"&"-BS",定位!$1:$1,0)),FALSE),"-")} -> - | D39: {=IFERROR(VLOOKUP($C$5,'美中-休斯顿'!$A:$BT,INDEX(定位!$A:$W,MATCH($B39,定位!$A:$A,0),MATCH("*"&$D$5&"*"&"-NBS",定位!$1:$1,0)),FALSE),"-")} -> - | E39: =IFERROR(VLOOKUP($C$5,'美中-休斯顿'!$A:$BT,_xlfn.XLOOKUP($B39,定位!A:A,定位!V:V),FALSE),"-") -> - | F39: =IFERROR(VLOOKUP($C$5,'美中-休斯顿'!$A:$BT,_xlfn.XLOOKUP($B39,定位!A:A,定位!W:W),FALSE),"-") -> - | G39: =IF(LEFT($C$5,3)<>"WM-","FBA卡派包税:【10-49KG:+1元/KG】","沃尔玛卡派包税: 【21-49KG:+2元/KG】； 【50-99KG:+1元/KG】；") -> FBA卡派包税:【10-49KG:+1元/KG】
A40: 拆派 | B40: 休斯顿直航38日达 | C40: {=IFERROR(VLOOKUP($C$5,'美中-休斯顿'!$A:$BT,INDEX(定位!$A:$W,MATCH($B40,定位!$A:$A,0),MATCH("*"&$D$5&"*"&"-BS",定位!$1:$1,0)),FALSE),"-")} -> - | D40: {=IFERROR(VLOOKUP($C$5,'美中-休斯顿'!$A:$BT,INDEX(定位!$A:$W,MATCH($B40,定位!$A:$A,0),MATCH("*"&$D$5&"*"&"-NBS",定位!$1:$1,0)),FALSE),"-")} -> - | E40: =IFERROR(VLOOKUP($C$5,'美中-休斯顿'!$A:$BT,_xlfn.XLOOKUP($B40,定位!A:A,定位!V:V),FALSE),"-") -> - | F40: =IFERROR(VLOOKUP($C$5,'美中-休斯顿'!$A:$BT,_xlfn.XLOOKUP($B40,定位!A:A,定位!W:W),FALSE),"-") -> - | G40: =IF(LEFT($C$5,3)<>"WM-","FBA卡派包税:【10-49KG:+1元/KG】","沃尔玛卡派包税: 【21-49KG:+2元/KG】； 【50-99KG:+1元/KG】；") -> FBA卡派包税:【10-49KG:+1元/KG】
A41: 拆派 | B41: 芝加哥海铁28日达 | C41: {=IFERROR(VLOOKUP($C$5,'美中-芝加哥'!$A:$CX,INDEX(定位!$A:$W,MATCH($B41,定位!$A:$A,0),MATCH("*"&$D$5&"*"&"-BS",定位!$1:$1,0)),FALSE),"-")} -> - | D41: {=IFERROR(VLOOKUP($C$5,'美中-芝加哥'!$A:$CX,INDEX(定位!$A:$W,MATCH($B41,定位!$A:$A,0),MATCH("*"&$D$5&"*"&"-NBS",定位!$1:$1,0)),FALSE),"-")} -> - | E41: =IFERROR(VLOOKUP($C$5,'美中-芝加哥'!$A:$CX,_xlfn.XLOOKUP($B41,定位!A:A,定位!V:V),FALSE),"-") -> - | F41: =IFERROR(VLOOKUP($C$5,'美中-芝加哥'!$A:$CX,_xlfn.XLOOKUP($B41,定位!A:A,定位!W:W),FALSE),"-") -> - | G41: =IF(LEFT($C$5,3)<>"WM-","FBA卡派包税:【10-49KG:+1元/KG】","沃尔玛卡派包税: 【21-49KG:+2元/KG】； 【50-99KG:+1元/KG】；") -> FBA卡派包税:【10-49KG:+1元/KG】
...

Sheet 定位
A1: 渠道 | B1: 华南-BS | C1: 重庆-BS | D1: 汕头-BS | E1: 厦门/泉州/福州-BS | F1: 华东-BS | G1: 青岛/郑州/温州/台州/连云港/南京/合肥-BS | H1: 天津/南昌/石家庄-BS | I1: 济南/潍坊-BS | J1: 西安/沧州/保定-BS | K1: 武汉/长沙/成都-BS | L1: 华南-NBS | M1: 重庆-NBS | N1: 汕头-NBS | O1: 厦门/泉州/福州-NBS | P1: 华东-NBS | Q1: 青岛/郑州/温州/台州/连云港/南京/合肥-NBS | R1: 天津/南昌/石家庄-NBS | S1: 济南/潍坊-NBS | T1: 西安/沧州/保定-NBS | U1: 武汉/长沙/成都-NBS | V1: 签收时效 开船后-入仓时效 | W1: 延时赔付 开船后-不入仓时效
A2: 洛杉矶普船28日达直送 | B2: 2 | C2: 3 | D2: 4 | E2: 5 | F2: 6 | G2: 7 | H2: 8 | I2: 9 | J2: 10 | K2: 11 | L2: 12 | M2: 13 | N2: 14 | O2: 15 | P2: 16 | Q2: 17 | R2: 18 | S2: 19 | T2: 20 | U2: 21 | V2: 22 | W2: 23
A3: 洛杉矶OA26日达直送 | B3: =B2+22 -> 24 | C3: =C2+22 -> 25 | D3: =D2+22 -> 26 | E3: =E2+22 -> 27 | F3: =F2+22 -> 28 | G3: =G2+22 -> 29 | H3: =H2+22 -> 30 | I3: =I2+22 -> 31 | ... W3: =W2+22 -> 45
A4: 奥克兰OA29日达直送 | B4: =B3+22 -> 46 | C4: =C3+22 -> 47 | D4: =D3+22 -> 48 | E4: =E3+22 -> 49 | F4: =F3+22 -> 50 | G4: =G3+22 -> 51 | H4: =H3+22 -> 52 | I4: =I3+22 -> 53 | ... W4: =W3+22 -> 67
A5: 奥克兰普船36日达直送 | B5: =B4+22 -> 68 | C5: =C4+22 -> 69 | D5: =D4+22 -> 70 | E5: =E4+22 -> 71 | F5: =F4+22 -> 72 | G5: =G4+22 -> 73 | H5: =H4+22 -> 74 | I5: =I4+22 -> 75 | ... W5: =W4+22 -> 89
A6: 纽约直航42日达直送特价 | B6: 2 | C6: 3 | D6: 4 | E6: 5 | F6: 6 | G6: 7 | H6: 8 | I6: 9 | J6: 10 | K6: 11 | L6: 12 | M6: 13 | N6: 14 | O6: 15 | P6: 16 | Q6: 17 | R6: 18 | S6: 19 | T6: 20 | U6: 21 | V6: 22 | W6: 23
A7: 纽约直航38日达直送特价 | B7: =B6+22 -> 24 | C7: =C6+22 -> 25 | D7: =D6+22 -> 26 | E7: =E6+22 -> 27 | F7: =F6+22 -> 28 | G7: =G6+22 -> 29 | H7: =H6+22 -> 30 | I7: =I6+22 -> 31 | ... W7: =W6+22 -> 45
A8: 萨凡纳直航36日达直送 | B8: 2 | C8: 3 | D8: 4 | E8: 5 | F8: 6 | G8: 7 | H8: 8 | I8: 9 | J8: 10 | K8: 11 | L8: 12 | M8: 13 | N8: 14 | O8: 15 | P8: 16 | Q8: 17 | R8: 18 | S8: 19 | T8: 20 | U8: 21 | V8: 22 | W8: 23
A9: 萨凡纳直航48日达直送 | B9: =B8+22 -> 24 | C9: =C8+22 -> 25 | D9: =D8+22 -> 26 | E9: =E8+22 -> 27 | F9: =F8+22 -> 28 | G9: =G8+22 -> 29 | H9: =H8+22 -> 30 | I9: =I8+22 -> 31 | ... W9: =W8+22 -> 45
A10: 休斯顿海铁23日达直送特价 | B10: =B11+22 -> 24 | C10: =C11+22 -> 25 | D10: =D11+22 -> 26 | E10: =E11+22 -> 27 | F10: =F11+22 -> 28 | G10: =G11+22 -> 29 | H10: =H11+22 -> 30 | I10: =I11+22 -> 31 | ... W10: =W11+22 -> 45
A11: 休斯顿直航38日达直送特价 | B11: 2 | C11: 3 | D11: 4 | E11: 5 | F11: 6 | G11: 7 | H11: 8 | I11: 9 | J11: 10 | K11: 11 | L11: 12 | M11: 13 | N11: 14 | O11: 15 | P11: 16 | Q11: 17 | R11: 18 | S11: 19 | T11: 20 | U11: 21 | V11: 22 | W11: 23
